File: example_data/211216/102.1.itosa5ei.vms
VAMAS Surface Chemical Analysis Standard Data Transfer Format 1988 May 4
MIT
PHI VersaProbe II
Emma Batson
FILE:C:\Datafiles\users\MIT\berggren\emmabat\211216\102.1.ITOSA5ei.spe;BATCH:211216;DESC:ITOSA5ei;
184
SOFH
Platform: PC
Technique: XPS
TechniqueEx: XPS
FileType:  SPECTRUM
FileDesc: ITOSA5ei
SoftwareVersion: SS 2.10.4.1
InstrumentModel: PHI VersaProbe II
AcqFilename: C:\Datafiles\users\MIT\berggren\emmabat\211216\102.1.ITOSA5ei.spe
FileDate: 2021 12 16
AcqFileDate: 2021 12 16
Institution: MIT
Operator: Emma Batson
ExperimentID: 211216
EnergyReference: none 0.0
AnalyserWorkFcn: 4.399 eV
AnalyserRetardGain: 1.000506
PlatenID: emmabat211216
PhotoFilename: 101.Low Mag.pho
SXIFilename:
SourceAnalyserAngle: 45.0 d
AnalyserSolidAngle: 0.38 sr
IntensityRecal: no
IntensityCalCoeff: 104.036 0.653
EnergyRecal: no
ScanDeflectionSpan: 30 60
ScanDeflectionOffset: 0 -20
SCAMultiplierVoltage: 1875.0 V
NarrowAcceptanceAngle: no
PeakToNoiseRatioState: no
DelayBeforeAcquire: 5 seconds
C60IonGun: 10kV C60 Ion Gun
BiasBoxMode: 0
TFCParameters: 0, 1, 2, 93.73, 7.481, 1, 1
SemFieldOfView: 0.0000000
ImageSizeXY: 0.0000 0.0000
IonGunMode: Neutralize
SputterIon: Ar+
SputterCurrent: 0.000 uA
SputterRate: 0.000 A/min
SputterEnergy: 0.110 kV
FloatVolt: -102.0 V
FloatEnable: yes
GridVolt: 120.0
CondensorVolt: 72.05
ObjectiveVolt: 99.00
BendVolt: 1.65
SputterRaster: 0.00 0.00 mm
SputterRasterOffset: 1.200 -0.100 mm
TargetSputterTime: 0.0 min
SputterEmission: 0.00 mA
DeflectionBias: 47.0 V
IonGunGasPressure: 0.000 mPa
NeutIon: Ar+
NeutCurrent: 0.000 uA
NeutRate: 0.000 A/min
NeutEnergy: 0.110 kV
NeutFloatVolt: -102.0 V
NeutFloatEnable: yes
NeutGridVolt: 120.0
NeutCondensorVolt: 72.05
NeutObjectiveVolt: 99.00
NeutBendVolt: 1.65
NeutRaster: 0.00 0.00 mm
NeutRasterOffset: 1.200 -0.100 mm
NeutTargetTimedOnTime: 0.0 min
NeutEmission: 0.00 mA
NeutDeflectionBias: 47.0 V
NeutIonGunGasPressure: 0.000 mPa
XpsScanMode: scanned
AnalyserMode: FAT
SurvNumCycles: 3
SurvTimePerStep: 50.000000
NoSpectralRegFull: 1
SpectralRegDefFull: 1 1 Su1s 111 1379 -0.8000 1100.0000 -3.0000 1099.0000 -2.0000 0.000000 187.85 AREA
SpectralRegDef2Full: 1 1103.0 1 0 1 1
SpectralRegBackgroundFull: 1 0.0 548.5 0.0
SpectralRegHeroFull: 1 548.5 0.0 0.0 0.00
SpectralRegIRFull: 1 0 0.000 0.000 0.0
NoSpectralReg: 1
SpectralRegDef: 1 1 Su1s 111 1379 -0.8000 1100.0000 -3.0000 1099.0000 -2.0000 0.150000 187.85 AREA
SpectralRegDef2: 1 1103.0 1 0 1 1
SpectralRegBackground: 1 0.0 548.5 0.0
SpectralRegHero: 1 548.5 0.0 0.0 0.00
SpectralRegIR: 1 1 0.000 0.000 0.0
NoSpatialArea: 1
SpatialAreaDef: 1 1 1 (436.4 -582.3 16948.3 45.0 0.0)
SpatialAreaDesc: 1
SpatialHRPhotoCor: 1 (0.0 0.0)
XraySource: Al 1486.6 mono
XrayAnodePosition: 5
XrayPower: 50.38 W
XrayBeamDiameter: 200.0 um
XRayBeamVoltage: 15000.0 V
XRayCondenserLensVoltage: 7600.0 V
XRayObjectiveCoilCurrent: 0.707 A
XRayBlankingVoltage: 290.0 V
XRayFilamentCurrent: 1.522 A
XRayStigmator: -0.3 0.0
XRayOffsetInUm: -130 10
XRayMagFactor: 0.367 0.351
XRayDelayFactor: 1400 0
XRayRotationInDeg: -20.75 V
XRayHighPower: no
XRayEmissionControl: yes
XRayEmissionCurrent: 4.000 mA
XRayStepDelayReadBeam: 5
XRayStepsPerDiameter: 1.0
XRayInterlaceInterval: 1
XRayMaxFilamentCurrent: 1.750 A
XRaySetting: 200u50W15KV
EgunNeutMode: Neutralize
NeutralizerCurrent: 20.0 uA
NeutralizerEnergy: 1.00 V
EgunNeutExtractor: 45.0 V
EgunNeutXSteering: 20.0
EgunNeutYSteering: -8.0
EgunNeutFilament: 1.13 A
EgunNeutPulseLength: 10.0 msec
EgunNeutPulseFrequency: 2
SxiPersistence: 1
SxiSecPerDisplay: 1.0
SxiAutoContrast: yes
SxiAutoContrastLow: 0.30
SxiAutoContrastHigh: 0.30
SxiBindingEnergy: 410.0 eV
SxiPassEnergy: 376 eV
SxiLens2: -804 V
SxiLens3: -761 V
SxiLensBias: 200 V
SxiShutterBias: no
SxiShutterBiasVoltage: 250.0 V
SxiDisplayMode: 2
Detector Acq Time: 20.0 (min)
Number Of Channels: 16
Channel Info: 1 1 1.688
Channel Info: 2 1 1.270
Channel Info: 3 1 1.225
Channel Info: 4 1 1.068
Channel Info: 5 1 1.078
Channel Info: 6 1 0.946
Channel Info: 7 1 0.996
Channel Info: 8 1 0.983
Channel Info: 9 1 1.103
Channel Info: 10 1 1.052
Channel Info: 11 1 0.980
Channel Info: 12 1 0.735
Channel Info: 13 1 0.768
Channel Info: 14 1 0.698
Channel Info: 15 1 0.850
Channel Info: 16 1 1.405
StagePosition: 0.2170 1.2722 16.9483 45.0031 -0.0500
StageCurrentRotationSpeed: 1.0000
DefectPosID: 1
DefectPosComment:
DefectPosU: 0.4341
DefectPosV: 0.5814
DefectPosX: 0.2170
DefectPosY: 1.2722
DefectPosZ: 16.9483
DefectPosTilt: 45.0031
DefectPosRotation: -0.0500
DefectPosAligment: None
DefectPosReferenceImage: 101.Low Mag.pho
C60IonGunMode: Off
C60IonCurrent: 0.0 uA
C60SputterRate: 0.0 A/min
C60Beam: 10.000 kV
C60Temperature: 383.0 C
C60Repellor: -76.0 V
C60Grid: 120.0 V
C60Lens2: 6.215 kV
C60Extractor: -833.0 kV
C60Deflector: -91.0 -124.0 V
C60BlankingDeflector: no yes
C60Raster: 0.8 2.3 mm
C60RasterOffset: 0.4 -0.2 mm
C60Emission: 10.00 mA
C60Filament: 2.80 A
Deconvolution: no
DeconvolutionPassEnergy: 2.95 eV
AutoIonNeut: yes
Presputter: no
EOFH
NORM
REGULAR
0
0
0
0
0
0
1
Su1s 1
C:\Datafiles\users\MIT\berggren\emmabat\211216\102.1.ITOSA5ei.spe:1:1:ITOSA5ei
2021
12
16
0
0
0
0
10
Casa Info Follows
0
0
0
0
ITOSA5ei
( 0.00217 m , 0.012722 m , 0.169483 m ) Angle: 45.0031 degrees , -0.05 degrees
emmabat211216
1
1
XPS
Al
1486.6
50.38
200
200
1e+037
1e+037
FAT
187.85
1e+037
4.399
1e+037
1e+037
1e+037
1e+037
1e+037
Su1s

-1
Kinetic Energy
eV
386.6
0.8
2
Intensity
d
Transmission
d
pulse counting
0.15
1
1e+037
1e+037
1e+037
1e+037
2
ESCAPE DEPTH TYPE
d
0
PHI_AtomicNumber
d
111
0
0
9556
9869
9422
9613
9564
9609
9694
9495
9387
9487
9536
9420
9518
9768
10019
10182
10494
10818
10916
10924
10944
10656
10561
10204
9865
9885
9929
10109
9763
9637
9449
9169
8919
8687
8718
8592
8522
8271
8547
8305
8525
8384
8436
8482
8386
8399
8554
8178
8504
8413
8423
8450
8612
8373
8552
8351
8327
8390
8452
8403
8377
8368
8376
8509
8387
8379
8335
8269
8321
8605
8399
8581
8410
8411
8609
8520
8459
8530
8688
8538
8626
8500
8597
8530
8573
8579
8672
8536
8785
8553
8633
8800
8704
8842
8709
8888
8832
8680
8692
8908
8837
8862
8993
8912
8766
8948
8984
9158
9202
9042
9345
9159
9185
9195
9094
9052
9032
9117
9152
9108
9127
9205
8959
9247
9182
9193
9378
9310
9596
9451
9400
9399
9543
9459
9476
9475
9271
9212
9508
9173
9219
9175
9195
9217
9301
9442
9268
9564
9416
9340
9352
9514
9400
9709
9675
9636
9955
10083
10037
10038
9951
9921
9728
9611
9552
9150
9339
9007
9102
8797
8844
8802
8883
8862
8850
8872
8840
8783
8797
8685
8947
8798
8776
8900
8716
8947
8874
8905
8965
8882
8807
8804
8779
8816
8994
8998
8947
9195
8808
8949
8988
9175
9027
9086
9161
9030
9209
9164
9142
9047
9107
8977
9342
9046
9092
9080
9106
9085
9196
9197
9298
9309
9140
9273
9301
9280
9346
9532
9370
9428
9343
9320
9282
9339
9360
9512
9485
9500
9466
9590
9548
9525
9463
9527
9395
9385
9482
9422
9668
9550
9577
9579
9754
9565
9923
9837
9617
9563
9776
9649
9772
9728
9839
9582
9815
9723
9601
9616
9786
9846
9674
9717
9980
9921
9710
10043
9783
9906
9977
10020
10010
9901
9977
9907
9943
9976
10037
10036
9923
9957
9854
10041
9968
10050
10106
9987
10091
10212
10218
10251
10258
10270
10312
10336
10073
10219
10291
10409
10144
10312
10181
10397
10267
10470
10125
10428
10213
10428
10483
10290
10195
10457
10331
10175
10185
10442
10418
10595
10468
10540
10592
10357
10386
10556
10678
10500
10574
10648
10621
10719
10854
10733
10901
10547
10869
10824
10711
10747
10500
10691
10455
10672
10768
10629
10410
10642
10474
10647
10668
10612
10523
10621
10486
10740
10532
10712
10672
10612
10642
10563
10647
10736
10736
10437
10723
10717
10699
10673
10841
10719
10646
10864
10746
10969
10741
10585
10805
10666
10782
10935
10825
10750
10930
10814
10789
10757
10987
11070
10933
10905
10968
11155
11174
11172
10991
10914
11021
10935
11041
11014
11146
10967
11197
11115
11038
11233
11067
11145
10948
11256
11146
11277
11258
11156
11182
11249
11241
11290
11347
11448
11252
11498
11442
11502
11336
11473
11439
11369
11586
11206
11546
11467
11350
11351
11323
11393
11272
11506
11409
11500
11701
11588
11611
11576
11574
11487
11582
11685
11598
11427
11670
11424
11394
11523
11750
11687
11626
11816
11732
11571
11462
11812
11550
11785
11559
12054
11826
11641
11797
11796
11864
11939
11797
11935
11876
11493
11539
11836
11559
11475
11645
11633
11874
11927
12327
12644
13327
13857
13419
13363
12689
12057
12025
11616
11303
11426
11383
11215
11251
11322
11365
11153
11467
11466
11319
11288
11252
11280
11247
11484
11377
11422
11193
11395
11210
11304
11043
11071
10906
10906
11028
11132
10690
10792
10776
10653
10748
10781
10812
11036
11568
11998
12843
13874
14929
14858
14430
13447
12404
11525
10972
10578
10433
10257
10005
10014
9958
9947
10019
9859
9984
9768
9770
9700
9872
9741
9836
9849
9638
9734
9737
9716
9503
9821
9668
9819
9603
10043
9505
9759
9746
9907
9650
9739
9642
9948
9943
9993
9828
10047
9935
9804
9812
9834
9841
9924
9760
9967
10123
10072
10124
10307
10091
9947
10100
10201
10114
10214
10208
9974
9834
10004
9893
10050
9992
10392
10100
10051
10242
10193
10184
10309
10113
10267
10459
10230
10272
10286
10426
10477
10234
10283
10489
10307
10374
10244
10294
10253
10231
10293
10334
10328
10198
10273
10458
10186
10419
10291
10499
10483
10511
10469
10528
10582
10478
10349
10483
10518
10543
10555
10635
10601
10650
10632
10613
10465
10581
10517
10531
10653
10646
10516
10634
10717
10676
10674
10684
10731
10587
10758
10987
10622
10868
10897
10732
10851
10981
10934
10992
11062
10862
10895
11013
10692
10800
10653
10620
10589
10367
10286
10412
10259
10245
10196
10100
10292
10126
10118
10307
10892
11608
13142
14280
14899
14456
13299
11791
10541
9971
9921
10029
9796
9763
9891
9691
9621
9713
9676
9696
9652
9744
9630
9773
9923
9804
9914
9765
9694
9696
9736
9570
9776
9766
9497
9691
9762
9793
9905
9732
9578
9789
9670
9718
9779
9656
9851
9908
10265
10283
10436
10367
9912
9747
9560
9336
9454
9498
9923
10421
10823
10620
10148
9892
9517
9266
9345
9404
9151
9251
9288
9217
9440
9314
9496
9410
9478
9642
9501
9517
9422
9625
9671
9526
9370
9420
9510
9304
9317
9185
8956
8547
8043
7907
7666
7650
7360
7551
7782
8064
9484
12860
17659
19549
16685
11553
7709
6118
6192
7585
11542
18504
24366
23478
16347
9205
5267
3861
3229
2983
2775
2529
2473
2270
2325
2286
2213
2152
2097
2068
2118
2018
2104
2055
2016
2136
2077
2063
1974
2067
2043
2021
1963
2033
2043
2093
1995
2008
2012
2090
2097
2092
1993
1969
2140
2115
2025
2051
2099
2122
2084
2082
2077
2105
2110
2060
2033
2013
2142
2115
2071
2118
2039
2009
2019
2078
2111
2077
2166
2101
2050
2121
2132
2094
2058
2200
2107
2175
2092
2125
2128
2099
2028
2133
2108
2152
2071
2164
2189
2112
2175
2139
2147
2140
2160
2177
2228
2185
2173
2208
2170
2255
2144
2276
2188
2166
2168
2196
2201
2228
2177
2152
2175
2270
2236
2246
2262
2240
2262
2221
2317
2271
2203
2200
2203
2286
2298
2267
2268
2275
2294
2345
2238
2305
2403
2322
2301
2303
2278
2323
2287
2265
2263
2375
2240
2344
2310
2365
2255
2437
2325
2413
2349
2344
2372
2334
2338
2331
2381
2381
2404
2351
2357
2364
2310
2428
2502
2403
2503
2477
2367
2455
2470
2522
2449
2520
2501
2427
2460
2542
2494
2418
2494
2390
2374
2382
2354
2396
2417
2325
2370
2304
2334
2302
2307
2432
2492
2652
2690
2864
3419
4294
4446
3825
2902
2472
2236
2272
2335
2306
2269
2278
2235
2204
2200
2227
2162
2231
2207
2253
2315
2287
2233
2288
2272
2333
2127
2186
2162
2279
2224
2296
2283
2222
2147
2150
2272
2259
2305
2290
2319
2274
2302
2325
2223
2282
2276
2355
2309
2340
2166
2295
2259
2302
2277
2243
2148
2334
2314
2360
2335
2274
2334
2278
2291
2432
2295
2386
2305
2423
2294
2351
2408
2366
2367
2437
2323
2283
2424
2343
2400
2438
2454
2436
2329
2361
2315
2415
2296
2366
2424
2367
2433
2437
2487
2434
2378
2454
2421
2472
2394
2409
2390
2470
2437
2450
2441
2477
2555
2457
2446
2485
2524
2437
2383
2401
2445
2347
2446
2399
2490
2362
2370
2424
2431
2489
2396
2529
2462
2528
2423
2548
2444
2442
2488
2448
2471
2492
2439
2439
2446
2523
2530
2518
2568
2416
2396
2535
2513
2495
2432
2522
2466
2547
2449
2570
2531
2465
2530
2579
2478
2639
2524
2595
2634
2735
2777
2850
2593
2650
2563
2668
2599
2539
2610
2462
2564
2518
2557
2653
2509
2486
2525
2477
2530
2457
2522
2503
2573
2648
2593
2520
2496
2570
2517
2532
2585
2600
2686
2624
2696
2675
2766
2820
2797
2840
2713
2654
2497
2441
2318
2474
2396
2361
2423
2456
2342
2344
2412
2324
2347
2343
2388
2309
2463
2409
2420
2373
2536
2514
2618
2573
2519
2515
2374
2344
2388
2325
2363
2399
2380
2373
2345
2363
2415
2417
2405
2420
2473
2438
2458
2489
2492
2459
2478
2417
2434
2485
2488
2539
2426
2307
2369
2179
2233
2101
2012
1882
1792
1731
1655
1613
1610
1523
1497
1384
1417
1401
1356
1380
1319
1320
1295
1325
1317
1292
1302
1327
1253
1373
1304
1331
1289
1317
1354
1353
1380
1334
1348
1387
1438
1373
1371
1380
1368
1488
1439
1473
1463
1452
1477
1458
1406
1373
1406
1334
1315
1253
1305
1244
1279
1363
1327
1392
1364
1311
1326
1264
1206
1145
1077
1187
1457
2285
3706
5323
5532
4362
2607
1365
671
431
353
291
265
247
265
290
295
329
308
342
331
278
204
120
95
52
51
36
187.141
end of experiment