File: example_data/211216/103.1.itosa5ei_depth.vms
VAMAS Surface Chemical Analysis Standard Data Transfer Format 1988 May 4
MIT
PHI VersaProbe II
Emma Batson
FILE:C:\Datafiles\users\MIT\berggren\emmabat\211216\Temp103.1.ITOSA5ei_1.pro;BATCH:211216;DESC:ITOSA5ei;
224
SOFH
Platform: PC
Technique: XPS
TechniqueEx: XPS
FileType: DEPTHPRO
FileDesc: ITOSA5ei
SoftwareVersion: SS 2.10.4.1
InstrumentModel: PHI VersaProbe II
AcqFilename: C:\Datafiles\users\MIT\berggren\emmabat\211216\Temp103.1.ITOSA5ei_1.pro
FileDate: 2021 12 16
AcqFileDate: 2021 12 16
Institution: MIT
Operator: Emma Batson
ExperimentID: 211216
EnergyReference: none 0.0
AnalyserWorkFcn: 4.399 eV
AnalyserRetardGain: 1.000506
PlatenID: emmabat211216
PhotoFilename: 101.Low Mag.pho
SXIFilename:
SourceAnalyserAngle: 45.0 d
AnalyserSolidAngle: 0.38 sr
IntensityRecal: no
IntensityCalCoeff: 104.036 0.653
EnergyRecal: no
ScanDeflectionSpan: 30 60
ScanDeflectionOffset: 0 -20
SCAMultiplierVoltage: 1875.0 V
NarrowAcceptanceAngle: no
PeakToNoiseRatioState: no
DelayBeforeAcquire: 5 seconds
C60IonGun: 10kV C60 Ion Gun
BiasBoxMode: 0
TFCParameters: 0, 1, 2, 93.73, 7.481, 1, 1
SemFieldOfView: 0.0000000
ImageSizeXY: 0.0000 0.0000
IonGunMode: Neutralize
SputterIon: Ar+
SputterCurrent: 0.000 uA
SputterRate: 0.000 A/min
SputterEnergy: 0.110 kV
FloatVolt: -102.0 V
FloatEnable: yes
GridVolt: 120.0
CondensorVolt: 72.05
ObjectiveVolt: 99.00
BendVolt: 1.65
SputterRaster: 0.00 0.00 mm
SputterRasterOffset: 1.200 -0.100 mm
TargetSputterTime: 0.0 min
SputterEmission: 0.00 mA
DeflectionBias: 47.0 V
IonGunGasPressure: 0.000 mPa
NeutIon: Ar+
NeutCurrent: 0.000 uA
NeutRate: 0.000 A/min
NeutEnergy: 0.110 kV
NeutFloatVolt: -102.0 V
NeutFloatEnable: yes
NeutGridVolt: 120.0
NeutCondensorVolt: 72.05
NeutObjectiveVolt: 99.00
NeutBendVolt: 1.65
NeutRaster: 0.00 0.00 mm
NeutRasterOffset: 1.200 -0.100 mm
NeutTargetTimedOnTime: 0.0 min
NeutEmission: 0.00 mA
NeutDeflectionBias: 47.0 V
NeutIonGunGasPressure: 0.000 mPa
XpsScanMode: scanned
AnalyserMode: FAT
SurvTimePerStep: 50.000000
NoDPDataCyc: 31
NoPreSputterCyc: 1
ProfSputterDelay: 10.0
ProfXrayOffDuringSputter: no
ProfSourceBlankDuringSputter: no
ProfZalarHighAccuracyInterval: 20
SampleRotation: off
DepthRecal: no
SputterMode: AlternatingZalar
NoDepthReg: 1
DepthCalDef: 1 Layer1 1 0.0000 0.0000 Ar+ 30.00 1.00 30 '1000V-1uA-2x2' 1.000 120 15.00 0 0 645 720 12 2.0 2.0 0.55 -0.65 0.00 0.00 Ar
NoSpectralRegFull: 4
SpectralRegDefFull: 1 1 In3d5 49 51 -0.4000 456.0000 436.0000 455.0000 437.0000 0.000000 93.90 AREA
SpectralRegDef2Full: 1 20.0 3 0 2 500
SpectralRegBackgroundFull: 1 0.0 446.0 0.0
SpectralRegHeroFull: 1 446.0 0.0 0.0 0.00
SpectralRegIRFull: 1 0 0.000 0.000 0.0
SpectralRegDefFull: 2 1 Sn3d 50 51 -0.4000 499.0000 479.0000 498.0000 480.0000 0.000000 93.90 AREA
SpectralRegDef2Full: 2 20.0 12 0 2 500
SpectralRegBackgroundFull: 2 0.0 489.0 0.0
SpectralRegHeroFull: 2 489.0 0.0 0.0 0.00
SpectralRegIRFull: 2 0 0.000 0.000 0.0
SpectralRegDefFull: 3 1 O1s 8 51 -0.4000 540.0000 520.0000 539.0000 521.0000 0.000000 93.90 AREA
SpectralRegDef2Full: 3 20.0 6 0 2 500
SpectralRegBackgroundFull: 3 0.0 530.0 0.0
SpectralRegHeroFull: 3 530.0 0.0 0.0 0.00
SpectralRegIRFull: 3 0 0.000 0.000 0.0
SpectralRegDefFull: 4 1 C1s 6 41 -0.5000 295.0000 275.0000 294.0000 276.0000 0.000000 117.40 AREA
SpectralRegDef2Full: 4 20.0 2 0 1 500
SpectralRegBackgroundFull: 4 0.0 285.0 0.0
SpectralRegHeroFull: 4 285.0 0.0 0.0 0.00
SpectralRegIRFull: 4 0 0.000 0.000 0.0
NoSpectralReg: 4
SpectralRegDef: 1 1 In3d5 49 51 -0.4000 456.0000 436.0000 455.0000 437.0000 0.300000 93.90 AREA
SpectralRegDef2: 1 20.0 3 0 2 500
SpectralRegBackground: 1 0.0 446.0 0.0
SpectralRegHero: 1 446.0 0.0 0.0 0.00
SpectralRegIR: 1 1 0.000 0.000 0.0
SpectralRegDef: 2 1 Sn3d 50 51 -0.4000 499.0000 479.0000 498.0000 480.0000 1.200000 93.90 AREA
SpectralRegDef2: 2 20.0 12 0 2 500
SpectralRegBackground: 2 0.0 489.0 0.0
SpectralRegHero: 2 489.0 0.0 0.0 0.00
SpectralRegIR: 2 1 0.000 0.000 0.0
SpectralRegDef: 3 1 O1s 8 51 -0.4000 540.0000 520.0000 539.0000 521.0000 0.600000 93.90 AREA
SpectralRegDef2: 3 20.0 6 0 2 500
SpectralRegBackground: 3 0.0 530.0 0.0
SpectralRegHero: 3 530.0 0.0 0.0 0.00
SpectralRegIR: 3 1 0.000 0.000 0.0
SpectralRegDef: 4 1 C1s 6 41 -0.5000 295.0000 275.0000 294.0000 276.0000 0.100000 117.40 AREA
SpectralRegDef2: 4 20.0 2 0 1 500
SpectralRegBackground: 4 0.0 285.0 0.0
SpectralRegHero: 4 285.0 0.0 0.0 0.00
SpectralRegIR: 4 1 0.000 0.000 0.0
NoSpatialArea: 1
SpatialAreaDef: 1 1 1 (436.4 -582.3 16948.3 45.0 0.0)
SpatialAreaDesc: 1
SpatialHRPhotoCor: 1 (0.0 0.0)
XraySource: Al 1486.6 mono
XrayAnodePosition: 5
XrayPower: 50.38 W
XrayBeamDiameter: 200.0 um
XRayBeamVoltage: 15000.0 V
XRayCondenserLensVoltage: 7600.0 V
XRayObjectiveCoilCurrent: 0.707 A
XRayBlankingVoltage: 290.0 V
XRayFilamentCurrent: 1.521 A
XRayStigmator: -0.3 0.0
XRayOffsetInUm: -130 10
XRayMagFactor: 0.367 0.351
XRayDelayFactor: 1400 0
XRayRotationInDeg: -20.75 V
XRayHighPower: no
XRayEmissionControl: yes
XRayEmissionCurrent: 4.000 mA
XRayStepDelayReadBeam: 5
XRayStepsPerDiameter: 1.0
XRayInterlaceInterval: 1
XRayMaxFilamentCurrent: 1.750 A
XRaySetting: 200u50W15KV
EgunNeutMode: Neutralize
NeutralizerCurrent: 20.0 uA
NeutralizerEnergy: 1.00 V
EgunNeutExtractor: 45.0 V
EgunNeutXSteering: 20.0
EgunNeutYSteering: -8.0
EgunNeutFilament: 1.13 A
EgunNeutPulseLength: 10.0 msec
EgunNeutPulseFrequency: 2
SxiPersistence: 1
SxiSecPerDisplay: 1.0
SxiAutoContrast: yes
SxiAutoContrastLow: 0.30
SxiAutoContrastHigh: 0.30
SxiBindingEnergy: 410.0 eV
SxiPassEnergy: 376 eV
SxiLens2: -804 V
SxiLens3: -761 V
SxiLensBias: 200 V
SxiShutterBias: no
SxiShutterBiasVoltage: 250.0 V
SxiDisplayMode: 2
Detector Acq Time: 20.0 (min)
Number Of Channels: 16
Channel Info: 1 1 1.688
Channel Info: 2 1 1.270
Channel Info: 3 1 1.225
Channel Info: 4 1 1.068
Channel Info: 5 1 1.078
Channel Info: 6 1 0.946
Channel Info: 7 1 0.996
Channel Info: 8 1 0.983
Channel Info: 9 1 1.103
Channel Info: 10 1 1.052
Channel Info: 11 1 0.980
Channel Info: 12 1 0.735
Channel Info: 13 1 0.768
Channel Info: 14 1 0.698
Channel Info: 15 1 0.850
Channel Info: 16 1 1.405
StagePosition: 0.2170 1.2722 16.9483 45.0031 -0.0500
StageCurrentRotationSpeed: 1.0000
DefectPosID: 1
DefectPosComment:
DefectPosU: 0.4341
DefectPosV: 0.5814
DefectPosX: 0.2170
DefectPosY: 1.2722
DefectPosZ: 16.9483
DefectPosTilt: 45.0031
DefectPosRotation: -0.0500
DefectPosAligment: None
DefectPosReferenceImage: 101.Low Mag.pho
C60IonGunMode: Off
C60IonCurrent: 0.0 uA
C60SputterRate: 0.0 A/min
C60Beam: 10.000 kV
C60Temperature: 383.0 C
C60Repellor: -76.0 V
C60Grid: 120.0 V
C60Lens2: 6.215 kV
C60Extractor: -833.0 kV
C60Deflector: -91.0 -124.0 V
C60BlankingDeflector: no yes
C60Raster: 0.8 2.3 mm
C60RasterOffset: 0.4 -0.2 mm
C60Emission: 10.00 mA
C60Filament: 2.80 A
Deconvolution: no
DeconvolutionPassEnergy: 2.95 eV
AutoIonNeut: yes
Presputter: no
EOFH
NORM
REGULAR
0
1
Etch Time
s
0
0
0
0
124
In 3d5 1
C:\Datafiles\users\MIT\berggren\emmabat\211216\Temp103.1.ITOSA5ei_1.pro:1:1:ITOSA5ei
2021
12
16
0
0
0
0
9
Casa Info Follows
0
0
0
0
ITOSA5ei
( 0.00217 m , 0.012722 m , 0.169483 m ) Angle: 45.0031 degrees , -0.05 degrees
emmabat211216
1 1
XPS
0
Al
1486.6
50.38
200
200
1e+037
1e+037
FAT
93.9
1e+037
4.399
1e+037
1e+037
1e+037
1e+037
1e+037
In
3d5
-1
Kinetic Energy
eV
1030.6
0.4
2
Intensity
d
Transmission
d
pulse counting
0.3
1
1e+037
1e+037
1e+037
1e+037
2
ESCAPE DEPTH TYPE
d
0
PHI_AtomicNumber
d
49
102
0
1
0
1
7058
93.2238
7070
93.2233
7111
93.2227
7129
93.2222
7277
93.2217
7303
93.2212
7507
93.2207
7658
93.2201
8068
93.2196
8772
93.2191
10559
93.2186
13678
93.218
18248
93.2175
23087
93.217
25747
93.2165
24731
93.216
20174
93.2154
15194
93.2149
10986
93.2144
7816
93.2139
5931
93.2133
5450
93.2128
5097
93.2123
5031
93.2118
4998
93.2112
5219
93.2107
5674
93.2102
6551
93.2097
8231
93.2091
11346
93.2086
16624
93.2081
23763
93.2076
30390
93.207
34204
93.2065
31532
93.206
24842
93.2055
17678
93.2049
11738
93.2044
7509
93.2039
4961
93.2033
4024
93.2028
3472
93.2023
3203
93.2018
2983
93.2012
2733
93.2007
2542
93.2002
2607
93.1997
2439
93.1991
2309
93.1986
2230
93.1981
2183
93.1975
In 3d5 2
C:\Datafiles\users\MIT\berggren\emmabat\211216\Temp103.1.ITOSA5ei_1.pro:1:1:ITOSA5ei
2021
12
16
0
0
0
0
9
Casa Info Follows
0
0
0
0
ITOSA5ei
( 0.00217 m , 0.012722 m , 0.169483 m ) Angle: 45.0031 degrees , -0.05 degrees
emmabat211216
1 1
XPS
60
Al
1486.6
50.38
200
200
1e+037
1e+037
FAT
93.9
1e+037
4.399
1e+037
1e+037
1e+037
1e+037
1e+037
In
3d5
-1
Kinetic Energy
eV
1030.6
0.4
2
Intensity
d
Transmission
d
pulse counting
0.3
1
1e+037
1e+037
1e+037
1e+037
2
ESCAPE DEPTH TYPE
d
0
PHI_AtomicNumber
d
49
102
0
1
0
1
13322
93.2238
13365
93.2233
13770
93.2227
14646
93.2222
15160
93.2217
15976
93.2212
16469
93.2207
16585
93.2201
16484
93.2196
16898
93.2191
18933
93.2186
22666
93.218
30007
93.2175
39728
93.217
45814
93.2165
46790
93.216
43537
93.2154
37136
93.2149
26823
93.2144
17066
93.2139
12464
93.2133
10912
93.2128
10059
93.2123
9585
93.2118
9611
93.2112
9556
93.2107
10417
93.2102
11312
93.2097
13271
93.2091
16868
93.2086
23310
93.2081
34944
93.2076
48125
93.207
56946
93.2065
57300
93.206
52970
93.2055
43464
93.2049
28218
93.2044
15227
93.2039
8839
93.2033
6713
93.2028
5259
93.2023
4729
93.2018
4065
93.2012
3640
93.2007
3422
93.2002
3091
93.1997
2831
93.1991
2741
93.1986
2705
93.1981
2462
93.1975
In 3d5 3
C:\Datafiles\users\MIT\berggren\emmabat\211216\Temp103.1.ITOSA5ei_1.pro:1:1:ITOSA5ei
2021
12
16
0
0
0
0
9
Casa Info Follows
0
0
0
0
ITOSA5ei
( 0.00217 m , 0.012722 m , 0.169483 m ) Angle: 45.0031 degrees , -0.05 degrees
emmabat211216
1 1
XPS
120
Al
1486.6
50.38
200
200
1e+037
1e+037
FAT
93.9
1e+037
4.399
1e+037
1e+037
1e+037
1e+037
1e+037
In
3d5
-1
Kinetic Energy
eV
1030.6
0.4
2
Intensity
d
Transmission
d
pulse counting
0.3
1
1e+037
1e+037
1e+037
1e+037
2
ESCAPE DEPTH TYPE
d
0
PHI_AtomicNumber
d
49
102
0
1
0
1
13736
93.2238
14222
93.2233
14735
93.2227
15237
93.2222
15859
93.2217
17090
93.2212
17747
93.2207
17949
93.2201
17920
93.2196
18388
93.2191
20398
93.2186
24345
93.218
31882
93.2175
40936
93.217
47320
93.2165
48568
93.216
46411
93.2154
40272
93.2149
28443
93.2144
18045
93.2139
13083
93.2133
11314
93.2128
10655
93.2123
10054
93.2118
9986
93.2112
10356
93.2107
10801
93.2102
12261
93.2097
14200
93.2091
17918
93.2086
24927
93.2081
36461
93.2076
49201
93.207
57642
93.2065
59214
93.206
56055
93.2055
46624
93.2049
29676
93.2044
15546
93.2039
9300
93.2033
6719
93.2028
5651
93.2023
4834
93.2018
4267
93.2012
3831
93.2007
3405
93.2002
3098
93.1997
2930
93.1991
2917
93.1986
2575
93.1981
2438
93.1975
In 3d5 4
C:\Datafiles\users\MIT\berggren\emmabat\211216\Temp103.1.ITOSA5ei_1.pro:1:1:ITOSA5ei
2021
12
16
0
0
0
0
9
Casa Info Follows
0
0
0
0
ITOSA5ei
( 0.00217 m , 0.012722 m , 0.169483 m ) Angle: 45.0031 degrees , -0.05 degrees
emmabat211216
1 1
XPS
180
Al
1486.6
50.38
200
200
1e+037
1e+037
FAT
93.9
1e+037
4.399
1e+037
1e+037
1e+037
1e+037
1e+037
In
3d5
-1
Kinetic Energy
eV
1030.6
0.4
2
Intensity
d
Transmission
d
pulse counting
0.3
1
1e+037
1e+037
1e+037
1e+037
2
ESCAPE DEPTH TYPE
d
0
PHI_AtomicNumber
d
49
102
0
1
0
1
14062
93.2238
14485
93.2233
14786
93.2227
15392
93.2222
16386
93.2217
17159
93.2212
18139
93.2207
17921
93.2201
18087
93.2196
18686
93.2191
20734
93.2186
25614
93.218
33073
93.2175
42507
93.217
48784
93.2165
49513
93.216
47366
93.2154
40383
93.2149
27973
93.2144
17562
93.2139
13038
93.2133
11212
93.2128
10522
93.2123
10233
93.2118
10201
93.2112
10250
93.2107
11265
93.2102
12384
93.2097
14782
93.2091
18717
93.2086
26139
93.2081
37928
93.2076
51076
93.207
59780
93.2065
60730
93.206
57078
93.2055
46470
93.2049
28466
93.2044
15064
93.2039
9210
93.2033
6769
93.2028
5605
93.2023
4795
93.2018
4244
93.2012
3870
93.2007
3471
93.2002
3243
93.1997
3017
93.1991
2879
93.1986
2644
93.1981
2475
93.1975
In 3d5 5
C:\Datafiles\users\MIT\berggren\emmabat\211216\Temp103.1.ITOSA5ei_1.pro:1:1:ITOSA5ei
2021
12
16
0
0
0
0
9
Casa Info Follows
0
0
0
0
ITOSA5ei
( 0.00217 m , 0.012722 m , 0.169483 m ) Angle: 45.0031 degrees , -0.05 degrees
emmabat211216
1 1
XPS
240
Al
1486.6
50.38
200
200
1e+037
1e+037
FAT
93.9
1e+037
4.399
1e+037
1e+037
1e+037
1e+037
1e+037
In
3d5
-1
Kinetic Energy
eV
1030.6
0.4
2
Intensity
d
Transmission
d
pulse counting
0.3
1
1e+037
1e+037
1e+037
1e+037
2
ESCAPE DEPTH TYPE
d
0
PHI_AtomicNumber
d
49
102
0
1
0
1
13834
93.2238
14410
93.2233
14734
93.2227
15403
93.2222
16342
93.2217
17330
93.2212
18125
93.2207
18132
93.2201
18099
93.2196
18959
93.2191
21496
93.2186
26016
93.218
34172
93.2175
43728
93.217
49585
93.2165
50873
93.216
47049
93.2154
39128
93.2149
26890
93.2144
16898
93.2139
12868
93.2133
11206
93.2128
10553
93.2123
10157
93.2118
10316
93.2112
10710
93.2107
11406
93.2102
12527
93.2097
15120
93.2091
19642
93.2086
27315
93.2081
39556
93.2076
53056
93.207
61419
93.2065
61672
93.206
57051
93.2055
44666
93.2049
26937
93.2044
14075
93.2039
8832
93.2033
6750
93.2028
5572
93.2023
4767
93.2018
4101
93.2012
3812
93.2007
3490
93.2002
3154
93.1997
2949
93.1991
2778
93.1986
2628
93.1981
2449
93.1975
In 3d5 6
C:\Datafiles\users\MIT\berggren\emmabat\211216\Temp103.1.ITOSA5ei_1.pro:1:1:ITOSA5ei
2021
12
16
0
0
0
0
9
Casa Info Follows
0
0
0
0
ITOSA5ei
( 0.00217 m , 0.012722 m , 0.169483 m ) Angle: 45.0031 degrees , -0.05 degrees
emmabat211216
1 1
XPS
300
Al
1486.6
50.38
200
200
1e+037
1e+037
FAT
93.9
1e+037
4.399
1e+037
1e+037
1e+037
1e+037
1e+037
In
3d5
-1
Kinetic Energy
eV
1030.6
0.4
2
Intensity
d
Transmission
d
pulse counting
0.3
1
1e+037
1e+037
1e+037
1e+037
2
ESCAPE DEPTH TYPE
d
0
PHI_AtomicNumber
d
49
102
0
1
0
1
13953
93.2238
14281
93.2233
14585
93.2227
15451
93.2222
16256
93.2217
16913
93.2212
17769
93.2207
18189
93.2201
18155
93.2196
18997
93.2191
21430
93.2186
26436
93.218
34893
93.2175
44512
93.217
50778
93.2165
51135
93.216
46719
93.2154
38728
93.2149
26377
93.2144
16733
93.2139
12728
93.2133
11380
93.2128
10855
93.2123
10023
93.2118
10467
93.2112
10619
93.2107
11309
93.2102
12921
93.2097
15376
93.2091
20221
93.2086
27791
93.2081
40710
93.2076
54410
93.207
62434
93.2065
62172
93.206
56810
93.2055
44167
93.2049
26219
93.2044
14239
93.2039
8803
93.2033
6730
93.2028
5526
93.2023
4793
93.2018
4145
93.2012
3759
93.2007
3390
93.2002
3135
93.1997
2920
93.1991
2781
93.1986
2618
93.1981
2483
93.1975
In 3d5 7
C:\Datafiles\users\MIT\berggren\emmabat\211216\Temp103.1.ITOSA5ei_1.pro:1:1:ITOSA5ei
2021
12
16
0
0
0
0
9
Casa Info Follows
0
0
0
0
ITOSA5ei
( 0.00217 m , 0.012722 m , 0.169483 m ) Angle: 45.0031 degrees , -0.05 degrees
emmabat211216
1 1
XPS
360
Al
1486.6
50.38
200
200
1e+037
1e+037
FAT
93.9
1e+037
4.399
1e+037
1e+037
1e+037
1e+037
1e+037
In
3d5
-1
Kinetic Energy
eV
1030.6
0.4
2
Intensity
d
Transmission
d
pulse counting
0.3
1
1e+037
1e+037
1e+037
1e+037
2
ESCAPE DEPTH TYPE
d
0
PHI_AtomicNumber
d
49
102
0
1
0
1
13840
93.2238
14249
93.2233
14784
93.2227
14982
93.2222
15936
93.2217
16816
93.2212
17688
93.2207
18078
93.2201
18083
93.2196
18892
93.2191
21570
93.2186
26884
93.218
35292
93.2175
44869
93.217
51413
93.2165
51399
93.216
46716
93.2154
37422
93.2149
25481
93.2144
16527
93.2139
12446
93.2133
11339
93.2128
10646
93.2123
10326
93.2118
10375
93.2112
10823
93.2107
11518
93.2102
13333
93.2097
15634
93.2091
20462
93.2086
28553
93.2081
41524
93.2076
55397
93.207
63598
93.2065
62671
93.206
56629
93.2055
43105
93.2049
25294
93.2044
13593
93.2039
8800
93.2033
6733
93.2028
5478
93.2023
4664
93.2018
4114
93.2012
3773
93.2007
3409
93.2002
3099
93.1997
2906
93.1991
2747
93.1986
2563
93.1981
2578
93.1975
In 3d5 8
C:\Datafiles\users\MIT\berggren\emmabat\211216\Temp103.1.ITOSA5ei_1.pro:1:1:ITOSA5ei
2021
12
16
0
0
0
0
9
Casa Info Follows
0
0
0
0
ITOSA5ei
( 0.00217 m , 0.012722 m , 0.169483 m ) Angle: 45.0031 degrees , -0.05 degrees
emmabat211216
1 1
XPS
420
Al
1486.6
50.38
200
200
1e+037
1e+037
FAT
93.9
1e+037
4.399
1e+037
1e+037
1e+037
1e+037
1e+037
In
3d5
-1
Kinetic Energy
eV
1030.6
0.4
2
Intensity
d
Transmission
d
pulse counting
0.3
1
1e+037
1e+037
1e+037
1e+037
2
ESCAPE DEPTH TYPE
d
0
PHI_AtomicNumber
d
49
102
0
1
0
1
13626
93.2238
14221
93.2233
14607
93.2227
14994
93.2222
15980
93.2217
16622
93.2212
17390
93.2207
17699
93.2201
17894
93.2196
18987
93.2191
21937
93.2186
27080
93.218
35561
93.2175
45599
93.217
51862
93.2165
51636
93.216
46513
93.2154
37020
93.2149
25201
93.2144
16140
93.2139
12605
93.2133
11247
93.2128
10540
93.2123
10198
93.2118
10292
93.2112
10615
93.2107
11504
93.2102
13014
93.2097
16085
93.2091
20914
93.2086
29336
93.2081
42104
93.2076
56415
93.207
64569
93.2065
63513
93.206
55744
93.2055
41981
93.2049
24931
93.2044
13348
93.2039
8435
93.2033
6631
93.2028
5375
93.2023
4709
93.2018
4119
93.2012
3705
93.2007
3358
93.2002
3090
93.1997
2942
93.1991
2735
93.1986
2632
93.1981
2487
93.1975
In 3d5 9
C:\Datafiles\users\MIT\berggren\emmabat\211216\Temp103.1.ITOSA5ei_1.pro:1:1:ITOSA5ei
2021
12
16
0
0
0
0
9
Casa Info Follows
0
0
0
0
ITOSA5ei
( 0.00217 m , 0.012722 m , 0.169483 m ) Angle: 45.0031 degrees , -0.05 degrees
emmabat211216
1 1
XPS
480
Al
1486.6
50.38
200
200
1e+037
1e+037
FAT
93.9
1e+037
4.399
1e+037
1e+037
1e+037
1e+037
1e+037
In
3d5
-1
Kinetic Energy
eV
1030.6
0.4
2
Intensity
d
Transmission
d
pulse counting
0.3
1
1e+037
1e+037
1e+037
1e+037
2
ESCAPE DEPTH TYPE
d
0
PHI_AtomicNumber
d
49
102
0
1
0
1
13514
93.2238
13920
93.2233
14371
93.2227
14939
93.2222
15553
93.2217
16457
93.2212
17373
93.2207
17519
93.2201
17618
93.2196
19160
93.2191
21751
93.2186
27647
93.218
35863
93.2175
46124
93.217
52537
93.2165
51681
93.216
46009
93.2154
35971
93.2149
23897
93.2144
15993
93.2139
12308
93.2133
11344
93.2128
10601
93.2123
10116
93.2118
10376
93.2112
10734
93.2107
11632
93.2102
13415
93.2097
15929
93.2091
21044
93.2086
29777
93.2081
43083
93.2076
57228
93.207
65128
93.2065
63412
93.206
54574
93.2055
40648
93.2049
23753
93.2044
12893
93.2039
8286
93.2033
6494
93.2028
5247
93.2023
4434
93.2018
4053
93.2012
3614
93.2007
3398
93.2002
3112
93.1997
2927
93.1991
2666
93.1986
2545
93.1981
2412
93.1975
In 3d5 10
C:\Datafiles\users\MIT\berggren\emmabat\211216\Temp103.1.ITOSA5ei_1.pro:1:1:ITOSA5ei
2021
12
16
0
0
0
0
9
Casa Info Follows
0
0
0
0
ITOSA5ei
( 0.00217 m , 0.012722 m , 0.169483 m ) Angle: 45.0031 degrees , -0.05 degrees
emmabat211216
1 1
XPS
540
Al
1486.6
50.38
200
200
1e+037
1e+037
FAT
93.9
1e+037
4.399
1e+037
1e+037
1e+037
1e+037
1e+037
In
3d5
-1
Kinetic Energy
eV
1030.6
0.4
2
Intensity
d
Transmission
d
pulse counting
0.3
1
1e+037
1e+037
1e+037
1e+037
2
ESCAPE DEPTH TYPE
d
0
PHI_AtomicNumber
d
49
102
0
1
0
1
13505
93.2238
13871
93.2233
14370
93.2227
15033
93.2222
15672
93.2217
16578
93.2212
17013
93.2207
17599
93.2201
17900
93.2196
19040
93.2191
22148
93.2186
27620
93.218
36411
93.2175
46702
93.217
53223
93.2165
51968
93.216
45366
93.2154
35623
93.2149
23838
93.2144
15663
93.2139
12236
93.2133
10964
93.2128
10466
93.2123
10106
93.2118
10423
93.2112
10872
93.2107
11473
93.2102
12931
93.2097
16183
93.2091
21327
93.2086
30690
93.2081
43882
93.2076
58718
93.207
66140
93.2065
63305
93.206
54672
93.2055
39591
93.2049
23069
93.2044
12699
93.2039
8300
93.2033
6513
93.2028
5286
93.2023
4609
93.2018
4132
93.2012
3658
93.2007
3347
93.2002
3057
93.1997
2915
93.1991
2671
93.1986
2567
93.1981
2367
93.1975
In 3d5 11
C:\Datafiles\users\MIT\berggren\emmabat\211216\Temp103.1.ITOSA5ei_1.pro:1:1:ITOSA5ei
2021
12
16
0
0
0
0
9
Casa Info Follows
0
0
0
0
ITOSA5ei
( 0.00217 m , 0.012722 m , 0.169483 m ) Angle: 45.0031 degrees , -0.05 degrees
emmabat211216
1 1
XPS
600
Al
1486.6
50.38
200
200
1e+037
1e+037
FAT
93.9
1e+037
4.399
1e+037
1e+037
1e+037
1e+037
1e+037
In
3d5
-1
Kinetic Energy
eV
1030.6
0.4
2
Intensity
d
Transmission
d
pulse counting
0.3
1
1e+037
1e+037
1e+037
1e+037
2
ESCAPE DEPTH TYPE
d
0
PHI_AtomicNumber
d
49
102
0
1
0
1
13151
93.2238
13679
93.2233
13912
93.2227
14717
93.2222
15335
93.2217
16479
93.2212
16900
93.2207
17294
93.2201
17875
93.2196
18904
93.2191
22394
93.2186
27856
93.218
36964
93.2175
47680
93.217
53486
93.2165
51509
93.216
44397
93.2154
34548
93.2149
22725
93.2144
15315
93.2139
12105
93.2133
10948
93.2128
10404
93.2123
10015
93.2118
10233
93.2112
10574
93.2107
11528
93.2102
13227
93.2097
16305
93.2091
21887
93.2086
31139
93.2081
44994
93.2076
59239
93.207
67391
93.2065
63386
93.206
53292
93.2055
38210
93.2049
22138
93.2044
12299
93.2039
8033
93.2033
6321
93.2028
5310
93.2023
4570
93.2018
3994
93.2012
3702
93.2007
3337
93.2002
3100
93.1997
2855
93.1991
2651
93.1986
2463
93.1981
2398
93.1975
In 3d5 12
C:\Datafiles\users\MIT\berggren\emmabat\211216\Temp103.1.ITOSA5ei_1.pro:1:1:ITOSA5ei
2021
12
16
0
0
0
0
9
Casa Info Follows
0
0
0
0
ITOSA5ei
( 0.00217 m , 0.012722 m , 0.169483 m ) Angle: 45.0031 degrees , -0.05 degrees
emmabat211216
1 1
XPS
660
Al
1486.6
50.38
200
200
1e+037
1e+037
FAT
93.9
1e+037
4.399
1e+037
1e+037
1e+037
1e+037
1e+037
In
3d5
-1
Kinetic Energy
eV
1030.6
0.4
2
Intensity
d
Transmission
d
pulse counting
0.3
1
1e+037
1e+037
1e+037
1e+037
2
ESCAPE DEPTH TYPE
d
0
PHI_AtomicNumber
d
49
102
0
1
0
1
13179
93.2238
13562
93.2233
13880
93.2227
14290
93.2222
15198
93.2217
16083
93.2212
16807
93.2207
16957
93.2201
17362
93.2196
18941
93.2191
22175
93.2186
28447
93.218
37340
93.2175
47599
93.217
54060
93.2165
51453
93.216
43694
93.2154
33291
93.2149
22154
93.2144
15014
93.2139
12024
93.2133
10800
93.2128
10350
93.2123
9947
93.2118
10219
93.2112
10738
93.2107
11630
93.2102
13335
93.2097
16647
93.2091
22244
93.2086
31518
93.2081
45997
93.2076
60548
93.207
68150
93.2065
63841
93.206
52285
93.2055
36760
93.2049
21394
93.2044
11824
93.2039
7907
93.2033
6188
93.2028
5322
93.2023
4454
93.2018
4041
93.2012
3552
93.2007
3308
93.2002
3006
93.1997
2867
93.1991
2635
93.1986
2488
93.1981
2347
93.1975
In 3d5 13
C:\Datafiles\users\MIT\berggren\emmabat\211216\Temp103.1.ITOSA5ei_1.pro:1:1:ITOSA5ei
2021
12
16
0
0
0
0
9
Casa Info Follows
0
0
0
0
ITOSA5ei
( 0.00217 m , 0.012722 m , 0.169483 m ) Angle: 45.0031 degrees , -0.05 degrees
emmabat211216
1 1
XPS
720
Al
1486.6
50.38
200
200
1e+037
1e+037
FAT
93.9
1e+037
4.399
1e+037
1e+037
1e+037
1e+037
1e+037
In
3d5
-1
Kinetic Energy
eV
1030.6
0.4
2
Intensity
d
Transmission
d
pulse counting
0.3
1
1e+037
1e+037
1e+037
1e+037
2
ESCAPE DEPTH TYPE
d
0
PHI_AtomicNumber
d
49
102
0
1
0
1
12808
93.2238
13344
93.2233
13637
93.2227
14437
93.2222
14811
93.2217
15713
93.2212
16348
93.2207
16904
93.2201
17278
93.2196
18967
93.2191
22472
93.2186
28396
93.218
37916
93.2175
48716
93.217
54627
93.2165
51840
93.216
43417
93.2154
32641
93.2149
21300
93.2144
14487
93.2139
11735
93.2133
10732
93.2128
10015
93.2123
9770
93.2118
10053
93.2112
10602
93.2107
11741
93.2102
13362
93.2097
16568
93.2091
22506
93.2086
32042
93.2081
46734
93.2076
61751
93.207
69184
93.2065
63180
93.206
50851
93.2055
35573
93.2049
20551
93.2044
11632
93.2039
7796
93.2033
6193
93.2028
5018
93.2023
4350
93.2018
3921
93.2012
3564
93.2007
3276
93.2002
2978
93.1997
2768
93.1991
2652
93.1986
2506
93.1981
2425
93.1975
In 3d5 14
C:\Datafiles\users\MIT\berggren\emmabat\211216\Temp103.1.ITOSA5ei_1.pro:1:1:ITOSA5ei
2021
12
16
0
0
0
0
9
Casa Info Follows
0
0
0
0
ITOSA5ei
( 0.00217 m , 0.012722 m , 0.169483 m ) Angle: 45.0031 degrees , -0.05 degrees
emmabat211216
1 1
XPS
780
Al
1486.6
50.38
200
200
1e+037
1e+037
FAT
93.9
1e+037
4.399
1e+037
1e+037
1e+037
1e+037
1e+037
In
3d5
-1
Kinetic Energy
eV
1030.6
0.4
2
Intensity
d
Transmission
d
pulse counting
0.3
1
1e+037
1e+037
1e+037
1e+037
2
ESCAPE DEPTH TYPE
d
0
PHI_AtomicNumber
d
49
102
0
1
0
1
12718
93.2238
13115
93.2233
13647
93.2227
13962
93.2222
14718
93.2217
15384
93.2212
15982
93.2207
16539
93.2201
17031
93.2196
18512
93.2191
22264
93.2186
28655
93.218
38249
93.2175
48891
93.217
54221
93.2165
51358
93.216
42003
93.2154
31134
93.2149
20886
93.2144
14355
93.2139
11657
93.2133
10429
93.2128
10040
93.2123
9930
93.2118
10010
93.2112
10557
93.2107
11731
93.2102
13433
93.2097
16790
93.2091
22706
93.2086
32385
93.2081
47663
93.2076
61991
93.207
69678
93.2065
63407
93.206
50185
93.2055
34513
93.2049
19924
93.2044
11355
93.2039
7590
93.2033
6157
93.2028
5083
93.2023
4368
93.2018
3857
93.2012
3590
93.2007
3151
93.2002
2997
93.1997
2843
93.1991
2517
93.1986
2364
93.1981
2351
93.1975
In 3d5 15
C:\Datafiles\users\MIT\berggren\emmabat\211216\Temp103.1.ITOSA5ei_1.pro:1:1:ITOSA5ei
2021
12
16
0
0
0
0
9
Casa Info Follows
0
0
0
0
ITOSA5ei
( 0.00217 m , 0.012722 m , 0.169483 m ) Angle: 45.0031 degrees , -0.05 degrees
emmabat211216
1 1
XPS
840
Al
1486.6
50.38
200
200
1e+037
1e+037
FAT
93.9
1e+037
4.399
1e+037
1e+037
1e+037
1e+037
1e+037
In
3d5
-1
Kinetic Energy
eV
1030.6
0.4
2
Intensity
d
Transmission
d
pulse counting
0.3
1
1e+037
1e+037
1e+037
1e+037
2
ESCAPE DEPTH TYPE
d
0
PHI_AtomicNumber
d
49
102
0
1
0
1
12702
93.2238
13097
93.2233
13221
93.2227
13792
93.2222
14038
93.2217
15219
93.2212
15803
93.2207
16493
93.2201
17020
93.2196
18892
93.2191
22003
93.2186
28932
93.218
38160
93.2175
49604
93.217
54989
93.2165
52051
93.216
41825
93.2154
30513
93.2149
20332
93.2144
14270
93.2139
11452
93.2133
10375
93.2128
9971
93.2123
10041
93.2118
10053
93.2112
10510
93.2107
11702
93.2102
13626
93.2097
16911
93.2091
23149
93.2086
32762
93.2081
47903
93.2076
63318
93.207
70045
93.2065
63550
93.206
49231
93.2055
33380
93.2049
18856
93.2044
11026
93.2039
7616
93.2033
6076
93.2028
4998
93.2023
4397
93.2018
3926
93.2012
3550
93.2007
3194
93.2002
2972
93.1997
2742
93.1991
2588
93.1986
2438
93.1981
2267
93.1975
In 3d5 16
C:\Datafiles\users\MIT\berggren\emmabat\211216\Temp103.1.ITOSA5ei_1.pro:1:1:ITOSA5ei
2021
12
16
0
0
0
0
9
Casa Info Follows
0
0
0
0
ITOSA5ei
( 0.00217 m , 0.012722 m , 0.169483 m ) Angle: 45.0031 degrees , -0.05 degrees
emmabat211216
1 1
XPS
900
Al
1486.6
50.38
200
200
1e+037
1e+037
FAT
93.9
1e+037
4.399
1e+037
1e+037
1e+037
1e+037
1e+037
In
3d5
-1
Kinetic Energy
eV
1030.6
0.4
2
Intensity
d
Transmission
d
pulse counting
0.3
1
1e+037
1e+037
1e+037
1e+037
2
ESCAPE DEPTH TYPE
d
0
PHI_AtomicNumber
d
49
102
0
1
0
1
12545
93.2238
13034
93.2233
13233
93.2227
13551
93.2222
14126
93.2217
14875
93.2212
15531
93.2207
15870
93.2201
16579
93.2196
18431
93.2191
22099
93.2186
28603
93.218
38702
93.2175
49755
93.217
55603
93.2165
51622
93.216
41400
93.2154
29350
93.2149
19602
93.2144
13609
93.2139
11274
93.2133
10232
93.2128
9983
93.2123
9815
93.2118
10139
93.2112
10515
93.2107
11511
93.2102
13589
93.2097
17196
93.2091
23267
93.2086
33347
93.2081
48432
93.2076
63629
93.207
70829
93.2065
63585
93.206
48351
93.2055
32040
93.2049
18745
93.2044
10851
93.2039
7485
93.2033
5983
93.2028
4913
93.2023
4189
93.2018
3877
93.2012
3388
93.2007
3239
93.2002
2959
93.1997
2803
93.1991
2555
93.1986
2402
93.1981
2235
93.1975
In 3d5 17
C:\Datafiles\users\MIT\berggren\emmabat\211216\Temp103.1.ITOSA5ei_1.pro:1:1:ITOSA5ei
2021
12
16
0
0
0
0
9
Casa Info Follows
0
0
0
0
ITOSA5ei
( 0.00217 m , 0.012722 m , 0.169483 m ) Angle: 45.0031 degrees , -0.05 degrees
emmabat211216
1 1
XPS
960
Al
1486.6
50.38
200
200
1e+037
1e+037
FAT
93.9
1e+037
4.399
1e+037
1e+037
1e+037
1e+037
1e+037
In
3d5
-1
Kinetic Energy
eV
1030.6
0.4
2
Intensity
d
Transmission
d
pulse counting
0.3
1
1e+037
1e+037
1e+037
1e+037
2
ESCAPE DEPTH TYPE
d
0
PHI_AtomicNumber
d
49
102
0
1
0
1
12621
93.2238
12577
93.2233
13058
93.2227
13350
93.2222
13642
93.2217
14649
93.2212
15290
93.2207
15848
93.2201
16575
93.2196
18471
93.2191
22218
93.2186
28768
93.218
38738
93.2175
50262
93.217
56172
93.2165
51350
93.216
40236
93.2154
28951
93.2149
19147
93.2144
13446
93.2139
11057
93.2133
10119
93.2128
9594
93.2123
9648
93.2118
9889
93.2112
10337
93.2107
11570
93.2102
13482
93.2097
17101
93.2091
23540
93.2086
33872
93.2081
48888
93.2076
64699
93.207
71872
93.2065
63523
93.206
47762
93.2055
31336
93.2049
18030
93.2044
10889
93.2039
7451
93.2033
5895
93.2028
4862
93.2023
4306
93.2018
3772
93.2012
3428
93.2007
3214
93.2002
2882
93.1997
2643
93.1991
2594
93.1986
2395
93.1981
2336
93.1975
In 3d5 18
C:\Datafiles\users\MIT\berggren\emmabat\211216\Temp103.1.ITOSA5ei_1.pro:1:1:ITOSA5ei
2021
12
16
0
0
0
0
9
Casa Info Follows
0
0
0
0
ITOSA5ei
( 0.00217 m , 0.012722 m , 0.169483 m ) Angle: 45.0031 degrees , -0.05 degrees
emmabat211216
1 1
XPS
1020
Al
1486.6
50.38
200
200
1e+037
1e+037
FAT
93.9
1e+037
4.399
1e+037
1e+037
1e+037
1e+037
1e+037
In
3d5
-1
Kinetic Energy
eV
1030.6
0.4
2
Intensity
d
Transmission
d
pulse counting
0.3
1
1e+037
1e+037
1e+037
1e+037
2
ESCAPE DEPTH TYPE
d
0
PHI_AtomicNumber
d
49
102
0
1
0
1
12350
93.2238
12576
93.2233
12918
93.2227
13118
93.2222
13645
93.2217
14320
93.2212
15175
93.2207
15587
93.2201
16522
93.2196
18398
93.2191
22524
93.2186
29016
93.218
39453
93.2175
50789
93.217
56458
93.2165
51224
93.216
40193
93.2154
27884
93.2149
18758
93.2144
13395
93.2139
11111
93.2133
10268
93.2128
9608
93.2123
9755
93.2118
9824
93.2112
10438
93.2107
11560
93.2102
13541
93.2097
17179
93.2091
23644
93.2086
34410
93.2081
49595
93.2076
65931
93.207
72083
93.2065
63237
93.206
46999
93.2055
30290
93.2049
17364
93.2044
10199
93.2039
7319
93.2033
5754
93.2028
4825
93.2023
4244
93.2018
3762
93.2012
3328
93.2007
3221
93.2002
2878
93.1997
2676
93.1991
2377
93.1986
2350
93.1981
2233
93.1975
In 3d5 19
C:\Datafiles\users\MIT\berggren\emmabat\211216\Temp103.1.ITOSA5ei_1.pro:1:1:ITOSA5ei
2021
12
16
0
0
0
0
9
Casa Info Follows
0
0
0
0
ITOSA5ei
( 0.00217 m , 0.012722 m , 0.169483 m ) Angle: 45.0031 degrees , -0.05 degrees
emmabat211216
1 1
XPS
1080
Al
1486.6
50.38
200
200
1e+037
1e+037
FAT
93.9
1e+037
4.399
1e+037
1e+037
1e+037
1e+037
1e+037
In
3d5
-1
Kinetic Energy
eV
1030.6
0.4
2
Intensity
d
Transmission
d
pulse counting
0.3
1
1e+037
1e+037
1e+037
1e+037
2
ESCAPE DEPTH TYPE
d
0
PHI_AtomicNumber
d
49
102
0
1
0
1
12074
93.2238
12320
93.2233
12608
93.2227
13138
93.2222
13429
93.2217
13927
93.2212
14759
93.2207
15263
93.2201
16212
93.2196
18237
93.2191
22581
93.2186
29207
93.218
39821
93.2175
50905
93.217
56584
93.2165
50999
93.216
39298
93.2154
27384
93.2149
18011
93.2144
13146
93.2139
10981
93.2133
10125
93.2128
9686
93.2123
9422
93.2118
9617
93.2112
10410
93.2107
11405
93.2102
13543
93.2097
17427
93.2091
24012
93.2086
34347
93.2081
50513
93.2076
66463
93.207
72577
93.2065
62713
93.206
45903
93.2055
28786
93.2049
16748
93.2044
9993
93.2039
7275
93.2033
5675
93.2028
4765
93.2023
4057
93.2018
3745
93.2012
3425
93.2007
3126
93.2002
2804
93.1997
2715
93.1991
2572
93.1986
2434
93.1981
2215
93.1975
In 3d5 20
C:\Datafiles\users\MIT\berggren\emmabat\211216\Temp103.1.ITOSA5ei_1.pro:1:1:ITOSA5ei
2021
12
16
0
0
0
0
9
Casa Info Follows
0
0
0
0
ITOSA5ei
( 0.00217 m , 0.012722 m , 0.169483 m ) Angle: 45.0031 degrees , -0.05 degrees
emmabat211216
1 1
XPS
1140
Al
1486.6
50.38
200
200
1e+037
1e+037
FAT
93.9
1e+037
4.399
1e+037
1e+037
1e+037
1e+037
1e+037
In
3d5
-1
Kinetic Energy
eV
1030.6
0.4
2
Intensity
d
Transmission
d
pulse counting
0.3
1
1e+037
1e+037
1e+037
1e+037
2
ESCAPE DEPTH TYPE
d
0
PHI_AtomicNumber
d
49
102
0
1
0
1
11822
93.2238
12114
93.2233
12460
93.2227
12863
93.2222
13139
93.2217
14147
93.2212
14434
93.2207
15195
93.2201
16035
93.2196
18157
93.2191
22275
93.2186
29224
93.218
39161
93.2175
51013
93.217
57110
93.2165
50819
93.216
38897
93.2154
26689
93.2149
17969
93.2144
13073
93.2139
10945
93.2133
9941
93.2128
9419
93.2123
9514
93.2118
9758
93.2112
10493
93.2107
11272
93.2102
13342
93.2097
17188
93.2091
24042
93.2086
34972
93.2081
50740
93.2076
66611
93.207
73612
93.2065
63587
93.206
45522
93.2055
28887
93.2049
16611
93.2044
9970
93.2039
7031
93.2033
5613
93.2028
4724
93.2023
4098
93.2018
3761
93.2012
3325
93.2007
2982
93.2002
2878
93.1997
2617
93.1991
2471
93.1986
2366
93.1981
2225
93.1975
In 3d5 21
C:\Datafiles\users\MIT\berggren\emmabat\211216\Temp103.1.ITOSA5ei_1.pro:1:1:ITOSA5ei
2021
12
16
0
0
0
0
9
Casa Info Follows
0
0
0
0
ITOSA5ei
( 0.00217 m , 0.012722 m , 0.169483 m ) Angle: 45.0031 degrees , -0.05 degrees
emmabat211216
1 1
XPS
1200
Al
1486.6
50.38
200
200
1e+037
1e+037
FAT
93.9
1e+037
4.399
1e+037
1e+037
1e+037
1e+037
1e+037
In
3d5
-1
Kinetic Energy
eV
1030.6
0.4
2
Intensity
d
Transmission
d
pulse counting
0.3
1
1e+037
1e+037
1e+037
1e+037
2
ESCAPE DEPTH TYPE
d
0
PHI_AtomicNumber
d
49
102
0
1
0
1
11794
93.2238
11942
93.2233
12475
93.2227
12511
93.2222
13110
93.2217
13432
93.2212
14185
93.2207
14675
93.2201
15846
93.2196
17877
93.2191
22189
93.2186
29428
93.218
39908
93.2175
51316
93.217
56736
93.2165
51030
93.216
37890
93.2154
25829
93.2149
17208
93.2144
12966
93.2139
10841
93.2133
9985
93.2128
9417
93.2123
9297
93.2118
9507
93.2112
10221
93.2107
11345
93.2102
13431
93.2097
17335
93.2091
24174
93.2086
35114
93.2081
50790
93.2076
67604
93.207
73392
93.2065
63444
93.206
44761
93.2055
27459
93.2049
15930
93.2044
9790
93.2039
7013
93.2033
5506
93.2028
4842
93.2023
4190
93.2018
3666
93.2012
3340
93.2007
3103
93.2002
2756
93.1997
2679
93.1991
2411
93.1986
2271
93.1981
2219
93.1975
In 3d5 22
C:\Datafiles\users\MIT\berggren\emmabat\211216\Temp103.1.ITOSA5ei_1.pro:1:1:ITOSA5ei
2021
12
16
0
0
0
0
9
Casa Info Follows
0
0
0
0
ITOSA5ei
( 0.00217 m , 0.012722 m , 0.169483 m ) Angle: 45.0031 degrees , -0.05 degrees
emmabat211216
1 1
XPS
1260
Al
1486.6
50.38
200
200
1e+037
1e+037
FAT
93.9
1e+037
4.399
1e+037
1e+037
1e+037
1e+037
1e+037
In
3d5
-1
Kinetic Energy
eV
1030.6
0.4
2
Intensity
d
Transmission
d
pulse counting
0.3
1
1e+037
1e+037
1e+037
1e+037
2
ESCAPE DEPTH TYPE
d
0
PHI_AtomicNumber
d
49
102
0
1
0
1
11701
93.2238
11716
93.2233
12003
93.2227
12243
93.2222
12645
93.2217
13374
93.2212
13851
93.2207
14477
93.2201
15709
93.2196
18084
93.2191
22072
93.2186
29011
93.218
39695
93.2175
51762
93.217
57002
93.2165
51313
93.216
37362
93.2154
25661
93.2149
16893
93.2144
12569
93.2139
10482
93.2133
9576
93.2128
9261
93.2123
9366
93.2118
9457
93.2112
10140
93.2107
11277
93.2102
13586
93.2097
17456
93.2091
24246
93.2086
35533
93.2081
51192
93.2076
68212
93.207
73740
93.2065
63885
93.206
44026
93.2055
27271
93.2049
15656
93.2044
9689
93.2039
6988
93.2033
5612
93.2028
4723
93.2023
4124
93.2018
3744
93.2012
3361
93.2007
2912
93.2002
2801
93.1997
2629
93.1991
2472
93.1986
2311
93.1981
2190
93.1975
In 3d5 23
C:\Datafiles\users\MIT\berggren\emmabat\211216\Temp103.1.ITOSA5ei_1.pro:1:1:ITOSA5ei
2021
12
16
0
0
0
0
9
Casa Info Follows
0
0
0
0
ITOSA5ei
( 0.00217 m , 0.012722 m , 0.169483 m ) Angle: 45.0031 degrees , -0.05 degrees
emmabat211216
1 1
XPS
1320
Al
1486.6
50.38
200
200
1e+037
1e+037
FAT
93.9
1e+037
4.399
1e+037
1e+037
1e+037
1e+037
1e+037
In
3d5
-1
Kinetic Energy
eV
1030.6
0.4
2
Intensity
d
Transmission
d
pulse counting
0.3
1
1e+037
1e+037
1e+037
1e+037
2
ESCAPE DEPTH TYPE
d
0
PHI_AtomicNumber
d
49
102
0
1
0
1
11445
93.2238
11633
93.2233
11987
93.2227
12212
93.2222
12548
93.2217
13223
93.2212
13799
93.2207
14290
93.2201
15546
93.2196
17860
93.2191
22270
93.2186
29691
93.218
40542
93.2175
52501
93.217
57481
93.2165
50972
93.216
37210
93.2154
24683
93.2149
16664
93.2144
12189
93.2139
10800
93.2133
9645
93.2128
9206
93.2123
9253
93.2118
9398
93.2112
9960
93.2107
11174
93.2102
13686
93.2097
17725
93.2091
24400
93.2086
35635
93.2081
52249
93.2076
68508
93.207
74458
93.2065
63075
93.206
44016
93.2055
25801
93.2049
15207
93.2044
9444
93.2039
6903
93.2033
5625
93.2028
4617
93.2023
4013
93.2018
3648
93.2012
3253
93.2007
2982
93.2002
2744
93.1997
2552
93.1991
2415
93.1986
2274
93.1981
2199
93.1975
In 3d5 24
C:\Datafiles\users\MIT\berggren\emmabat\211216\Temp103.1.ITOSA5ei_1.pro:1:1:ITOSA5ei
2021
12
16
0
0
0
0
9
Casa Info Follows
0
0
0
0
ITOSA5ei
( 0.00217 m , 0.012722 m , 0.169483 m ) Angle: 45.0031 degrees , -0.05 degrees
emmabat211216
1 1
XPS
1380
Al
1486.6
50.38
200
200
1e+037
1e+037
FAT
93.9
1e+037
4.399
1e+037
1e+037
1e+037
1e+037
1e+037
In
3d5
-1
Kinetic Energy
eV
1030.6
0.4
2
Intensity
d
Transmission
d
pulse counting
0.3
1
1e+037
1e+037
1e+037
1e+037
2
ESCAPE DEPTH TYPE
d
0
PHI_AtomicNumber
d
49
102
0
1
0
1
11422
93.2238
11604
93.2233
12015
93.2227
11972
93.2222
12666
93.2217
13065
93.2212
13445
93.2207
14171
93.2201
15427
93.2196
17948
93.2191
22422
93.2186
29603
93.218
40634
93.2175
52747
93.217
57672
93.2165
50500
93.216
36633
93.2154
23745
93.2149
16111
93.2144
12092
93.2139
10228
93.2133
9463
93.2128
9328
93.2123
9222
93.2118
9166
93.2112
9840
93.2107
11339
93.2102
13528
93.2097
17702
93.2091
24706
93.2086
36340
93.2081
52695
93.2076
69608
93.207
74695
93.2065
62936
93.206
42685
93.2055
25080
93.2049
14395
93.2044
9020
93.2039
6763
93.2033
5394
93.2028
4602
93.2023
3958
93.2018
3404
93.2012
3186
93.2007
2949
93.2002
2747
93.1997
2554
93.1991
2451
93.1986
2271
93.1981
2125
93.1975
In 3d5 25
C:\Datafiles\users\MIT\berggren\emmabat\211216\Temp103.1.ITOSA5ei_1.pro:1:1:ITOSA5ei
2021
12
16
0
0
0
0
9
Casa Info Follows
0
0
0
0
ITOSA5ei
( 0.00217 m , 0.012722 m , 0.169483 m ) Angle: 45.0031 degrees , -0.05 degrees
emmabat211216
1 1
XPS
1440
Al
1486.6
50.38
200
200
1e+037
1e+037
FAT
93.9
1e+037
4.399
1e+037
1e+037
1e+037
1e+037
1e+037
In
3d5
-1
Kinetic Energy
eV
1030.6
0.4
2
Intensity
d
Transmission
d
pulse counting
0.3
1
1e+037
1e+037
1e+037
1e+037
2
ESCAPE DEPTH TYPE
d
0
PHI_AtomicNumber
d
49
102
0
1
0
1
11283
93.2238
11409
93.2233
11615
93.2227
11966
93.2222
12248
93.2217
12867
93.2212
13409
93.2207
14116
93.2201
15385
93.2196
17793
93.2191
22202
93.2186
29666
93.218
40674
93.2175
52282
93.217
57708
93.2165
50389
93.216
36234
93.2154
23708
93.2149
15848
93.2144
11878
93.2139
10260
93.2133
9357
93.2128
9181
93.2123
9119
93.2118
9217
93.2112
9983
93.2107
11182
93.2102
13567
93.2097
17595
93.2091
24991
93.2086
36607
93.2081
52930
93.2076
69401
93.207
75960
93.2065
63171
93.206
42468
93.2055
24869
93.2049
14195
93.2044
8958
93.2039
6699
93.2033
5368
93.2028
4534
93.2023
4036
93.2018
3556
93.2012
3292
93.2007
2853
93.2002
2715
93.1997
2606
93.1991
2492
93.1986
2246
93.1981
2122
93.1975
In 3d5 26
C:\Datafiles\users\MIT\berggren\emmabat\211216\Temp103.1.ITOSA5ei_1.pro:1:1:ITOSA5ei
2021
12
16
0
0
0
0
9
Casa Info Follows
0
0
0
0
ITOSA5ei
( 0.00217 m , 0.012722 m , 0.169483 m ) Angle: 45.0031 degrees , -0.05 degrees
emmabat211216
1 1
XPS
1500
Al
1486.6
50.38
200
200
1e+037
1e+037
FAT
93.9
1e+037
4.399
1e+037
1e+037
1e+037
1e+037
1e+037
In
3d5
-1
Kinetic Energy
eV
1030.6
0.4
2
Intensity
d
Transmission
d
pulse counting
0.3
1
1e+037
1e+037
1e+037
1e+037
2
ESCAPE DEPTH TYPE
d
0
PHI_AtomicNumber
d
49
102
0
1
0
1
11350
93.2238
11249
93.2233
11376
93.2227
11779
93.2222
11877
93.2217
12565
93.2212
13147
93.2207
13718
93.2201
15201
93.2196
17750
93.2191
22163
93.2186
29747
93.218
40882
93.2175
52603
93.217
58443
93.2165
50429
93.216
36017
93.2154
22904
93.2149
15630
93.2144
11797
93.2139
10098
93.2133
9213
93.2128
9144
93.2123
9005
93.2118
9161
93.2112
9955
93.2107
11071
93.2102
13471
93.2097
17805
93.2091
25331
93.2086
37346
93.2081
53573
93.2076
70598
93.207
75740
93.2065
62827
93.206
41677
93.2055
24199
93.2049
13901
93.2044
8838
93.2039
6654
93.2033
5241
93.2028
4555
93.2023
3955
93.2018
3585
93.2012
3295
93.2007
2937
93.2002
2724
93.1997
2509
93.1991
2323
93.1986
2207
93.1981
2124
93.1975
In 3d5 27
C:\Datafiles\users\MIT\berggren\emmabat\211216\Temp103.1.ITOSA5ei_1.pro:1:1:ITOSA5ei
2021
12
16
0
0
0
0
9
Casa Info Follows
0
0
0
0
ITOSA5ei
( 0.00217 m , 0.012722 m , 0.169483 m ) Angle: 45.0031 degrees , -0.05 degrees
emmabat211216
1 1
XPS
1560
Al
1486.6
50.38
200
200
1e+037
1e+037
FAT
93.9
1e+037
4.399
1e+037
1e+037
1e+037
1e+037
1e+037
In
3d5
-1
Kinetic Energy
eV
1030.6
0.4
2
Intensity
d
Transmission
d
pulse counting
0.3
1
1e+037
1e+037
1e+037
1e+037
2
ESCAPE DEPTH TYPE
d
0
PHI_AtomicNumber
d
49
102
0
1
0
1
11204
93.2238
11073
93.2233
11260
93.2227
11570
93.2222
11836
93.2217
12291
93.2212
13016
93.2207
13625
93.2201
14977
93.2196
17664
93.2191
22335
93.2186
30006
93.218
41111
93.2175
53132
93.217
58097
93.2165
50358
93.216
35314
93.2154
22337
93.2149
15387
93.2144
11675
93.2139
10054
93.2133
9194
93.2128
9053
93.2123
8807
93.2118
9383
93.2112
9867
93.2107
11251
93.2102
13662
93.2097
17696
93.2091
25223
93.2086
37237
93.2081
54086
93.2076
70762
93.207
75926
93.2065
62958
93.206
41257
93.2055
23752
93.2049
13771
93.2044
8959
93.2039
6577
93.2033
5218
93.2028
4575
93.2023
3995
93.2018
3564
93.2012
3138
93.2007
2907
93.2002
2743
93.1997
2427
93.1991
2370
93.1986
2270
93.1981
2129
93.1975
In 3d5 28
C:\Datafiles\users\MIT\berggren\emmabat\211216\Temp103.1.ITOSA5ei_1.pro:1:1:ITOSA5ei
2021
12
16
0
0
0
0
9
Casa Info Follows
0
0
0
0
ITOSA5ei
[...]
Al
1486.6
50.38
200
200
1e+037
1e+037
FAT
117.4
1e+037
4.399
1e+037
1e+037
1e+037
1e+037
1e+037
C
1s
-1
Kinetic Energy
eV
1191.6
0.5
2
Intensity
d
Transmission
d
pulse counting
0.1
1
1e+037
1e+037
1e+037
1e+037
2
ESCAPE DEPTH TYPE
d
0
PHI_AtomicNumber
d
6
82
0
1
0
1
908
116.676
917
116.675
918
116.675
920
116.674
901
116.674
904
116.673
856
116.672
936
116.672
937
116.671
929
116.671
920
116.67
894
116.669
937
116.669
902
116.668
986
116.668
959
116.667
936
116.666
960
116.666
963
116.665
898
116.665
901
116.664
953
116.663
943
116.663
948
116.662
1004
116.661
949
116.661
985
116.66
975
116.66
959
116.659
897
116.658
955
116.658
946
116.657
966
116.657
891
116.656
926
116.655
964
116.655
944
116.654
925
116.654
949
116.653
995
116.652
888
116.652
C 1s 106
C:\Datafiles\users\MIT\berggren\emmabat\211216\Temp103.1.ITOSA5ei_1.pro:1:1:ITOSA5ei
2021
12
16
0
0
0
0
9
Casa Info Follows
0
0
0
0
ITOSA5ei
( 0.00217 m , 0.012722 m , 0.169483 m ) Angle: 45.0031 degrees , -0.05 degrees
emmabat211216
1 1
XPS
720
Al
1486.6
50.38
200
200
1e+037
1e+037
FAT
117.4
1e+037
4.399
1e+037
1e+037
1e+037
1e+037
1e+037
C
1s
-1
Kinetic Energy
eV
1191.6
0.5
2
Intensity
d
Transmission
d
pulse counting
0.1
1
1e+037
1e+037
1e+037
1e+037
2
ESCAPE DEPTH TYPE
d
0
PHI_AtomicNumber
d
6
82
0
1
0
1
948
116.676
864
116.675
847
116.675
914
116.674
894
116.674
921
116.673
838
116.672
913
116.672
926
116.671
951
116.671
903
116.67
890
116.669
903
116.669
926
116.668
956
116.668
864
116.667
926
116.666
900
116.666
955
116.665
950
116.665
924
116.664
985
116.663
966
116.663
911
116.662
961
116.661
897
116.661
906
116.66
898
116.66
908
116.659
878
116.658
953
116.658
897
116.657
993
116.657
916
116.656
971
116.655
921
116.655
883
116.654
922
116.654
930
116.653
934
116.652
926
116.652
C 1s 107
C:\Datafiles\users\MIT\berggren\emmabat\211216\Temp103.1.ITOSA5ei_1.pro:1:1:ITOSA5ei
2021
12
16
0
0
0
0
9
Casa Info Follows
0
0
0
0
ITOSA5ei
( 0.00217 m , 0.012722 m , 0.169483 m ) Angle: 45.0031 degrees , -0.05 degrees
emmabat211216
1 1
XPS
780
Al
1486.6
50.38
200
200
1e+037
1e+037
FAT
117.4
1e+037
4.399
1e+037
1e+037
1e+037
1e+037
1e+037
C
1s
-1
Kinetic Energy
eV
1191.6
0.5
2
Intensity
d
Transmission
d
pulse counting
0.1
1
1e+037
1e+037
1e+037
1e+037
2
ESCAPE DEPTH TYPE
d
0
PHI_AtomicNumber
d
6
82
0
1
0
1
874
116.676
897
116.675
925
116.675
876
116.674
888
116.674
875
116.673
930
116.672
943
116.672
963
116.671
942
116.671
841
116.67
950
116.669
845
116.669
937
116.668
888
116.668
890
116.667
984
116.666
959
116.666
897
116.665
924
116.665
907
116.664
922
116.663
896
116.663
942
116.662
920
116.661
969
116.661
913
116.66
995
116.66
923
116.659
890
116.658
932
116.658
919
116.657
874
116.657
946
116.656
905
116.655
930
116.655
939
116.654
925
116.654
962
116.653
943
116.652
905
116.652
C 1s 108
C:\Datafiles\users\MIT\berggren\emmabat\211216\Temp103.1.ITOSA5ei_1.pro:1:1:ITOSA5ei
2021
12
16
0
0
0
0
9
Casa Info Follows
0
0
0
0
ITOSA5ei
( 0.00217 m , 0.012722 m , 0.169483 m ) Angle: 45.0031 degrees , -0.05 degrees
emmabat211216
1 1
XPS
840
Al
1486.6
50.38
200
200
1e+037
1e+037
FAT
117.4
1e+037
4.399
1e+037
1e+037
1e+037
1e+037
1e+037
C
1s
-1
Kinetic Energy
eV
1191.6
0.5
2
Intensity
d
Transmission
d
pulse counting
0.1
1
1e+037
1e+037
1e+037
1e+037
2
ESCAPE DEPTH TYPE
d
0
PHI_AtomicNumber
d
6
82
0
1
0
1
887
116.676
927
116.675
858
116.675
904
116.674
878
116.674
885
116.673
950
116.672
931
116.672
940
116.671
866
116.671
932
116.67
865
116.669
897
116.669
847
116.668
913
116.668
859
116.667
888
116.666
873
116.666
911
116.665
898
116.665
894
116.664
889
116.663
917
116.663
910
116.662
905
116.661
936
116.661
914
116.66
927
116.66
937
116.659
961
116.658
910
116.658
934
116.657
960
116.657
934
116.656
936
116.655
894
116.655
872
116.654
874
116.654
906
116.653
893
116.652
894
116.652
C 1s 109
C:\Datafiles\users\MIT\berggren\emmabat\211216\Temp103.1.ITOSA5ei_1.pro:1:1:ITOSA5ei
2021
12
16
0
0
0
0
9
Casa Info Follows
0
0
0
0
ITOSA5ei
( 0.00217 m , 0.012722 m , 0.169483 m ) Angle: 45.0031 degrees , -0.05 degrees
emmabat211216
1 1
XPS
900
Al
1486.6
50.38
200
200
1e+037
1e+037
FAT
117.4
1e+037
4.399
1e+037
1e+037
1e+037
1e+037
1e+037
C
1s
-1
Kinetic Energy
eV
1191.6
0.5
2
Intensity
d
Transmission
d
pulse counting
0.1
1
1e+037
1e+037
1e+037
1e+037
2
ESCAPE DEPTH TYPE
d
0
PHI_AtomicNumber
d
6
82
0
1
0
1
861
116.676
934
116.675
916
116.675
908
116.674
934
116.674
952
116.673
901
116.672
897
116.672
907
116.671
900
116.671
928
116.67
940
116.669
840
116.669
884
116.668
922
116.668
835
116.667
878
116.666
983
116.666
883
116.665
889
116.665
924
116.664
894
116.663
949
116.663
915
116.662
925
116.661
876
116.661
919
116.66
899
116.66
944
116.659
894
116.658
920
116.658
937
116.657
909
116.657
924
116.656
932
116.655
921
116.655
930
116.654
859
116.654
927
116.653
913
116.652
920
116.652
C 1s 110
C:\Datafiles\users\MIT\berggren\emmabat\211216\Temp103.1.ITOSA5ei_1.pro:1:1:ITOSA5ei
2021
12
16
0
0
0
0
9
Casa Info Follows
0
0
0
0
ITOSA5ei
( 0.00217 m , 0.012722 m , 0.169483 m ) Angle: 45.0031 degrees , -0.05 degrees
emmabat211216
1 1
XPS
960
Al
1486.6
50.38
200
200
1e+037
1e+037
FAT
117.4
1e+037
4.399
1e+037
1e+037
1e+037
1e+037
1e+037
C
1s
-1
Kinetic Energy
eV
1191.6
0.5
2
Intensity
d
Transmission
d
pulse counting
0.1
1
1e+037
1e+037
1e+037
1e+037
2
ESCAPE DEPTH TYPE
d
0
PHI_AtomicNumber
d
6
82
0
1
0
1
836
116.676
905
116.675
837
116.675
835
116.674
888
116.674
856
116.673
894
116.672
928
116.672
829
116.671
896
116.671
910
116.67
913
116.669
898
116.669
926
116.668
887
116.668
850
116.667
939
116.666
888
116.666
911
116.665
869
116.665
875
116.664
983
116.663
924
116.663
894
116.662
917
116.661
911
116.661
896
116.66
873
116.66
862
116.659
908
116.658
864
116.658
891
116.657
947
116.657
925
116.656
957
116.655
930
116.655
904
116.654
959
116.654
902
116.653
849
116.652
888
116.652
C 1s 111
C:\Datafiles\users\MIT\berggren\emmabat\211216\Temp103.1.ITOSA5ei_1.pro:1:1:ITOSA5ei
2021
12
16
0
0
0
0
9
Casa Info Follows
0
0
0
0
ITOSA5ei
( 0.00217 m , 0.012722 m , 0.169483 m ) Angle: 45.0031 degrees , -0.05 degrees
emmabat211216
1 1
XPS
1020
Al
1486.6
50.38
200
200
1e+037
1e+037
FAT
117.4
1e+037
4.399
1e+037
1e+037
1e+037
1e+037
1e+037
C
1s
-1
Kinetic Energy
eV
1191.6
0.5
2
Intensity
d
Transmission
d
pulse counting
0.1
1
1e+037
1e+037
1e+037
1e+037
2
ESCAPE DEPTH TYPE
d
0
PHI_AtomicNumber
d
6
82
0
1
0
1
862
116.676
918
116.675
844
116.675
849
116.674
866
116.674
955
116.673
903
116.672
872
116.672
823
116.671
869
116.671
846
116.67
882
116.669
927
116.669
868
116.668
918
116.668
882
116.667
876
116.666
899
116.666
860
116.665
835
116.665
956
116.664
901
116.663
847
116.663
872
116.662
896
116.661
910
116.661
924
116.66
878
116.66
929
116.659
914
116.658
845
116.658
896
116.657
885
116.657
860
116.656
901
116.655
934
116.655
905
116.654
944
116.654
904
116.653
931
116.652
881
116.652
C 1s 112
C:\Datafiles\users\MIT\berggren\emmabat\211216\Temp103.1.ITOSA5ei_1.pro:1:1:ITOSA5ei
2021
12
16
0
0
0
0
9
Casa Info Follows
0
0
0
0
ITOSA5ei
( 0.00217 m , 0.012722 m , 0.169483 m ) Angle: 45.0031 degrees , -0.05 degrees
emmabat211216
1 1
XPS
1080
Al
1486.6
50.38
200
200
1e+037
1e+037
FAT
117.4
1e+037
4.399
1e+037
1e+037
1e+037
1e+037
1e+037
C
1s
-1
Kinetic Energy
eV
1191.6
0.5
2
Intensity
d
Transmission
d
pulse counting
0.1
1
1e+037
1e+037
1e+037
1e+037
2
ESCAPE DEPTH TYPE
d
0
PHI_AtomicNumber
d
6
82
0
1
0
1
924
116.676
806
116.675
872
116.675
835
116.674
863
116.674
819
116.673
904
116.672
835
116.672
885
116.671
824
116.671
839
116.67
832
116.669
862
116.669
831
116.668
927
116.668
926
116.667
857
116.666
905
116.666
861
116.665
908
116.665
924
116.664
873
116.663
925
116.663
896
116.662
888
116.661
874
116.661
906
116.66
878
116.66
902
116.659
894
116.658
922
116.658
926
116.657
869
116.657
884
116.656
855
116.655
881
116.655
865
116.654
846
116.654
856
116.653
872
116.652
872
116.652
C 1s 113
C:\Datafiles\users\MIT\berggren\emmabat\211216\Temp103.1.ITOSA5ei_1.pro:1:1:ITOSA5ei
2021
12
16
0
0
0
0
9
Casa Info Follows
0
0
0
0
ITOSA5ei
( 0.00217 m , 0.012722 m , 0.169483 m ) Angle: 45.0031 degrees , -0.05 degrees
emmabat211216
1 1
XPS
1140
Al
1486.6
50.38
200
200
1e+037
1e+037
FAT
117.4
1e+037
4.399
1e+037
1e+037
1e+037
1e+037
1e+037
C
1s
-1
Kinetic Energy
eV
1191.6
0.5
2
Intensity
d
Transmission
d
pulse counting
0.1
1
1e+037
1e+037
1e+037
1e+037
2
ESCAPE DEPTH TYPE
d
0
PHI_AtomicNumber
d
6
82
0
1
0
1
841
116.676
857
116.675
891
116.675
917
116.674
878
116.674
884
116.673
902
116.672
888
116.672
889
116.671
850
116.671
896
116.67
859
116.669
874
116.669
818
116.668
877
116.668
899
116.667
842
116.666
865
116.666
860
116.665
903
116.665
878
116.664
890
116.663
877
116.663
882
116.662
935
116.661
853
116.661
926
116.66
910
116.66
935
116.659
920
116.658
912
116.658
899
116.657
913
116.657
818
116.656
873
116.655
933
116.655
856
116.654
897
116.654
933
116.653
940
116.652
849
116.652
C 1s 114
C:\Datafiles\users\MIT\berggren\emmabat\211216\Temp103.1.ITOSA5ei_1.pro:1:1:ITOSA5ei
2021
12
16
0
0
0
0
9
Casa Info Follows
0
0
0
0
ITOSA5ei
( 0.00217 m , 0.012722 m , 0.169483 m ) Angle: 45.0031 degrees , -0.05 degrees
emmabat211216
1 1
XPS
1200
Al
1486.6
50.38
200
200
1e+037
1e+037
FAT
117.4
1e+037
4.399
1e+037
1e+037
1e+037
1e+037
1e+037
C
1s
-1
Kinetic Energy
eV
1191.6
0.5
2
Intensity
d
Transmission
d
pulse counting
0.1
1
1e+037
1e+037
1e+037
1e+037
2
ESCAPE DEPTH TYPE
d
0
PHI_AtomicNumber
d
6
82
0
1
0
1
807
116.676
851
116.675
830
116.675
849
116.674
906
116.674
823
116.673
828
116.672
784
116.672
862
116.671
861
116.671
818
116.67
849
116.669
919
116.669
847
116.668
939
116.668
883
116.667
935
116.666
842
116.666
912
116.665
795
116.665
875
116.664
841
116.663
879
116.663
908
116.662
875
116.661
889
116.661
877
116.66
859
116.66
894
116.659
923
116.658
893
116.658
921
116.657
885
116.657
901
116.656
885
116.655
864
116.655
887
116.654
921
116.654
981
116.653
882
116.652
875
116.652
C 1s 115
C:\Datafiles\users\MIT\berggren\emmabat\211216\Temp103.1.ITOSA5ei_1.pro:1:1:ITOSA5ei
2021
12
16
0
0
0
0
9
Casa Info Follows
0
0
0
0
ITOSA5ei
( 0.00217 m , 0.012722 m , 0.169483 m ) Angle: 45.0031 degrees , -0.05 degrees
emmabat211216
1 1
XPS
1260
Al
1486.6
50.38
200
200
1e+037
1e+037
FAT
117.4
1e+037
4.399
1e+037
1e+037
1e+037
1e+037
1e+037
C
1s
-1
Kinetic Energy
eV
1191.6
0.5
2
Intensity
d
Transmission
d
pulse counting
0.1
1
1e+037
1e+037
1e+037
1e+037
2
ESCAPE DEPTH TYPE
d
0
PHI_AtomicNumber
d
6
82
0
1
0
1
824
116.676
881
116.675
850
116.675
875
116.674
871
116.674
870
116.673
811
116.672
880
116.672
911
116.671
820
116.671
807
116.67
836
116.669
853
116.669
866
116.668
872
116.668
864
116.667
908
116.666
870
116.666
915
116.665
895
116.665
867
116.664
930
116.663
880
116.663
903
116.662
880
116.661
858
116.661
879
116.66
916
116.66
887
116.659
891
116.658
851
116.658
875
116.657
837
116.657
933
116.656
854
116.655
910
116.655
824
116.654
821
116.654
791
116.653
808
116.652
905
116.652
C 1s 116
C:\Datafiles\users\MIT\berggren\emmabat\211216\Temp103.1.ITOSA5ei_1.pro:1:1:ITOSA5ei
2021
12
16
0
0
0
0
9
Casa Info Follows
0
0
0
0
ITOSA5ei
( 0.00217 m , 0.012722 m , 0.169483 m ) Angle: 45.0031 degrees , -0.05 degrees
emmabat211216
1 1
XPS
1320
Al
1486.6
50.38
200
200
1e+037
1e+037
FAT
117.4
1e+037
4.399
1e+037
1e+037
1e+037
1e+037
1e+037
C
1s
-1
Kinetic Energy
eV
1191.6
0.5
2
Intensity
d
Transmission
d
pulse counting
0.1
1
1e+037
1e+037
1e+037
1e+037
2
ESCAPE DEPTH TYPE
d
0
PHI_AtomicNumber
d
6
82
0
1
0
1
858
116.676
865
116.675
909
116.675
828
116.674
873
116.674
819
116.673
871
116.672
774
116.672
874
116.671
816
116.671
880
116.67
866
116.669
883
116.669
892
116.668
892
116.668
834
116.667
846
116.666
861
116.666
850
116.665
840
116.665
858
116.664
844
116.663
884
116.663
867
116.662
879
116.661
844
116.661
857
116.66
868
116.66
848
116.659
883
116.658
862
116.658
907
116.657
871
116.657
875
116.656
849
116.655
846
116.655
842
116.654
919
116.654
818
116.653
943
116.652
834
116.652
C 1s 117
C:\Datafiles\users\MIT\berggren\emmabat\211216\Temp103.1.ITOSA5ei_1.pro:1:1:ITOSA5ei
2021
12
16
0
0
0
0
9
Casa Info Follows
0
0
0
0
ITOSA5ei
( 0.00217 m , 0.012722 m , 0.169483 m ) Angle: 45.0031 degrees , -0.05 degrees
emmabat211216
1 1
XPS
1380
Al
1486.6
50.38
200
200
1e+037
1e+037
FAT
117.4
1e+037
4.399
1e+037
1e+037
1e+037
1e+037
1e+037
C
1s
-1
Kinetic Energy
eV
1191.6
0.5
2
Intensity
d
Transmission
d
pulse counting
0.1
1
1e+037
1e+037
1e+037
1e+037
2
ESCAPE DEPTH TYPE
d
0
PHI_AtomicNumber
d
6
82
0
1
0
1
910
116.676
848
116.675
887
116.675
861
116.674
876
116.674
858
116.673
846
116.672
843
116.672
841
116.671
876
116.671
851
116.67
828
116.669
820
116.669
869
116.668
885
116.668
895
116.667
862
116.666
885
116.666
912
116.665
856
116.665
858
116.664
883
116.663
910
116.663
857
116.662
883
116.661
891
116.661
895
116.66
862
116.66
812
116.659
828
116.658
903
116.658
863
116.657
807
116.657
906
116.656
844
116.655
840
116.655
855
116.654
863
116.654
878
116.653
884
116.652
869
116.652
C 1s 118
C:\Datafiles\users\MIT\berggren\emmabat\211216\Temp103.1.ITOSA5ei_1.pro:1:1:ITOSA5ei
2021
12
16
0
0
0
0
9
Casa Info Follows
0
0
0
0
ITOSA5ei
( 0.00217 m , 0.012722 m , 0.169483 m ) Angle: 45.0031 degrees , -0.05 degrees
emmabat211216
1 1
XPS
1440
Al
1486.6
50.38
200
200
1e+037
1e+037
FAT
117.4
1e+037
4.399
1e+037
1e+037
1e+037
1e+037
1e+037
C
1s
-1
Kinetic Energy
eV
1191.6
0.5
2
Intensity
d
Transmission
d
pulse counting
0.1
1
1e+037
1e+037
1e+037
1e+037
2
ESCAPE DEPTH TYPE
d
0
PHI_AtomicNumber
d
6
82
0
1
0
1
890
116.676
864
116.675
866
116.675
812
116.674
780
116.674
878
116.673
884
116.672
890
116.672
873
116.671
822
116.671
838
116.67
844
116.669
842
116.669
869
116.668
835
116.668
843
116.667
871
116.666
821
116.666
796
116.665
818
116.665
850
116.664
860
116.663
887
116.663
883
116.662
875
116.661
881
116.661
863
116.66
860
116.66
812
116.659
851
116.658
829
116.658
854
116.657
885
116.657
861
116.656
911
116.655
876
116.655
909
116.654
825
116.654
818
116.653
854
116.652
877
116.652
C 1s 119
C:\Datafiles\users\MIT\berggren\emmabat\211216\Temp103.1.ITOSA5ei_1.pro:1:1:ITOSA5ei
2021
12
16
0
0
0
0
9
Casa Info Follows
0
0
0
0
ITOSA5ei
( 0.00217 m , 0.012722 m , 0.169483 m ) Angle: 45.0031 degrees , -0.05 degrees
emmabat211216
1 1
XPS
1500
Al
1486.6
50.38
200
200
1e+037
1e+037
FAT
117.4
1e+037
4.399
1e+037
1e+037
1e+037
1e+037
1e+037
C
1s
-1
Kinetic Energy
eV
1191.6
0.5
2
Intensity
d
Transmission
d
pulse counting
0.1
1
1e+037
1e+037
1e+037
1e+037
2
ESCAPE DEPTH TYPE
d
0
PHI_AtomicNumber
d
6
82
0
1
0
1
829
116.676
834
116.675
836
116.675
842
116.674
821
116.674
852
116.673
773
116.672
883
116.672
877
116.671
816
116.671
817
116.67
865
116.669
863
116.669
851
116.668
900
116.668
854
116.667
849
116.666
886
116.666
841
116.665
801
116.665
833
116.664
883
116.663
897
116.663
840
116.662
858
116.661
864
116.661
891
116.66
840
116.66
883
116.659
906
116.658
848
116.658
878
116.657
905
116.657
853
116.656
898
116.655
878
116.655
923
116.654
880
116.654
832
116.653
887
116.652
882
116.652
C 1s 120
C:\Datafiles\users\MIT\berggren\emmabat\211216\Temp103.1.ITOSA5ei_1.pro:1:1:ITOSA5ei
2021
12
16
0
0
0
0
9
Casa Info Follows
0
0
0
0
ITOSA5ei
( 0.00217 m , 0.012722 m , 0.169483 m ) Angle: 45.0031 degrees , -0.05 degrees
emmabat211216
1 1
XPS
1560
Al
1486.6
50.38
200
200
1e+037
1e+037
FAT
117.4
1e+037
4.399
1e+037
1e+037
1e+037
1e+037
1e+037
C
1s
-1
Kinetic Energy
eV
1191.6
0.5
2
Intensity
d
Transmission
d
pulse counting
0.1
1
1e+037
1e+037
1e+037
1e+037
2
ESCAPE DEPTH TYPE
d
0
PHI_AtomicNumber
d
6
82
0
1
0
1
821
116.676
907
116.675
802
116.675
766
116.674
822
116.674
859
116.673
839
116.672
844
116.672
885
116.671
862
116.671
808
116.67
874
116.669
797
116.669
801
116.668
860
116.668
797
116.667
806
116.666
822
116.666
807
116.665
847
116.665
885
116.664
865
116.663
853
116.663
866
116.662
825
116.661
812
116.661
814
116.66
825
116.66
828
116.659
861
116.658
868
116.658
836
116.657
867
116.657
782
116.656
820
116.655
830
116.655
829
116.654
838
116.654
859
116.653
860
116.652
883
116.652
C 1s 121
C:\Datafiles\users\MIT\berggren\emmabat\211216\Temp103.1.ITOSA5ei_1.pro:1:1:ITOSA5ei
2021
12
16
0
0
0
0
9
Casa Info Follows
0
0
0
0
ITOSA5ei
( 0.00217 m , 0.012722 m , 0.169483 m ) Angle: 45.0031 degrees , -0.05 degrees
emmabat211216
1 1
XPS
1620
Al
1486.6
50.38
200
200
1e+037
1e+037
FAT
117.4
1e+037
4.399
1e+037
1e+037
1e+037
1e+037
1e+037
C
1s
-1
Kinetic Energy
eV
1191.6
0.5
2
Intensity
d
Transmission
d
pulse counting
0.1
1
1e+037
1e+037
1e+037
1e+037
2
ESCAPE DEPTH TYPE
d
0
PHI_AtomicNumber
d
6
82
0
1
0
1
798
116.676
862
116.675
805
116.675
883
116.674
813
116.674
807
116.673
854
116.672
807
116.672
811
116.671
861
116.671
841
116.67
839
116.669
857
116.669
822
116.668
886
116.668
863
116.667
843
116.666
828
116.666
847
116.665
785
116.665
847
116.664
830
116.663
866
116.663
833
116.662
824
116.661
840
116.661
893
116.66
826
116.66
827
116.659
776
116.658
855
116.658
847
116.657
862
116.657
860
116.656
812
116.655
876
116.655
864
116.654
814
116.654
861
116.653
856
116.652
862
116.652
C 1s 122
C:\Datafiles\users\MIT\berggren\emmabat\211216\Temp103.1.ITOSA5ei_1.pro:1:1:ITOSA5ei
2021
12
16
0
0
0
0
9
Casa Info Follows
0
0
0
0
ITOSA5ei
( 0.00217 m , 0.012722 m , 0.169483 m ) Angle: 45.0031 degrees , -0.05 degrees
emmabat211216
1 1
XPS
1680
Al
1486.6
50.38
200
200
1e+037
1e+037
FAT
117.4
1e+037
4.399
1e+037
1e+037
1e+037
1e+037
1e+037
C
1s
-1
Kinetic Energy
eV
1191.6
0.5
2
Intensity
d
Transmission
d
pulse counting
0.1
1
1e+037
1e+037
1e+037
1e+037
2
ESCAPE DEPTH TYPE
d
0
PHI_AtomicNumber
d
6
82
0
1
0
1
850
116.676
821
116.675
808
116.675
813
116.674
874
116.674
826
116.673
780
116.672
850
116.672
850
116.671
876
116.671
859
116.67
863
116.669
819
116.669
877
116.668
835
116.668
848
116.667
846
116.666
875
116.666
860
116.665
835
116.665
836
116.664
879
116.663
873
116.663
818
116.662
855
116.661
849
116.661
891
116.66
876
116.66
896
116.659
819
116.658
822
116.658
756
116.657
828
116.657
864
116.656
876
116.655
857
116.655
835
116.654
849
116.654
837
116.653
839
116.652
801
116.652
C 1s 123
C:\Datafiles\users\MIT\berggren\emmabat\211216\Temp103.1.ITOSA5ei_1.pro:1:1:ITOSA5ei
2021
12
16
0
0
0
0
9
Casa Info Follows
0
0
0
0
ITOSA5ei
( 0.00217 m , 0.012722 m , 0.169483 m ) Angle: 45.0031 degrees , -0.05 degrees
emmabat211216
1 1
XPS
1740
Al
1486.6
50.38
200
200
1e+037
1e+037
FAT
117.4
1e+037
4.399
1e+037
1e+037
1e+037
1e+037
1e+037
C
1s
-1
Kinetic Energy
eV
1191.6
0.5
2
Intensity
d
Transmission
d
pulse counting
0.1
1
1e+037
1e+037
1e+037
1e+037
2
ESCAPE DEPTH TYPE
d
0
PHI_AtomicNumber
d
6
82
0
1
0
1
852
116.676
830
116.675
885
116.675
850
116.674
828
116.674
848
116.673
855
116.672
826
116.672
836
116.671
829
116.671
835
116.67
761
116.669
831
116.669
830
116.668
866
116.668
844
116.667
797
116.666
835
116.666
845
116.665
872
116.665
815
116.664
810
116.663
823
116.663
866
116.662
825
116.661
873
116.661
853
116.66
855
116.66
828
116.659
811
116.658
852
116.658
819
116.657
810
116.657
815
116.656
846
116.655
845
116.655
800
116.654
843
116.654
898
116.653
878
116.652
828
116.652
C 1s 124
C:\Datafiles\users\MIT\berggren\emmabat\211216\Temp103.1.ITOSA5ei_1.pro:1:1:ITOSA5ei
2021
12
16
0
0
0
0
9
Casa Info Follows
0
0
0
0
ITOSA5ei
( 0.00217 m , 0.012722 m , 0.169483 m ) Angle: 45.0031 degrees , -0.05 degrees
emmabat211216
1 1
XPS
1800
Al
1486.6
50.38
200
200
1e+037
1e+037
FAT
117.4
1e+037
4.399
1e+037
1e+037
1e+037
1e+037
1e+037
C
1s
-1
Kinetic Energy
eV
1191.6
0.5
2
Intensity
d
Transmission
d
pulse counting
0.1
1
1e+037
1e+037
1e+037
1e+037
2
ESCAPE DEPTH TYPE
d
0
PHI_AtomicNumber
d
6
82
0
1
0
1
771
116.676
823
116.675
848
116.675
821
116.674
825
116.674
812
116.673
821
116.672
831
116.672
801
116.671
795
116.671
805
116.67
837
116.669
848
116.669
762
116.668
827
116.668
853
116.667
887
116.666
852
116.666
766
116.665
849
116.665
792
116.664
834
116.663
843
116.663
808
116.662
789
116.661
878
116.661
823
116.66
797
116.66
838
116.659
814
116.658
753
116.658
783
116.657
830
116.657
831
116.656
838
116.655
827
116.655
860
116.654
909
116.654
841
116.653
792
116.652
891
116.652
end of experiment