File: example_data/211206/102.1.itosa3ci.vms
VAMAS Surface Chemical Analysis Standard Data Transfer Format 1988 May 4
MIT
PHI VersaProbe II
Emma Batson
FILE:C:\Datafiles\users\MIT\berggren\emmabat\211206\102.1.ITOSA3ci.spe;BATCH:211206;DESC:1.ITOSA3ci;
153
SOFH
Platform: PC
Technique: XPS
FileType:  SPECTRUM
FileDesc: 1.ITOSA3ci
SoftwareVersion: SS 2.8.0.30
InstrumentModel: PHI VersaProbe II
AcqFilename: C:\Datafiles\users\MIT\berggren\emmabat\211206\102.1.ITOSA3ci.spe
FileDate: 2021 12 6
AcqFileDate: 2021 12 6
Institution: MIT
Operator: Emma Batson
ExperimentID: 211206
EnergyReference: none 0.0
AnalyserWorkFcn: 4.399 eV
AnalyserRetardGain: 1.000506
PlatenID: emmabat211206
PhotoFilename: 101.Low Mag.pho
SXIFilename:
SourceAnalyserAngle: 45.0 d
AnalyserSolidAngle: 0.38 sr
IntensityRecal: no
IntensityCalCoeff: 104.036 0.653
EnergyRecal: no
ScanDeflectionSpan: 30 60
ScanDeflectionOffset: 0 -20
SCAMultiplierVoltage: 1875.0 V
NarrowAcceptanceAngle: no
PeakToNoiseRatioState: no
DelayBeforeAcquire: 5 seconds
C60IonGun: 10kV C60 Ion Gun
BiasBoxMode: 0
TFCParameters: 0, 1, 2, 93.73, 7.481, 1, 1
SemFieldOfView: 0.0000000
ImageSizeXY: 0.0000 0.0000
IonGunMode: Neutralize
SputterIon: Ar+
SputterCurrent: 0.000 uA
SputterRate: 0.000 A/min
SputterEnergy: 0.110 kV
FloatVolt: -102.0 V
FloatEnable: yes
GridVolt: 120.0
CondensorVolt: 72.05
ObjectiveVolt: 99.00
BendVolt: 1.65
SputterRaster: 0.00 0.00 mm
SputterRasterOffset: 1.200 -0.100 mm
TargetSputterTime: 9.0 min
SputterEmission: 5.00 mA
DeflectionBias: 47.0 V
XpsScanMode: scanned
AnalyserMode: FAT
SurvNumCycles: 3
SurvTimePerStep: 50.000000
NoSpectralRegFull: 1
SpectralRegDefFull: 1 1 Su1s 111 1379 -0.8000 1100.0000 -3.0000 1099.0000 -2.0000 0.000000 187.85 AREA
SpectralRegDef2Full: 1 1103.0 1 0 1 1
SpectralRegBackgroundFull: 1 0.0 548.5 0.0
SpectralRegHeroFull: 1 548.5 0.0 0.0 0.00
SpectralRegIRFull: 1 0 0.000 0.000 0.0
NoSpectralReg: 1
SpectralRegDef: 1 1 Su1s 111 1379 -0.8000 1100.0000 -3.0000 1099.0000 -2.0000 0.150000 187.85 AREA
SpectralRegDef2: 1 1103.0 1 0 1 1
SpectralRegBackground: 1 0.0 548.5 0.0
SpectralRegHero: 1 548.5 0.0 0.0 0.00
SpectralRegIR: 1 0 0.000 0.000 0.0
NoSpatialArea: 1
SpatialAreaDef: 1 1 1 (600.1 138.9 16950.4 45.0 0.0)
SpatialAreaDesc: 1
SpatialHRPhotoCor: 1 (0.0 0.0)
XraySource: Al 1486.6 mono
XrayAnodePosition: 5
XrayPower: 50.38 W
XrayBeamDiameter: 200.0 um
XRayBeamVoltage: 15000.0 V
XRayCondenserLensVoltage: 7600.0 V
XRayObjectiveCoilCurrent: 0.707 A
XRayBlankingVoltage: 290.0 V
XRayFilamentCurrent: 1.518 A
XRayStigmator: -0.3 0.0
XRayHighPower: no
EgunNeutMode: Neutralize
NeutralizerCurrent: 20.0 uA
NeutralizerEnergy: 1.00 V
EgunNeutExtractor: 45.0 V
EgunNeutXSteering: 20.0
EgunNeutYSteering: -8.0
EgunNeutFilament: 1.13 A
EgunNeutPulseLength: 10.0 msec
SxiPersistence: 1
SxiSecPerDisplay: 1.0
SxiAutoContrast: yes
SxiAutoContrastLow: 0.30
SxiAutoContrastHigh: 0.30
SxiBindingEnergy: 410.0 eV
SxiPassEnergy: 376 eV
SxiLens2: -804 V
SxiLens3: -761 V
SxiLensBias: 200 V
SxiShutterBias: no
SxiShutterBiasVoltage: 250.0 V
SxiDisplayMode: 2
Detector Acq Time: 20.0 (min)
Number Of Channels: 16
Channel Info: 1 1 1.688
Channel Info: 2 1 1.270
Channel Info: 3 1 1.225
Channel Info: 4 1 1.068
Channel Info: 5 1 1.078
Channel Info: 6 1 0.946
Channel Info: 7 1 0.996
Channel Info: 8 1 0.983
Channel Info: 9 1 1.103
Channel Info: 10 1 1.052
Channel Info: 11 1 0.980
Channel Info: 12 1 0.735
Channel Info: 13 1 0.768
Channel Info: 14 1 0.698
Channel Info: 15 1 0.850
Channel Info: 16 1 1.405
StagePosition: 0.3698 0.5537 16.9504 45.0031 -0.0500
StageCurrentRotationSpeed: 1.0000
DefectPosID: 1
DefectPosComment:
DefectPosU: 0.5990
DefectPosV: -0.1394
DefectPosX: 0.3698
DefectPosY: 0.5537
DefectPosZ: 16.9504
DefectPosTilt: 45.0031
DefectPosRotation: -0.0500
DefectPosAligment: None
DefectPosReferenceImage: 101.Low Mag.pho
C60IonGunMode: Off
C60IonCurrent: 0.0 uA
C60SputterRate: 0.0 A/min
C60Beam: 10.000 kV
C60Temperature: 383.0 C
C60Repellor: -76.0 V
C60Grid: 120.0 V
C60Lens2: 6.215 kV
C60Extractor: -833.0 kV
C60Deflector: -91.0 -124.0 V
C60BlankingDeflector: no yes
C60Raster: 0.8 2.3 mm
C60RasterOffset: 0.4 -0.2 mm
C60Emission: 10.00 mA
C60Filament: 2.80 A
Deconvolution: no
DeconvolutionPassEnergy: 2.95 eV
XRaySetting: 200u50W15KV
EOFH
NORM
REGULAR
0
0
0
0
0
0
1
Su1s 1
C:\Datafiles\users\MIT\berggren\emmabat\211206\102.1.ITOSA3ci.spe:1:1:1.ITOSA3ci
2021
12
6
0
0
0
0
10
Casa Info Follows
0
0
0
0
1.ITOSA3ci
( 0.003698 m , 0.005537 m , 0.169504 m ) Angle: 45.0031 degrees , -0.05 degrees
emmabat211206
1
1
XPS
Al
1486.6
50.38
200
200
1e+037
1e+037
FAT
187.85
1e+037
4.399
1e+037
1e+037
1e+037
1e+037
1e+037
Su1s

-1
Kinetic Energy
eV
386.6
0.8
2
Intensity
d
Transmission
d
pulse counting
0.15
1
1e+037
1e+037
1e+037
1e+037
2
ESCAPE DEPTH TYPE
d
0
PHI_AtomicNumber
d
111
0
0
9145
8934
9043
9066
9009
9158
9057
8860
9025
9034
9010
8992
9121
9001
9333
9586
9808
9920
10323
10267
10285
10190
10087
9657
9596
9376
9535
9552
9392
9180
9107
8815
8398
8263
8026
8279
8084
8108
8284
8183
8003
8115
8044
7976
8099
8096
8010
8117
8292
7961
8357
8261
8359
8144
8288
8266
7963
8098
8123
8206
8060
8154
8022
8268
7960
8034
7836
8022
7885
8064
8019
8069
7877
8085
8189
8214
8070
8230
8202
8306
8307
8417
8324
8250
8275
8206
8208
8390
8273
8389
8377
8300
8411
8465
8384
8333
8384
8298
8361
8398
8466
8643
8499
8686
8576
8636
8542
8696
8701
8591
8559
8602
8805
8825
8713
8739
8704
8694
8839
8796
8709
8747
8728
8988
8809
9038
9130
8846
9022
8886
9094
8923
9056
9055
9086
9125
8972
8957
8944
9006
8957
8850
8917
8834
9030
9043
8871
9101
8914
8894
9051
8850
9191
8904
9335
9278
9573
9613
9760
9754
9630
9388
9467
9200
9120
9058
8931
8914
8590
8720
8350
8545
8453
8361
8282
8313
8458
8436
8355
8438
8534
8468
8390
8508
8672
8580
8565
8549
8585
8507
8500
8482
8558
8603
8610
8679
8637
8679
8779
8735
8910
8642
8783
8914
8789
8655
8604
8809
8840
8818
8837
8689
8891
8921
8852
8786
8798
8971
9031
9066
9012
9051
9138
9041
9006
9026
9255
9113
9168
9052
8833
8863
8791
9254
9049
9029
8982
9345
9037
9309
9305
9151
9086
9099
9272
9225
9301
9188
9127
9220
9312
9359
9424
9310
9337
9412
9214
9346
9290
9379
9452
9287
9208
9410
9381
9459
9400
9399
9551
9381
9587
9384
9630
9488
9601
9487
9569
9567
9642
9737
9716
9583
9714
9635
9538
9559
9619
9719
9512
9698
9557
9710
9600
9797
9776
9676
9833
9930
9781
9787
9609
10071
9915
9967
9932
9777
9962
9743
9985
10093
10038
9841
10058
9959
10113
9944
10088
10129
10044
10118
10041
10136
10075
10064
10012
10035
10078
9934
10228
10173
10143
10125
10361
10234
10251
10103
10433
10324
10397
10451
10459
10556
10505
10777
10428
10542
10521
10567
10436
10447
10328
10352
10303
10335
10165
10218
10233
10119
10143
10216
10359
10345
10087
10344
10299
10419
10245
10304
10207
10404
10111
10507
10298
10366
10285
10301
10468
10426
10511
10370
10482
10581
10625
10586
10416
10515
10326
10529
10450
10471
10534
10419
10509
10559
10490
10593
10695
10519
10730
10731
10684
10505
10707
10695
10664
10587
10871
10501
10875
10767
10795
10759
10547
10750
11057
10949
10873
10964
10877
11040
10766
10972
10853
11099
10875
10780
11162
11165
10969
11272
11008
11192
10914
11238
10858
11236
10976
11046
10970
11099
11116
11220
10960
11116
10925
11264
11058
11182
10988
10975
11098
11147
11096
11288
11232
11234
11266
11064
11185
11263
11424
11501
11312
11497
11492
11355
11605
11276
11612
11457
11459
11493
11477
11504
11607
11447
11519
11513
11659
11593
11602
11521
11654
11430
11424
11575
11294
11382
11202
11280
11360
11250
11437
11664
12036
12643
12970
13380
13176
12764
12104
11875
11558
11188
11127
11042
11135
10919
10874
10966
10837
11058
10997
10930
11145
11043
11093
11095
11230
11070
11186
11135
11047
10840
11099
11013
11003
10786
10747
10758
10728
10503
10504
10488
10377
10340
10463
10554
10644
10924
10912
12087
12762
13858
14596
14858
14049
12976
11870
11113
10611
10296
10068
9804
9912
9699
9657
9630
9636
9720
9515
9657
9505
9572
9499
9585
9499
9274
9531
9390
9635
9356
9472
9437
9372
9553
9308
9554
9580
9288
9425
9490
9593
9542
9471
9386
9566
9619
9668
9649
9482
9704
9671
9799
9676
9613
9553
9817
9447
9509
9683
9444
9624
9711
9680
9657
9682
9790
9576
9672
9606
9765
9892
9869
9760
9905
9788
9864
9863
9940
9838
9737
9846
9994
9630
10027
9930
9834
9892
9948
9790
10065
9831
9959
9793
9803
9898
9981
10014
10117
9952
10248
10229
10111
9920
10058
10007
10159
10179
9884
10093
10087
10138
10106
10108
10241
10145
10082
10014
10205
10145
9992
10179
10422
10131
10343
10203
10305
10152
10118
10384
10403
10325
10191
10242
10270
10299
10260
10218
10211
10378
10213
10274
10374
10596
10399
10586
10255
10478
10451
10505
10490
10361
10479
10316
10377
10148
9963
9991
10162
9747
9893
9850
9766
9557
9763
9507
9616
9822
10146
10756
11882
13188
14477
14176
13381
11566
10052
9705
9583
9511
9300
9338
9341
9166
9243
9089
9373
9292
9218
9244
9277
9269
9404
9221
9190
9298
9114
9235
9169
9067
9094
9096
9319
9265
9182
9337
9137
9155
9337
9218
9215
9129
9271
9072
9311
9560
9809
9990
10068
9458
9355
8996
8918
8980
9110
9437
9899
10337
10496
9957
9255
9040
8908
8820
8794
8915
8861
9020
9133
8969
8931
9153
9051
9066
9334
9324
9454
9570
9450
9427
9367
9300
9265
9175
9203
9068
8921
8766
8459
8249
7838
7466
7125
6955
6909
6737
6940
7419
9035
13310
18520
20515
15928
9647
6417
5509
5827
7397
12226
20527
26131
23534
14828
7350
4541
3533
3107
2732
2693
2439
2319
2289
2183
2150
2076
2058
2082
2053
2041
2008
2013
2009
1849
1972
1973
1917
1906
1969
2022
1923
1966
2007
2011
1919
2003
1932
1964
1967
2012
1994
1868
1961
1965
1951
2004
1980
1981
1981
2063
1988
1952
1975
1990
1959
1996
1973
1990
2026
2020
2023
2081
1956
2026
1927
2017
2038
1995
1976
2007
1917
1999
2041
1965
1978
2129
1951
2052
2012
2061
2107
2075
2096
2015
2047
2046
2018
2141
2083
1986
2063
2057
2048
2077
2029
2110
2038
1980
2071
2022
2042
2105
2100
2036
2065
2176
2051
2177
2161
2110
2151
2003
2137
2142
2122
2093
2152
2087
2192
2138
2255
2090
2165
2235
2261
2303
2120
2122
2192
2215
2108
2260
2243
2151
2226
2227
2192
2172
2224
2227
2257
2209
2243
2281
2241
2241
2288
2276
2318
2214
2206
2283
2308
2226
2306
2317
2329
2275
2337
2291
2311
2226
2309
2335
2290
2274
2332
2321
2436
2322
2332
2327
2349
2371
2425
2395
2492
2439
2474
2439
2408
2319
2378
2444
2334
2343
2281
2281
2200
2223
2243
2153
2272
2217
2346
2356
2519
2690
2774
3280
4236
4752
4040
2955
2464
2295
2241
2239
2213
2170
2141
2188
2182
2240
2094
2106
2194
2049
2203
2143
2288
2146
2203
2141
2225
2203
2170
2157
2229
2149
2153
2088
2185
2116
2214
2162
2179
2179
2173
2125
2136
2199
2266
2136
2182
2204
2296
2130
2151
2099
2300
2193
2221
2183
2176
2171
2213
2187
2188
2190
2232
2205
2206
2259
2197
2369
2277
2236
2158
2227
2171
2205
2205
2196
2239
2279
2220
2207
2274
2247
2323
2253
2287
2206
2226
2174
2258
2246
2301
2284
2307
2262
2340
2222
2303
2246
2301
2315
2362
2258
2273
2296
2332
2260
2297
2301
2358
2317
2301
2289
2379
2275
2248
2329
2307
2338
2229
2343
2275
2321
2359
2312
2322
2311
2364
2342
2340
2467
2323
2259
2291
2268
2317
2281
2415
2331
2443
2355
2372
2403
2380
2411
2505
2427
2459
2433
2405
2343
2453
2369
2376
2308
2392
2318
2285
2345
2353
2391
2395
2470
2267
2455
2385
2602
2700
2716
2675
2646
2489
2420
2374
2448
2453
2485
2430
2374
2420
2543
2449
2483
2487
2413
2472
2465
2432
2474
2336
2341
2292
2346
2410
2448
2355
2337
2371
2371
2361
2453
2439
2619
2659
2703
2798
2806
2739
2660
2548
2492
2400
2384
2320
2333
2319
2253
2366
2307
2227
2258
2219
2306
2234
2293
2256
2299
2245
2373
2290
2496
2509
2665
2607
2487
2337
2321
2274
2281
2262
2246
2248
2272
2316
2194
2314
2289
2305
2254
2249
2300
2316
2431
2338
2450
2341
2412
2331
2410
2392
2465
2343
2444
2355
2360
2167
2040
1950
1935
1776
1885
1642
1620
1556
1532
1523
1444
1397
1340
1317
1341
1314
1290
1305
1265
1246
1239
1258
1311
1231
1278
1280
1287
1280
1293
1331
1303
1232
1244
1275
1275
1387
1380
1385
1268
1470
1289
1386
1413
1466
1365
1431
1404
1448
1316
1340
1284
1291
1244
1172
1184
1153
1105
1142
1135
1152
1296
1262
1188
1077
1036
988
1099
1182
1592
2552
4443
5893
5863
3981
2079
973
579
389
346
292
248
255
285
325
332
356
351
370
332
303
230
114
39
34
39
25
187.141
end of experiment