File: example_data/211206/104.1.itosa3ci+1_1.vms
VAMAS Surface Chemical Analysis Standard Data Transfer Format 1988 May 4
MIT
PHI VersaProbe II
Emma Batson
FILE:C:\Datafiles\users\MIT\berggren\emmabat\211206\Temp104.1.ITOSA3ci+1_1.pro;BATCH:211206;DESC:1.ITOSA3ci;
194
SOFH
Platform: PC
Technique: XPS
FileType: DEPTHPRO
FileDesc: 1.ITOSA3ci
SoftwareVersion: SS 2.8.0.30
InstrumentModel: PHI VersaProbe II
AcqFilename: C:\Datafiles\users\MIT\berggren\emmabat\211206\Temp104.1.ITOSA3ci+1_1.pro
FileDate: 2021 12 6
AcqFileDate: 2021 12 6
Institution: MIT
Operator: Emma Batson
ExperimentID: 211206
EnergyReference: none 0.0
AnalyserWorkFcn: 4.399 eV
AnalyserRetardGain: 1.000506
PlatenID: emmabat211206
PhotoFilename: 101.Low Mag.pho
SXIFilename:
SourceAnalyserAngle: 45.0 d
AnalyserSolidAngle: 0.38 sr
IntensityRecal: no
IntensityCalCoeff: 104.036 0.653
EnergyRecal: no
ScanDeflectionSpan: 30 60
ScanDeflectionOffset: 0 -20
SCAMultiplierVoltage: 1875.0 V
NarrowAcceptanceAngle: no
PeakToNoiseRatioState: no
DelayBeforeAcquire: 5 seconds
C60IonGun: 10kV C60 Ion Gun
BiasBoxMode: 0
TFCParameters: 0, 1, 2, 93.73, 7.481, 1, 1
SemFieldOfView: 0.0000000
ImageSizeXY: 0.0000 0.0000
IonGunMode: Neutralize
SputterIon: Ar+
SputterCurrent: 0.000 uA
SputterRate: 0.000 A/min
SputterEnergy: 0.110 kV
FloatVolt: -102.0 V
FloatEnable: yes
GridVolt: 120.0
CondensorVolt: 72.05
ObjectiveVolt: 99.00
BendVolt: 1.65
SputterRaster: 0.00 0.00 mm
SputterRasterOffset: 1.200 -0.100 mm
TargetSputterTime: 9.0 min
SputterEmission: 5.00 mA
DeflectionBias: 47.0 V
XpsScanMode: scanned
AnalyserMode: FAT
SurvTimePerStep: 50.000000
NoDPDataCyc: 34
NoPreSputterCyc: 1
ProfSputterDelay: 10.0
ProfXrayOffDuringSputter: no
ProfSourceBlankDuringSputter: no
ProfZalarHighAccuracyInterval: 20
SampleRotation: off
DepthRecal: no
SputterMode: AlternatingZalar
NoDepthReg: 2
DepthCalDef: 1 Layer1 1 0.0000 0.0000 Ar+ 11.00 1.00 11 '1000V-1uA-2x2' 1.000 120 15.00 0 0 645 720 12 2.0 2.0 0.55 -0.65 0.00 0.00 Ar
DepthCalDef: 2 Layer1 12 0.0000 0.0000 Ar+ 22.00 1.00 22 '1000V-1uA-2x2' 1.000 120 15.00 0 0 645 720 12 2.0 2.0 0.55 -0.65 0.00 0.00 Ar
NoSpectralRegFull: 4
SpectralRegDefFull: 1 1 In3d5 49 51 -0.4000 456.0000 436.0000 455.0000 437.0000 0.000000 93.90 AREA
SpectralRegDef2Full: 1 20.0 2 0 2 500
SpectralRegBackgroundFull: 1 0.0 446.0 0.0
SpectralRegHeroFull: 1 446.0 0.0 0.0 0.00
SpectralRegIRFull: 1 0 0.000 0.000 0.0
SpectralRegDefFull: 2 1 Sn3d 50 51 -0.4000 499.0000 479.0000 498.0000 480.0000 0.000000 93.90 AREA
SpectralRegDef2Full: 2 20.0 15 0 2 500
SpectralRegBackgroundFull: 2 0.0 489.0 0.0
SpectralRegHeroFull: 2 489.0 0.0 0.0 0.00
SpectralRegIRFull: 2 0 0.000 0.000 0.0
SpectralRegDefFull: 3 1 O1s 8 51 -0.4000 540.0000 520.0000 539.0000 521.0000 0.000000 93.90 AREA
SpectralRegDef2Full: 3 20.0 9 0 2 500
SpectralRegBackgroundFull: 3 0.0 530.0 0.0
SpectralRegHeroFull: 3 530.0 0.0 0.0 0.00
SpectralRegIRFull: 3 0 0.000 0.000 0.0
SpectralRegDefFull: 4 1 C1s 6 41 -0.5000 295.0000 275.0000 294.0000 276.0000 0.000000 117.40 AREA
SpectralRegDef2Full: 4 20.0 2 0 1 500
SpectralRegBackgroundFull: 4 0.0 285.0 0.0
SpectralRegHeroFull: 4 285.0 0.0 0.0 0.00
SpectralRegIRFull: 4 0 0.000 0.000 0.0
NoSpectralReg: 4
SpectralRegDef: 1 1 In3d5 49 51 -0.4000 456.0000 436.0000 455.0000 437.0000 0.200000 93.90 AREA
SpectralRegDef2: 1 20.0 2 0 2 500
SpectralRegBackground: 1 0.0 446.0 0.0
SpectralRegHero: 1 446.0 0.0 0.0 0.00
SpectralRegIR: 1 0 0.000 0.000 0.0
SpectralRegDef: 2 1 Sn3d 50 51 -0.4000 499.0000 479.0000 498.0000 480.0000 1.500000 93.90 AREA
SpectralRegDef2: 2 20.0 15 0 2 500
SpectralRegBackground: 2 0.0 489.0 0.0
SpectralRegHero: 2 489.0 0.0 0.0 0.00
SpectralRegIR: 2 0 0.000 0.000 0.0
SpectralRegDef: 3 1 O1s 8 51 -0.4000 540.0000 520.0000 539.0000 521.0000 0.900000 93.90 AREA
SpectralRegDef2: 3 20.0 9 0 2 500
SpectralRegBackground: 3 0.0 530.0 0.0
SpectralRegHero: 3 530.0 0.0 0.0 0.00
SpectralRegIR: 3 0 0.000 0.000 0.0
SpectralRegDef: 4 1 C1s 6 41 -0.5000 295.0000 275.0000 294.0000 276.0000 0.100000 117.40 AREA
SpectralRegDef2: 4 20.0 2 0 1 500
SpectralRegBackground: 4 0.0 285.0 0.0
SpectralRegHero: 4 285.0 0.0 0.0 0.00
SpectralRegIR: 4 0 0.000 0.000 0.0
NoSpatialArea: 1
SpatialAreaDef: 1 1 1 (600.1 138.9 16950.4 45.0 0.0)
SpatialAreaDesc: 1
SpatialHRPhotoCor: 1 (0.0 0.0)
XraySource: Al 1486.6 mono
XrayAnodePosition: 5
XrayPower: 50.38 W
XrayBeamDiameter: 200.0 um
XRayBeamVoltage: 15000.0 V
XRayCondenserLensVoltage: 7600.0 V
XRayObjectiveCoilCurrent: 0.707 A
XRayBlankingVoltage: 290.0 V
XRayFilamentCurrent: 1.521 A
XRayStigmator: -0.3 0.0
XRayHighPower: no
EgunNeutMode: Neutralize
NeutralizerCurrent: 20.0 uA
NeutralizerEnergy: 1.00 V
EgunNeutExtractor: 45.0 V
EgunNeutXSteering: 20.0
EgunNeutYSteering: -8.0
EgunNeutFilament: 1.13 A
EgunNeutPulseLength: 10.0 msec
SxiPersistence: 1
SxiSecPerDisplay: 1.0
SxiAutoContrast: yes
SxiAutoContrastLow: 0.30
SxiAutoContrastHigh: 0.30
SxiBindingEnergy: 410.0 eV
SxiPassEnergy: 376 eV
SxiLens2: -804 V
SxiLens3: -761 V
SxiLensBias: 200 V
SxiShutterBias: no
SxiShutterBiasVoltage: 250.0 V
SxiDisplayMode: 2
Detector Acq Time: 20.0 (min)
Number Of Channels: 16
Channel Info: 1 1 1.688
Channel Info: 2 1 1.270
Channel Info: 3 1 1.225
Channel Info: 4 1 1.068
Channel Info: 5 1 1.078
Channel Info: 6 1 0.946
Channel Info: 7 1 0.996
Channel Info: 8 1 0.983
Channel Info: 9 1 1.103
Channel Info: 10 1 1.052
Channel Info: 11 1 0.980
Channel Info: 12 1 0.735
Channel Info: 13 1 0.768
Channel Info: 14 1 0.698
Channel Info: 15 1 0.850
Channel Info: 16 1 1.405
StagePosition: 0.3689 0.5537 16.9504 45.0062 -0.1000
StageCurrentRotationSpeed: 1.0000
DefectPosID: 1
DefectPosComment:
DefectPosU: 0.5976
DefectPosV: -0.1391
DefectPosX: 0.3689
DefectPosY: 0.5537
DefectPosZ: 16.9504
DefectPosTilt: 45.0063
DefectPosRotation: -0.1000
DefectPosAligment: None
DefectPosReferenceImage: 101.Low Mag.pho
C60IonGunMode: Off
C60IonCurrent: 0.0 uA
C60SputterRate: 0.0 A/min
C60Beam: 10.000 kV
C60Temperature: 383.0 C
C60Repellor: -76.0 V
C60Grid: 120.0 V
C60Lens2: 6.215 kV
C60Extractor: -833.0 kV
C60Deflector: -91.0 -124.0 V
C60BlankingDeflector: no yes
C60Raster: 0.8 2.3 mm
C60RasterOffset: 0.4 -0.2 mm
C60Emission: 10.00 mA
C60Filament: 2.80 A
Deconvolution: no
DeconvolutionPassEnergy: 2.95 eV
XRaySetting: 200u50W15KV
EOFH
NORM
REGULAR
0
1
Etch Time
s
0
0
0
0
136
In 3d5 1
C:\Datafiles\users\MIT\berggren\emmabat\211206\Temp104.1.ITOSA3ci+1_1.pro:1:1:1.ITOSA3ci
2021
12
6
0
0
0
0
9
Casa Info Follows
0
0
0
0
1.ITOSA3ci
( 0.003689 m , 0.005537 m , 0.169504 m ) Angle: 45.0062 degrees , -0.1 degrees
emmabat211206
1 1
XPS
0
Al
1486.6
50.38
200
200
1e+037
1e+037
FAT
93.9
1e+037
4.399
1e+037
1e+037
1e+037
1e+037
1e+037
In
3d5
-1
Kinetic Energy
eV
1030.6
0.4
2
Intensity
d
Transmission
d
pulse counting
0.2
1
1e+037
1e+037
1e+037
1e+037
2
ESCAPE DEPTH TYPE
d
0
PHI_AtomicNumber
d
49
102
0
1
0
1
4409
93.2238
4279
93.2233
4199
93.2227
4195
93.2222
4218
93.2217
4188
93.2212
4387
93.2207
4516
93.2201
4888
93.2196
5728
93.2191
7269
93.2186
9843
93.218
13146
93.2175
16890
93.217
19636
93.2165
19099
93.216
14211
93.2154
8794
93.2149
5502
93.2144
4008
93.2139
3396
93.2133
3139
93.2128
3054
93.2123
2903
93.2118
3069
93.2112
3307
93.2107
3748
93.2102
4550
93.2097
5929
93.2091
8555
93.2086
12351
93.2081
17598
93.2076
22757
93.207
26154
93.2065
24716
93.206
17894
93.2055
10053
93.2049
5611
93.2044
3810
93.2039
3092
93.2033
2633
93.2028
2242
93.2023
2096
93.2018
1910
93.2012
1847
93.2007
1675
93.2002
1544
93.1997
1537
93.1991
1507
93.1986
1366
93.1981
1406
93.1975
In 3d5 2
C:\Datafiles\users\MIT\berggren\emmabat\211206\Temp104.1.ITOSA3ci+1_1.pro:1:1:1.ITOSA3ci
2021
12
6
0
0
0
0
9
Casa Info Follows
0
0
0
0
1.ITOSA3ci
( 0.003689 m , 0.005537 m , 0.169504 m ) Angle: 45.0062 degrees , -0.1 degrees
emmabat211206
1 1
XPS
60
Al
1486.6
50.38
200
200
1e+037
1e+037
FAT
93.9
1e+037
4.399
1e+037
1e+037
1e+037
1e+037
1e+037
In
3d5
-1
Kinetic Energy
eV
1030.6
0.4
2
Intensity
d
Transmission
d
pulse counting
0.2
1
1e+037
1e+037
1e+037
1e+037
2
ESCAPE DEPTH TYPE
d
0
PHI_AtomicNumber
d
49
102
0
1
0
1
7584
93.2238
7648
93.2233
7581
93.2227
7629
93.2222
7965
93.2217
8030
93.2212
8276
93.2207
8763
93.2201
9375
93.2196
10596
93.2191
12571
93.2186
16842
93.218
22912
93.2175
31202
93.217
38471
93.2165
37437
93.216
29107
93.2154
18488
93.2149
11840
93.2144
8559
93.2139
7273
93.2133
6579
93.2128
6326
93.2123
6276
93.2118
6250
93.2112
6689
93.2107
6913
93.2102
8191
93.2097
10132
93.2091
13796
93.2086
19975
93.2081
29628
93.2076
41745
93.207
50310
93.2065
48095
93.206
34560
93.2055
19789
93.2049
11178
93.2044
6924
93.2039
5095
93.2033
4072
93.2028
3359
93.2023
2946
93.2018
2710
93.2012
2380
93.2007
2231
93.2002
2011
93.1997
1841
93.1991
1732
93.1986
1719
93.1981
1665
93.1975
In 3d5 3
C:\Datafiles\users\MIT\berggren\emmabat\211206\Temp104.1.ITOSA3ci+1_1.pro:1:1:1.ITOSA3ci
2021
12
6
0
0
0
0
9
Casa Info Follows
0
0
0
0
1.ITOSA3ci
( 0.003689 m , 0.005537 m , 0.169504 m ) Angle: 45.0062 degrees , -0.1 degrees
emmabat211206
1 1
XPS
120
Al
1486.6
50.38
200
200
1e+037
1e+037
FAT
93.9
1e+037
4.399
1e+037
1e+037
1e+037
1e+037
1e+037
In
3d5
-1
Kinetic Energy
eV
1030.6
0.4
2
Intensity
d
Transmission
d
pulse counting
0.2
1
1e+037
1e+037
1e+037
1e+037
2
ESCAPE DEPTH TYPE
d
0
PHI_AtomicNumber
d
49
102
0
1
0
1
7874
93.2238
7991
93.2233
7988
93.2227
8162
93.2222
8360
93.2217
9009
93.2212
8999
93.2207
9118
93.2201
9851
93.2196
10945
93.2191
13090
93.2186
16434
93.218
22790
93.2175
30697
93.217
37635
93.2165
37049
93.216
29199
93.2154
19844
93.2149
12979
93.2144
9234
93.2139
7441
93.2133
6990
93.2128
6526
93.2123
6462
93.2118
6518
93.2112
6796
93.2107
7298
93.2102
8307
93.2097
10206
93.2091
13654
93.2086
19308
93.2081
28682
93.2076
40811
93.207
49673
93.2065
47253
93.206
35078
93.2055
21769
93.2049
12528
93.2044
7485
93.2039
5177
93.2033
4090
93.2028
3334
93.2023
2997
93.2018
2618
93.2012
2452
93.2007
2240
93.2002
2076
93.1997
1849
93.1991
1800
93.1986
1591
93.1981
1665
93.1975
In 3d5 4
C:\Datafiles\users\MIT\berggren\emmabat\211206\Temp104.1.ITOSA3ci+1_1.pro:1:1:1.ITOSA3ci
2021
12
6
0
0
0
0
9
Casa Info Follows
0
0
0
0
1.ITOSA3ci
( 0.003689 m , 0.005537 m , 0.169504 m ) Angle: 45.0062 degrees , -0.1 degrees
emmabat211206
1 1
XPS
180
Al
1486.6
50.38
200
200
1e+037
1e+037
FAT
93.9
1e+037
4.399
1e+037
1e+037
1e+037
1e+037
1e+037
In
3d5
-1
Kinetic Energy
eV
1030.6
0.4
2
Intensity
d
Transmission
d
pulse counting
0.2
1
1e+037
1e+037
1e+037
1e+037
2
ESCAPE DEPTH TYPE
d
0
PHI_AtomicNumber
d
49
102
0
1
0
1
8091
93.2238
8486
93.2233
8457
93.2227
8781
93.2222
9100
93.2217
9518
93.2212
9776
93.2207
10139
93.2201
10519
93.2196
11456
93.2191
13199
93.2186
16661
93.218
22359
93.2175
30521
93.217
36265
93.2165
36160
93.216
29942
93.2154
21800
93.2149
14690
93.2144
9980
93.2139
7994
93.2133
7137
93.2128
6551
93.2123
6520
93.2118
6549
93.2112
6689
93.2107
7196
93.2102
8204
93.2097
10149
93.2091
13293
93.2086
18780
93.2081
28067
93.2076
38637
93.207
47188
93.2065
45605
93.206
36382
93.2055
24362
93.2049
14525
93.2044
8418
93.2039
5574
93.2033
4147
93.2028
3552
93.2023
3065
93.2018
2785
93.2012
2498
93.2007
2208
93.2002
2114
93.1997
1861
93.1991
1840
93.1986
1658
93.1981
1609
93.1975
In 3d5 5
C:\Datafiles\users\MIT\berggren\emmabat\211206\Temp104.1.ITOSA3ci+1_1.pro:1:1:1.ITOSA3ci
2021
12
6
0
0
0
0
9
Casa Info Follows
0
0
0
0
1.ITOSA3ci
( 0.003689 m , 0.005537 m , 0.169504 m ) Angle: 45.0062 degrees , -0.1 degrees
emmabat211206
1 1
XPS
240
Al
1486.6
50.38
200
200
1e+037
1e+037
FAT
93.9
1e+037
4.399
1e+037
1e+037
1e+037
1e+037
1e+037
In
3d5
-1
Kinetic Energy
eV
1030.6
0.4
2
Intensity
d
Transmission
d
pulse counting
0.2
1
1e+037
1e+037
1e+037
1e+037
2
ESCAPE DEPTH TYPE
d
0
PHI_AtomicNumber
d
49
102
0
1
0
1
8398
93.2238
8369
93.2233
8806
93.2227
9163
93.2222
9455
93.2217
9952
93.2212
10319
93.2207
10681
93.2201
10913
93.2196
11688
93.2191
13319
93.2186
16710
93.218
22379
93.2175
29906
93.217
35555
93.2165
35473
93.216
30340
93.2154
23243
93.2149
15760
93.2144
10493
93.2139
8080
93.2133
7040
93.2128
6751
93.2123
6552
93.2118
6478
93.2112
6874
93.2107
7341
93.2102
8411
93.2097
10047
93.2091
13337
93.2086
18636
93.2081
27327
93.2076
37960
93.207
45650
93.2065
44760
93.206
36768
93.2055
26187
93.2049
16147
93.2044
8857
93.2039
5625
93.2033
4316
93.2028
3529
93.2023
3052
93.2018
2705
93.2012
2447
93.2007
2215
93.2002
1994
93.1997
1964
93.1991
1731
93.1986
1713
93.1981
1530
93.1975
In 3d5 6
C:\Datafiles\users\MIT\berggren\emmabat\211206\Temp104.1.ITOSA3ci+1_1.pro:1:1:1.ITOSA3ci
2021
12
6
0
0
0
0
9
Casa Info Follows
0
0
0
0
1.ITOSA3ci
( 0.003689 m , 0.005537 m , 0.169504 m ) Angle: 45.0062 degrees , -0.1 degrees
emmabat211206
1 1
XPS
300
Al
1486.6
50.38
200
200
1e+037
1e+037
FAT
93.9
1e+037
4.399
1e+037
1e+037
1e+037
1e+037
1e+037
In
3d5
-1
Kinetic Energy
eV
1030.6
0.4
2
Intensity
d
Transmission
d
pulse counting
0.2
1
1e+037
1e+037
1e+037
1e+037
2
ESCAPE DEPTH TYPE
d
0
PHI_AtomicNumber
d
49
102
0
1
0
1
8434
93.2238
8605
93.2233
8790
93.2227
9057
93.2222
9665
93.2217
10062
93.2212
10353
93.2207
10906
93.2201
11089
93.2196
12019
93.2191
13879
93.2186
17196
93.218
22862
93.2175
30209
93.217
35933
93.2165
35709
93.216
30659
93.2154
23444
93.2149
16124
93.2144
10592
93.2139
8094
93.2133
7188
93.2128
6707
93.2123
6743
93.2118
6599
93.2112
6989
93.2107
7386
93.2102
8573
93.2097
10425
93.2091
13620
93.2086
19082
93.2081
28083
93.2076
38411
93.207
45627
93.2065
44658
93.206
37205
93.2055
26559
93.2049
16141
93.2044
9005
93.2039
5691
93.2033
4340
93.2028
3612
93.2023
2990
93.2018
2811
93.2012
2435
93.2007
2197
93.2002
1976
93.1997
1841
93.1991
1688
93.1986
1656
93.1981
1583
93.1975
In 3d5 7
C:\Datafiles\users\MIT\berggren\emmabat\211206\Temp104.1.ITOSA3ci+1_1.pro:1:1:1.ITOSA3ci
2021
12
6
0
0
0
0
9
Casa Info Follows
0
0
0
0
1.ITOSA3ci
( 0.003689 m , 0.005537 m , 0.169504 m ) Angle: 45.0062 degrees , -0.1 degrees
emmabat211206
1 1
XPS
360
Al
1486.6
50.38
200
200
1e+037
1e+037
FAT
93.9
1e+037
4.399
1e+037
1e+037
1e+037
1e+037
1e+037
In
3d5
-1
Kinetic Energy
eV
1030.6
0.4
2
Intensity
d
Transmission
d
pulse counting
0.2
1
1e+037
1e+037
1e+037
1e+037
2
ESCAPE DEPTH TYPE
d
0
PHI_AtomicNumber
d
49
102
0
1
0
1
8292
93.2238
8525
93.2233
8910
93.2227
8827
93.2222
9452
93.2217
9967
93.2212
10495
93.2207
10442
93.2201
11129
93.2196
11690
93.2191
13903
93.2186
17857
93.218
23236
93.2175
30505
93.217
36239
93.2165
35941
93.216
30315
93.2154
22914
93.2149
15529
93.2144
10371
93.2139
7979
93.2133
7058
93.2128
6602
93.2123
6372
93.2118
6544
93.2112
6784
93.2107
7335
93.2102
8481
93.2097
10280
93.2091
13822
93.2086
19542
93.2081
28672
93.2076
39349
93.207
46152
93.2065
45107
93.206
36580
93.2055
26204
93.2049
15676
93.2044
8914
93.2039
5687
93.2033
4392
93.2028
3538
93.2023
2989
93.2018
2643
93.2012
2488
93.2007
2133
93.2002
2122
93.1997
1782
93.1991
1695
93.1986
1658
93.1981
1531
93.1975
In 3d5 8
C:\Datafiles\users\MIT\berggren\emmabat\211206\Temp104.1.ITOSA3ci+1_1.pro:1:1:1.ITOSA3ci
2021
12
6
0
0
0
0
9
Casa Info Follows
0
0
0
0
1.ITOSA3ci
( 0.003689 m , 0.005537 m , 0.169504 m ) Angle: 45.0062 degrees , -0.1 degrees
emmabat211206
1 1
XPS
420
Al
1486.6
50.38
200
200
1e+037
1e+037
FAT
93.9
1e+037
4.399
1e+037
1e+037
1e+037
1e+037
1e+037
In
3d5
-1
Kinetic Energy
eV
1030.6
0.4
2
Intensity
d
Transmission
d
pulse counting
0.2
1
1e+037
1e+037
1e+037
1e+037
2
ESCAPE DEPTH TYPE
d
0
PHI_AtomicNumber
d
49
102
0
1
0
1
8262
93.2238
8498
93.2233
8438
93.2227
8840
93.2222
9087
93.2217
9462
93.2212
10035
93.2207
10380
93.2201
10716
93.2196
11890
93.2191
13993
93.2186
17853
93.218
23925
93.2175
31549
93.217
36865
93.2165
35702
93.216
30075
93.2154
21791
93.2149
14674
93.2144
10039
93.2139
7729
93.2133
6929
93.2128
6576
93.2123
6459
93.2118
6225
93.2112
6744
93.2107
7306
93.2102
8476
93.2097
10420
93.2091
14435
93.2086
20256
93.2081
30075
93.2076
40910
93.207
47762
93.2065
45101
93.206
36081
93.2055
24411
93.2049
14718
93.2044
8417
93.2039
5532
93.2033
4229
93.2028
3445
93.2023
3037
93.2018
2647
93.2012
2371
93.2007
2131
93.2002
1903
93.1997
1848
93.1991
1721
93.1986
1638
93.1981
1492
93.1975
In 3d5 9
C:\Datafiles\users\MIT\berggren\emmabat\211206\Temp104.1.ITOSA3ci+1_1.pro:1:1:1.ITOSA3ci
2021
12
6
0
0
0
0
9
Casa Info Follows
0
0
0
0
1.ITOSA3ci
( 0.003689 m , 0.005537 m , 0.169504 m ) Angle: 45.0062 degrees , -0.1 degrees
emmabat211206
1 1
XPS
480
Al
1486.6
50.38
200
200
1e+037
1e+037
FAT
93.9
1e+037
4.399
1e+037
1e+037
1e+037
1e+037
1e+037
In
3d5
-1
Kinetic Energy
eV
1030.6
0.4
2
Intensity
d
Transmission
d
pulse counting
0.2
1
1e+037
1e+037
1e+037
1e+037
2
ESCAPE DEPTH TYPE
d
0
PHI_AtomicNumber
d
49
102
0
1
0
1
7861
93.2238
8044
93.2233
8364
93.2227
8505
93.2222
8750
93.2217
9337
93.2212
9577
93.2207
9996
93.2201
10374
93.2196
11587
93.2191
14010
93.2186
18042
93.218
24192
93.2175
32140
93.217
37509
93.2165
36450
93.216
28992
93.2154
21052
93.2149
13962
93.2144
9496
93.2139
7532
93.2133
6889
93.2128
6278
93.2123
6313
93.2118
6392
93.2112
6714
93.2107
7373
93.2102
8496
93.2097
10573
93.2091
14708
93.2086
20729
93.2081
30352
93.2076
41647
93.207
48492
93.2065
45464
93.206
35428
93.2055
23385
93.2049
13840
93.2044
7827
93.2039
5280
93.2033
4030
93.2028
3357
93.2023
2927
93.2018
2701
93.2012
2366
93.2007
2116
93.2002
1886
93.1997
1780
93.1991
1685
93.1986
1616
93.1981
1572
93.1975
In 3d5 10
C:\Datafiles\users\MIT\berggren\emmabat\211206\Temp104.1.ITOSA3ci+1_1.pro:1:1:1.ITOSA3ci
2021
12
6
0
0
0
0
9
Casa Info Follows
0
0
0
0
1.ITOSA3ci
( 0.003689 m , 0.005537 m , 0.169504 m ) Angle: 45.0062 degrees , -0.1 degrees
emmabat211206
1 1
XPS
540
Al
1486.6
50.38
200
200
1e+037
1e+037
FAT
93.9
1e+037
4.399
1e+037
1e+037
1e+037
1e+037
1e+037
In
3d5
-1
Kinetic Energy
eV
1030.6
0.4
2
Intensity
d
Transmission
d
pulse counting
0.2
1
1e+037
1e+037
1e+037
1e+037
2
ESCAPE DEPTH TYPE
d
0
PHI_AtomicNumber
d
49
102
0
1
0
1
7944
93.2238
8019
93.2233
7984
93.2227
8361
93.2222
8588
93.2217
9072
93.2212
9552
93.2207
9742
93.2201
10364
93.2196
11557
93.2191
13955
93.2186
18155
93.218
24667
93.2175
32903
93.217
38198
93.2165
36224
93.216
28517
93.2154
19828
93.2149
12970
93.2144
9213
93.2139
7312
93.2133
6613
93.2128
6306
93.2123
6130
93.2118
6419
93.2112
6571
93.2107
7172
93.2102
8348
93.2097
10918
93.2091
14951
93.2086
21370
93.2081
31419
93.2076
43202
93.207
49538
93.2065
45346
93.206
33800
93.2055
22002
93.2049
12862
93.2044
7418
93.2039
5142
93.2033
4111
93.2028
3442
93.2023
2901
93.2018
2572
93.2012
2346
93.2007
2109
93.2002
1878
93.1997
1710
93.1991
1614
93.1986
1588
93.1981
1463
93.1975
In 3d5 11
C:\Datafiles\users\MIT\berggren\emmabat\211206\Temp104.1.ITOSA3ci+1_1.pro:1:1:1.ITOSA3ci
2021
12
6
0
0
0
0
9
Casa Info Follows
0
0
0
0
1.ITOSA3ci
( 0.003689 m , 0.005537 m , 0.169504 m ) Angle: 45.0062 degrees , -0.1 degrees
emmabat211206
1 1
XPS
600
Al
1486.6
50.38
200
200
1e+037
1e+037
FAT
93.9
1e+037
4.399
1e+037
1e+037
1e+037
1e+037
1e+037
In
3d5
-1
Kinetic Energy
eV
1030.6
0.4
2
Intensity
d
Transmission
d
pulse counting
0.2
1
1e+037
1e+037
1e+037
1e+037
2
ESCAPE DEPTH TYPE
d
0
PHI_AtomicNumber
d
49
102
0
1
0
1
7693
93.2238
7766
93.2233
7938
93.2227
8086
93.2222
8363
93.2217
8744
93.2212
9139
93.2207
9525
93.2201
10091
93.2196
11578
93.2191
13764
93.2186
18391
93.218
25076
93.2175
33637
93.217
38706
93.2165
36483
93.216
27290
93.2154
18672
93.2149
12419
93.2144
8875
93.2139
7216
93.2133
6583
93.2128
6182
93.2123
6106
93.2118
6271
93.2112
6566
93.2107
7233
93.2102
8476
93.2097
10966
93.2091
15263
93.2086
21948
93.2081
32100
93.2076
43591
93.207
50033
93.2065
45690
93.206
33071
93.2055
20777
93.2049
11831
93.2044
7172
93.2039
4878
93.2033
3957
93.2028
3205
93.2023
2827
93.2018
2608
93.2012
2266
93.2007
2066
93.2002
1931
93.1997
1873
93.1991
1636
93.1986
1629
93.1981
1557
93.1975
In 3d5 12
C:\Datafiles\users\MIT\berggren\emmabat\211206\Temp104.1.ITOSA3ci+1_1.pro:1:1:1.ITOSA3ci
2021
12
6
0
0
0
0
9
Casa Info Follows
0
0
0
0
1.ITOSA3ci
( 0.003689 m , 0.005537 m , 0.169504 m ) Angle: 45.0062 degrees , -0.1 degrees
emmabat211206
1 1
XPS
660
Al
1486.6
50.38
200
200
1e+037
1e+037
FAT
93.9
1e+037
4.399
1e+037
1e+037
1e+037
1e+037
1e+037
In
3d5
-1
Kinetic Energy
eV
1030.6
0.4
2
Intensity
d
Transmission
d
pulse counting
0.2
1
1e+037
1e+037
1e+037
1e+037
2
ESCAPE DEPTH TYPE
d
0
PHI_AtomicNumber
d
49
102
0
1
0
1
7663
93.2238
7554
93.2233
7787
93.2227
7927
93.2222
8404
93.2217
8548
93.2212
8883
93.2207
9369
93.2201
9850
93.2196
11478
93.2191
13885
93.2186
18659
93.218
25302
93.2175
34018
93.217
38688
93.2165
35959
93.216
27071
93.2154
18066
93.2149
11825
93.2144
8604
93.2139
7016
93.2133
6415
93.2128
5968
93.2123
5993
93.2118
6056
93.2112
6619
93.2107
7172
93.2102
8489
93.2097
10840
93.2091
15319
93.2086
22517
93.2081
32667
93.2076
44508
93.207
50501
93.2065
45487
93.206
32474
93.2055
19910
93.2049
11320
93.2044
6852
93.2039
4972
93.2033
3833
93.2028
3233
93.2023
2908
93.2018
2467
93.2012
2379
93.2007
2063
93.2002
1957
93.1997
1767
93.1991
1640
93.1986
1481
93.1981
1520
93.1975
In 3d5 13
C:\Datafiles\users\MIT\berggren\emmabat\211206\Temp104.1.ITOSA3ci+1_1.pro:1:1:1.ITOSA3ci
2021
12
6
0
0
0
0
9
Casa Info Follows
0
0
0
0
1.ITOSA3ci
( 0.003689 m , 0.005537 m , 0.169504 m ) Angle: 45.0062 degrees , -0.1 degrees
emmabat211206
1 1
XPS
720
Al
1486.6
50.38
200
200
1e+037
1e+037
FAT
93.9
1e+037
4.399
1e+037
1e+037
1e+037
1e+037
1e+037
In
3d5
-1
Kinetic Energy
eV
1030.6
0.4
2
Intensity
d
Transmission
d
pulse counting
0.2
1
1e+037
1e+037
1e+037
1e+037
2
ESCAPE DEPTH TYPE
d
0
PHI_AtomicNumber
d
49
102
0
1
0
1
7680
93.2238
7665
93.2233
7793
93.2227
7970
93.2222
8178
93.2217
8428
93.2212
8923
93.2207
9249
93.2201
10066
93.2196
11563
93.2191
14552
93.2186
19045
93.218
25922
93.2175
33811
93.217
38884
93.2165
36031
93.216
26914
93.2154
17305
93.2149
11660
93.2144
8361
93.2139
6953
93.2133
6308
93.2128
6146
93.2123
6094
93.2118
6239
93.2112
6646
93.2107
7073
93.2102
8800
93.2097
11205
93.2091
15863
93.2086
22849
93.2081
33468
93.2076
45351
93.207
51677
93.2065
45385
93.206
32020
93.2055
19049
93.2049
10816
93.2044
6799
93.2039
4838
93.2033
3853
93.2028
3190
93.2023
2913
93.2018
2538
93.2012
2244
93.2007
2011
93.2002
1875
93.1997
1793
93.1991
1607
93.1986
1542
93.1981
1477
93.1975
In 3d5 14
C:\Datafiles\users\MIT\berggren\emmabat\211206\Temp104.1.ITOSA3ci+1_1.pro:1:1:1.ITOSA3ci
2021
12
6
0
0
0
0
9
Casa Info Follows
0
0
0
0
1.ITOSA3ci
( 0.003689 m , 0.005537 m , 0.169504 m ) Angle: 45.0062 degrees , -0.1 degrees
emmabat211206
1 1
XPS
780
Al
1486.6
50.38
200
200
1e+037
1e+037
FAT
93.9
1e+037
4.399
1e+037
1e+037
1e+037
1e+037
1e+037
In
3d5
-1
Kinetic Energy
eV
1030.6
0.4
2
Intensity
d
Transmission
d
pulse counting
0.2
1
1e+037
1e+037
1e+037
1e+037
2
ESCAPE DEPTH TYPE
d
0
PHI_AtomicNumber
d
49
102
0
1
0
1
7373
93.2238
7564
93.2233
7668
93.2227
7696
93.2222
7995
93.2217
8364
93.2212
8683
93.2207
9313
93.2201
9954
93.2196
11382
93.2191
14170
93.2186
18898
93.218
26276
93.2175
34457
93.217
39585
93.2165
35862
93.216
26523
93.2154
16852
93.2149
11208
93.2144
8237
93.2139
7011
93.2133
6479
93.2128
6040
93.2123
5987
93.2118
6136
93.2112
6691
93.2107
7338
93.2102
8808
93.2097
11393
93.2091
16107
93.2086
23101
93.2081
33993
93.2076
45939
93.207
51871
93.2065
45371
93.206
30900
93.2055
18212
93.2049
10258
93.2044
6455
93.2039
4942
93.2033
3880
93.2028
3205
93.2023
2800
93.2018
2472
93.2012
2217
93.2007
1951
93.2002
1843
93.1997
1627
93.1991
1634
93.1986
1497
93.1981
1422
93.1975
In 3d5 15
C:\Datafiles\users\MIT\berggren\emmabat\211206\Temp104.1.ITOSA3ci+1_1.pro:1:1:1.ITOSA3ci
2021
12
6
0
0
0
0
9
Casa Info Follows
0
0
0
0
1.ITOSA3ci
( 0.003689 m , 0.005537 m , 0.169504 m ) Angle: 45.0062 degrees , -0.1 degrees
emmabat211206
1 1
XPS
840
Al
1486.6
50.38
200
200
1e+037
1e+037
FAT
93.9
1e+037
4.399
1e+037
1e+037
1e+037
1e+037
1e+037
In
3d5
-1
Kinetic Energy
eV
1030.6
0.4
2
Intensity
d
Transmission
d
pulse counting
0.2
1
1e+037
1e+037
1e+037
1e+037
2
ESCAPE DEPTH TYPE
d
0
PHI_AtomicNumber
d
49
102
0
1
0
1
7441
93.2238
7586
93.2233
7493
93.2227
7560
93.2222
7806
93.2217
8166
93.2212
8580
93.2207
8950
93.2201
9804
93.2196
11426
93.2191
14095
93.2186
18734
93.218
26287
93.2175
34553
93.217
39462
93.2165
35655
93.216
25963
93.2154
16514
93.2149
10764
93.2144
7947
93.2139
6963
93.2133
6315
93.2128
6088
93.2123
6028
93.2118
6233
93.2112
6602
93.2107
7273
93.2102
8622
93.2097
11320
93.2091
16038
93.2086
23469
93.2081
34449
93.2076
46561
93.207
52322
93.2065
45669
93.206
30414
93.2055
17815
93.2049
10044
93.2044
6540
93.2039
4609
93.2033
3680
93.2028
3073
93.2023
2788
93.2018
2451
93.2012
2254
93.2007
2021
93.2002
1943
93.1997
1696
93.1991
1577
93.1986
1466
93.1981
1488
93.1975
In 3d5 16
C:\Datafiles\users\MIT\berggren\emmabat\211206\Temp104.1.ITOSA3ci+1_1.pro:1:1:1.ITOSA3ci
2021
12
6
0
0
0
0
9
Casa Info Follows
0
0
0
0
1.ITOSA3ci
( 0.003689 m , 0.005537 m , 0.169504 m ) Angle: 45.0062 degrees , -0.1 degrees
emmabat211206
1 1
XPS
900
Al
1486.6
50.38
200
200
1e+037
1e+037
FAT
93.9
1e+037
4.399
1e+037
1e+037
1e+037
1e+037
1e+037
In
3d5
-1
Kinetic Energy
eV
1030.6
0.4
2
Intensity
d
Transmission
d
pulse counting
0.2
1
1e+037
1e+037
1e+037
1e+037
2
ESCAPE DEPTH TYPE
d
0
PHI_AtomicNumber
d
49
102
0
1
0
1
7329
93.2238
7268
93.2233
7328
93.2227
7514
93.2222
7825
93.2217
8058
93.2212
8432
93.2207
8844
93.2201
9606
93.2196
11328
93.2191
14297
93.2186
19184
93.218
26496
93.2175
34988
93.217
39509
93.2165
36108
93.216
25823
93.2154
15874
93.2149
10694
93.2144
8005
93.2139
6924
93.2133
6186
93.2128
5912
93.2123
5706
93.2118
6093
93.2112
6538
93.2107
7214
93.2102
8842
93.2097
11345
93.2091
16041
93.2086
23691
93.2081
34606
93.2076
46784
93.207
52321
93.2065
45584
93.206
30594
93.2055
17310
93.2049
9717
93.2044
6334
93.2039
4577
93.2033
3684
93.2028
3139
93.2023
2697
93.2018
2419
93.2012
2220
93.2007
2101
93.2002
1759
93.1997
1732
93.1991
1641
93.1986
1585
93.1981
1381
93.1975
In 3d5 17
C:\Datafiles\users\MIT\berggren\emmabat\211206\Temp104.1.ITOSA3ci+1_1.pro:1:1:1.ITOSA3ci
2021
12
6
0
0
0
0
9
Casa Info Follows
0
0
0
0
1.ITOSA3ci
( 0.003689 m , 0.005537 m , 0.169504 m ) Angle: 45.0062 degrees , -0.1 degrees
emmabat211206
1 1
XPS
960
Al
1486.6
50.38
200
200
1e+037
1e+037
FAT
93.9
1e+037
4.399
1e+037
1e+037
1e+037
1e+037
1e+037
In
3d5
-1
Kinetic Energy
eV
1030.6
0.4
2
Intensity
d
Transmission
d
pulse counting
0.2
1
1e+037
1e+037
1e+037
1e+037
2
ESCAPE DEPTH TYPE
d
0
PHI_AtomicNumber
d
49
102
0
1
0
1
7360
93.2238
7269
93.2233
7431
93.2227
7475
93.2222
7572
93.2217
7938
93.2212
8279
93.2207
8678
93.2201
9712
93.2196
11265
93.2191
14260
93.2186
19200
93.218
26759
93.2175
35231
93.217
39632
93.2165
35598
93.216
25563
93.2154
15939
93.2149
10325
93.2144
7865
93.2139
6730
93.2133
6241
93.2128
6008
93.2123
5831
93.2118
6143
93.2112
6504
93.2107
7446
93.2102
8846
93.2097
11502
93.2091
16120
93.2086
24053
93.2081
35162
93.2076
47486
93.207
52726
93.2065
45168
93.206
29737
93.2055
16674
93.2049
9442
93.2044
6128
93.2039
4432
93.2033
3767
93.2028
3073
93.2023
2680
93.2018
2389
93.2012
2113
93.2007
1979
93.2002
1797
93.1997
1684
93.1991
1549
93.1986
1480
93.1981
1419
93.1975
In 3d5 18
C:\Datafiles\users\MIT\berggren\emmabat\211206\Temp104.1.ITOSA3ci+1_1.pro:1:1:1.ITOSA3ci
2021
12
6
0
0
0
0
9
Casa Info Follows
0
0
0
0
1.ITOSA3ci
( 0.003689 m , 0.005537 m , 0.169504 m ) Angle: 45.0062 degrees , -0.1 degrees
emmabat211206
1 1
XPS
1020
Al
1486.6
50.38
200
200
1e+037
1e+037
FAT
93.9
1e+037
4.399
1e+037
1e+037
1e+037
1e+037
1e+037
In
3d5
-1
Kinetic Energy
eV
1030.6
0.4
2
Intensity
d
Transmission
d
pulse counting
0.2
1
1e+037
1e+037
1e+037
1e+037
2
ESCAPE DEPTH TYPE
d
0
PHI_AtomicNumber
d
49
102
0
1
0
1
7343
93.2238
7414
93.2233
7392
93.2227
7577
93.2222
7467
93.2217
7782
93.2212
8189
93.2207
8590
93.2201
9601
93.2196
11278
93.2191
14232
93.2186
19204
93.218
26910
93.2175
35356
93.217
39906
93.2165
36049
93.216
24803
93.2154
15233
93.2149
9965
93.2144
7541
93.2139
6655
93.2133
6258
93.2128
5908
93.2123
6024
93.2118
5999
93.2112
6377
93.2107
7229
93.2102
8705
93.2097
11332
93.2091
16390
93.2086
24063
93.2081
35605
93.2076
47828
93.207
53104
93.2065
44805
93.206
29666
93.2055
16428
93.2049
9227
93.2044
5965
93.2039
4497
93.2033
3624
93.2028
3137
93.2023
2784
93.2018
2469
93.2012
2149
93.2007
2024
93.2002
1769
93.1997
1670
93.1991
1621
93.1986
1459
93.1981
1381
93.1975
In 3d5 19
C:\Datafiles\users\MIT\berggren\emmabat\211206\Temp104.1.ITOSA3ci+1_1.pro:1:1:1.ITOSA3ci
2021
12
6
0
0
0
0
9
Casa Info Follows
0
0
0
0
1.ITOSA3ci
( 0.003689 m , 0.005537 m , 0.169504 m ) Angle: 45.0062 degrees , -0.1 degrees
emmabat211206
1 1
XPS
1080
Al
1486.6
50.38
200
200
1e+037
1e+037
FAT
93.9
1e+037
4.399
1e+037
1e+037
1e+037
1e+037
1e+037
In
3d5
-1
Kinetic Energy
eV
1030.6
0.4
2
Intensity
d
Transmission
d
pulse counting
0.2
1
1e+037
1e+037
1e+037
1e+037
2
ESCAPE DEPTH TYPE
d
0
PHI_AtomicNumber
d
49
102
0
1
0
1
7133
93.2238
7134
93.2233
7166
93.2227
7222
93.2222
7595
93.2217
7728
93.2212
8156
93.2207
8675
93.2201
9726
93.2196
11286
93.2191
14060
93.2186
19261
93.218
27279
93.2175
35331
93.217
40036
93.2165
35590
93.216
24603
93.2154
15151
93.2149
9923
93.2144
7627
93.2139
6665
93.2133
6171
93.2128
5771
93.2123
5813
93.2118
5896
93.2112
6417
93.2107
7149
93.2102
8703
93.2097
11618
93.2091
16503
93.2086
24491
93.2081
35870
93.2076
47997
93.207
53178
93.2065
44862
93.206
28775
93.2055
16015
93.2049
9060
93.2044
6049
93.2039
4459
93.2033
3566
93.2028
3070
93.2023
2734
93.2018
2444
93.2012
2211
93.2007
2041
93.2002
1845
93.1997
1704
93.1991
1591
93.1986
1483
93.1981
1474
93.1975
In 3d5 20
C:\Datafiles\users\MIT\berggren\emmabat\211206\Temp104.1.ITOSA3ci+1_1.pro:1:1:1.ITOSA3ci
2021
12
6
0
0
0
0
9
Casa Info Follows
0
0
0
0
1.ITOSA3ci
( 0.003689 m , 0.005537 m , 0.169504 m ) Angle: 45.0062 degrees , -0.1 degrees
emmabat211206
1 1
XPS
1140
Al
1486.6
50.38
200
200
1e+037
1e+037
FAT
93.9
1e+037
4.399
1e+037
1e+037
1e+037
1e+037
1e+037
In
3d5
-1
Kinetic Energy
eV
1030.6
0.4
2
Intensity
d
Transmission
d
pulse counting
0.2
1
1e+037
1e+037
1e+037
1e+037
2
ESCAPE DEPTH TYPE
d
0
PHI_AtomicNumber
d
49
102
0
1
0
1
7007
93.2238
7064
93.2233
7175
93.2227
7272
93.2222
7563
93.2217
7700
93.2212
7922
93.2207
8567
93.2201
9452
93.2196
11264
93.2191
14397
93.2186
19487
93.218
27406
93.2175
35786
93.217
40225
93.2165
35535
93.216
24707
93.2154
15023
93.2149
9682
93.2144
7538
93.2139
6560
93.2133
5914
93.2128
5581
93.2123
5609
93.2118
5906
93.2112
6295
93.2107
7108
93.2102
8828
93.2097
11657
93.2091
16930
93.2086
24390
93.2081
36361
93.2076
48397
93.207
53583
93.2065
44849
93.206
28940
93.2055
15781
93.2049
8788
93.2044
5765
93.2039
4402
93.2033
3550
93.2028
3083
93.2023
2628
93.2018
2388
93.2012
2128
93.2007
1987
93.2002
1774
93.1997
1585
93.1991
1556
93.1986
1402
93.1981
1436
93.1975
In 3d5 21
C:\Datafiles\users\MIT\berggren\emmabat\211206\Temp104.1.ITOSA3ci+1_1.pro:1:1:1.ITOSA3ci
2021
12
6
0
0
0
0
9
Casa Info Follows
0
0
0
0
1.ITOSA3ci
( 0.003689 m , 0.005537 m , 0.169504 m ) Angle: 45.0062 degrees , -0.1 degrees
emmabat211206
1 1
XPS
1200
Al
1486.6
50.38
200
200
1e+037
1e+037
FAT
93.9
1e+037
4.399
1e+037
1e+037
1e+037
1e+037
1e+037
In
3d5
-1
Kinetic Energy
eV
1030.6
0.4
2
Intensity
d
Transmission
d
pulse counting
0.2
1
1e+037
1e+037
1e+037
1e+037
2
ESCAPE DEPTH TYPE
d
0
PHI_AtomicNumber
d
49
102
0
1
0
1
6915
93.2238
6989
93.2233
7159
93.2227
7144
93.2222
7356
93.2217
7590
93.2212
8088
93.2207
8411
93.2201
9294
93.2196
11130
93.2191
14415
93.2186
19585
93.218
27161
93.2175
35880
93.217
40159
93.2165
35363
93.216
24536
93.2154
14963
93.2149
9502
93.2144
7383
93.2139
6486
93.2133
6013
93.2128
5774
93.2123
5708
93.2118
5940
93.2112
6339
93.2107
7289
93.2102
8723
93.2097
11660
93.2091
16698
93.2086
24621
93.2081
36597
93.2076
48580
93.207
53505
93.2065
44716
93.206
28385
93.2055
15362
93.2049
8685
93.2044
5672
93.2039
4483
93.2033
3487
93.2028
3146
93.2023
2580
93.2018
2328
93.2012
2189
93.2007
1907
93.2002
1770
93.1997
1616
93.1991
1559
93.1986
1417
93.1981
1397
93.1975
In 3d5 22
C:\Datafiles\users\MIT\berggren\emmabat\211206\Temp104.1.ITOSA3ci+1_1.pro:1:1:1.ITOSA3ci
2021
12
6
0
0
0
0
9
Casa Info Follows
0
0
0
0
1.ITOSA3ci
( 0.003689 m , 0.005537 m , 0.169504 m ) Angle: 45.0062 degrees , -0.1 degrees
emmabat211206
1 1
XPS
1260
Al
1486.6
50.38
200
200
1e+037
1e+037
FAT
93.9
1e+037
4.399
1e+037
1e+037
1e+037
1e+037
1e+037
In
3d5
-1
Kinetic Energy
eV
1030.6
0.4
2
Intensity
d
Transmission
d
pulse counting
0.2
1
1e+037
1e+037
1e+037
1e+037
2
ESCAPE DEPTH TYPE
d
0
PHI_AtomicNumber
d
49
102
0
1
0
1
7109
93.2238
7175
93.2233
7049
93.2227
7256
93.2222
7318
93.2217
7638
93.2212
7821
93.2207
8267
93.2201
9437
93.2196
10999
93.2191
14368
93.2186
19544
93.218
27268
93.2175
35817
93.217
40128
93.2165
35032
93.216
23864
93.2154
14405
93.2149
9617
93.2144
7401
93.2139
6432
93.2133
5987
93.2128
5825
93.2123
5741
93.2118
5815
93.2112
6413
93.2107
7226
93.2102
8827
93.2097
11672
93.2091
16737
93.2086
24839
93.2081
36711
93.2076
48505
93.207
53093
93.2065
44489
93.206
28217
93.2055
15395
93.2049
8719
93.2044
5775
93.2039
4432
93.2033
3599
93.2028
3058
93.2023
2637
93.2018
2424
93.2012
2065
93.2007
1873
93.2002
1763
93.1997
1640
93.1991
1601
93.1986
1434
93.1981
1331
93.1975
In 3d5 23
C:\Datafiles\users\MIT\berggren\emmabat\211206\Temp104.1.ITOSA3ci+1_1.pro:1:1:1.ITOSA3ci
2021
12
6
0
0
0
0
9
Casa Info Follows
0
0
0
0
1.ITOSA3ci
( 0.003689 m , 0.005537 m , 0.169504 m ) Angle: 45.0062 degrees , -0.1 degrees
emmabat211206
1 1
XPS
1320
Al
1486.6
50.38
200
200
1e+037
1e+037
FAT
93.9
1e+037
4.399
1e+037
1e+037
1e+037
1e+037
1e+037
In
3d5
-1
Kinetic Energy
eV
1030.6
0.4
2
Intensity
d
Transmission
d
pulse counting
0.2
1
1e+037
1e+037
1e+037
1e+037
2
ESCAPE DEPTH TYPE
d
0
PHI_AtomicNumber
d
49
102
0
1
0
1
7016
93.2238
7081
93.2233
7060
93.2227
7234
93.2222
7089
93.2217
7594
93.2212
7878
93.2207
8579
93.2201
9382
93.2196
11278
93.2191
14331
93.2186
19786
93.218
27632
93.2175
36240
93.217
40153
93.2165
35086
93.216
24018
93.2154
14426
93.2149
9545
93.2144
7529
93.2139
6545
93.2133
5899
93.2128
5725
93.2123
5502
93.2118
5794
93.2112
6236
93.2107
7241
93.2102
8704
93.2097
11907
93.2091
17070
93.2086
25030
93.2081
36524
93.2076
49143
93.207
53490
93.2065
44281
93.206
27818
93.2055
15202
93.2049
8484
93.2044
5876
93.2039
4428
93.2033
3582
93.2028
3001
93.2023
2667
93.2018
2314
93.2012
2152
93.2007
1971
93.2002
1805
93.1997
1640
93.1991
1515
93.1986
1488
93.1981
1406
93.1975
In 3d5 24
C:\Datafiles\users\MIT\berggren\emmabat\211206\Temp104.1.ITOSA3ci+1_1.pro:1:1:1.ITOSA3ci
2021
12
6
0
0
0
0
9
Casa Info Follows
0
0
0
0
1.ITOSA3ci
( 0.003689 m , 0.005537 m , 0.169504 m ) Angle: 45.0062 degrees , -0.1 degrees
emmabat211206
1 1
XPS
1380
Al
1486.6
50.38
200
200
1e+037
1e+037
FAT
93.9
1e+037
4.399
1e+037
1e+037
1e+037
1e+037
1e+037
In
3d5
-1
Kinetic Energy
eV
1030.6
0.4
2
Intensity
d
Transmission
d
pulse counting
0.2
1
1e+037
1e+037
1e+037
1e+037
2
ESCAPE DEPTH TYPE
d
0
PHI_AtomicNumber
d
49
102
0
1
0
1
6933
93.2238
6892
93.2233
7055
93.2227
7052
93.2222
7193
93.2217
7506
93.2212
7909
93.2207
8480
93.2201
9388
93.2196
11392
93.2191
14558
93.2186
20049
93.218
27698
93.2175
36120
93.217
39916
93.2165
34875
93.216
23648
93.2154
14273
93.2149
9569
93.2144
7369
93.2139
6270
93.2133
5948
93.2128
5738
93.2123
5713
93.2118
5743
93.2112
6491
93.2107
7190
93.2102
8719
93.2097
11788
93.2091
16942
93.2086
25240
93.2081
37032
93.2076
49089
93.207
53678
93.2065
44355
93.206
27383
93.2055
15100
93.2049
8505
93.2044
5672
93.2039
4433
93.2033
3542
93.2028
3056
93.2023
2626
93.2018
2351
93.2012
2109
93.2007
1947
93.2002
1730
93.1997
1565
93.1991
1531
93.1986
1469
93.1981
1434
93.1975
In 3d5 25
C:\Datafiles\users\MIT\berggren\emmabat\211206\Temp104.1.ITOSA3ci+1_1.pro:1:1:1.ITOSA3ci
2021
12
6
0
0
0
0
9
Casa Info Follows
0
0
0
0
1.ITOSA3ci
( 0.003689 m , 0.005537 m , 0.169504 m ) Angle: 45.0062 degrees , -0.1 degrees
emmabat211206
1 1
XPS
1440
Al
1486.6
50.38
200
200
1e+037
1e+037
FAT
93.9
1e+037
4.399
1e+037
1e+037
1e+037
1e+037
1e+037
In
3d5
-1
Kinetic Energy
eV
1030.6
0.4
2
Intensity
d
Transmission
d
pulse counting
0.2
1
1e+037
1e+037
1e+037
1e+037
2
ESCAPE DEPTH TYPE
d
0
PHI_AtomicNumber
d
49
102
0
1
0
1
6821
93.2238
6952
93.2233
6802
93.2227
7069
93.2222
7292
93.2217
7557
93.2212
7737
93.2207
8291
93.2201
9404
93.2196
11163
93.2191
14420
93.2186
19824
93.218
27560
93.2175
36386
93.217
40077
93.2165
35054
93.216
23379
93.2154
14101
93.2149
9249
93.2144
7251
93.2139
6249
93.2133
5895
93.2128
5606
93.2123
5634
93.2118
5770
93.2112
6407
93.2107
7069
93.2102
8833
93.2097
11898
93.2091
17010
93.2086
25261
93.2081
36980
93.2076
48767
93.207
53807
93.2065
44231
93.206
27687
93.2055
14890
93.2049
8313
93.2044
5725
93.2039
4243
93.2033
3527
93.2028
2994
93.2023
2543
93.2018
2350
93.2012
2173
93.2007
1943
93.2002
1739
93.1997
1677
93.1991
1523
93.1986
1491
93.1981
1334
93.1975
In 3d5 26
C:\Datafiles\users\MIT\berggren\emmabat\211206\Temp104.1.ITOSA3ci+1_1.pro:1:1:1.ITOSA3ci
2021
12
6
0
0
0
0
9
Casa Info Follows
0
0
0
0
1.ITOSA3ci
( 0.003689 m , 0.005537 m , 0.169504 m ) Angle: 45.0062 degrees , -0.1 degrees
emmabat211206
1 1
XPS
1500
Al
1486.6
50.38
200
200
1e+037
1e+037
FAT
93.9
1e+037
4.399
1e+037
1e+037
1e+037
1e+037
1e+037
In
3d5
-1
Kinetic Energy
eV
1030.6
0.4
2
Intensity
d
Transmission
d
pulse counting
0.2
1
1e+037
1e+037
1e+037
1e+037
2
ESCAPE DEPTH TYPE
d
0
PHI_AtomicNumber
d
49
102
0
1
0
1
7041
93.2238
7014
93.2233
6933
93.2227
7138
93.2222
7200
93.2217
7494
93.2212
7945
93.2207
8308
93.2201
9420
93.2196
11187
93.2191
14385
93.2186
19727
93.218
27685
93.2175
36280
93.217
39978
93.2165
34485
93.216
23419
93.2154
14103
93.2149
9339
93.2144
7268
93.2139
6190
93.2133
5792
93.2128
5646
93.2123
5683
93.2118
5862
93.2112
6336
93.2107
7048
93.2102
8627
93.2097
11734
93.2091
16891
93.2086
25161
93.2081
37242
93.2076
49459
93.207
53589
93.2065
44262
93.206
27381
93.2055
14745
93.2049
8515
93.2044
5684
93.2039
4236
93.2033
3473
93.2028
3057
93.2023
2653
93.2018
2327
93.2012
2049
93.2007
1848
93.2002
1762
93.1997
1606
93.1991
1565
93.1986
1405
93.1981
1413
93.1975
In 3d5 27
C:\Datafiles\users\MIT\berggren\emmabat\211206\Temp104.1.ITOSA3ci+1_1.pro:1:1:1.ITOSA3ci
2021
12
6
0
0
0
0
9
Casa Info Follows
0
0
0
0
1.ITOSA3ci
( 0.003689 m , 0.005537 m , 0.169504 m ) Angle: 45.0062 degrees , -0.1 degrees
emmabat211206
1 1
XPS
1560
Al
1486.6
50.38
200
200
1e+037
1e+037
FAT
93.9
1e+037
4.399
1e+037
1e+037
1e+037
1e+037
1e+037
In
3d5
-1
Kinetic Energy
eV
1030.6
0.4
2
Intensity
d
Transmission
d
pulse counting
0.2
1
1e+037
1e+037
1e+037
1e+037
2
ESCAPE DEPTH TYPE
d
0
PHI_AtomicNumber
d
49
102
0
1
0
1
6829
93.2238
6917
93.2233
6970
93.2227
6923
93.2222
7084
93.2217
7496
93.2212
7759
93.2207
8478
93.2201
9224
93.2196
11394
93.2191
14529
93.2186
19919
93.218
27602
93.2175
36300
93.217
39821
93.2165
34374
93.216
23224
93.2154
14287
93.2149
9159
93.2144
7308
93.2139
6202
93.2133
5764
93.2128
5561
93.2123
5473
93.2118
5734
93.2112
6223
93.2107
7145
93.2102
8894
93.2097
11977
93.2091
16999
93.2086
25775
93.2081
36942
93.2076
49282
93.207
53601
93.2065
43962
93.206
27432
93.2055
14266
93.2049
8201
93.2044
5648
93.2039
4224
93.2033
3429
93.2028
2965
93.2023
2573
93.2018
2218
93.2012
2044
93.2007
1911
93.2002
1749
93.1997
1632
93.1991
1516
93.1986
1404
93.1981
1399
93.1975
In 3d5 28
C:\Datafiles\users\MIT\berggren\emmabat\211206\Temp104.1.ITOSA3ci+1_1.pro:1:1:1.ITOSA3ci
2021
12
6
0
0
0
0
9
Casa Info Follows
0
0
0
0
1.ITOSA3ci
( 0.003689 m , 0.005537 m , 0.169504 m ) Angle: 45.0062 degrees , -0.1 degrees
emmabat211206
1 1
XPS
1620
Al
1486.6
50.38
200
200
1e+037
1e+037
FAT
93.9
1e+037
4.399
1e+037
1e+037
1e+037
1e+037
1e+037
In
3d5
-1
Kinetic Energy
eV
1030.6
0.4
2
Intensity
d
Transmission
d
pulse counting
0.2
1
1e+037
1e+037
1e+037
1e+037
2
ESCAPE DEPTH TYPE
d
0
PHI_AtomicNumber
d
49
102
0
1
0
1
6811
93.2238
6833
93.2233
6778
93.2227
6981
93.2222
7196
93.2217
7342
93.2212
7738
93.2207
8365
93.2201
9484
93.2196
11182
93.2191
14328
93.2186
19574
93.218
27860
93.2175
36546
93.217
40144
93.2165
34229
93.216
23077
93.2154
13645
93.2149
9179
93.2144
7197
93.2139
6291
93.2133
5869
93.2128
5680
93.2123
5695
93.2118
5776
93.2112
6298
93.2107
7253
93.2102
8881
93.2097
12032
93.2091
17167
93.2086
25453
93.2081
37446
93.2076
49303
93.207
52817
93.2065
43429
93.206
26790
93.2055
14210
93.2049
8233
93.2044
5620
93.2039
4173
93.2033
3555
93.2028
2946
93.2023
2658
93.2018
2427
93.2012
2043
[...]
C
1s
-1
Kinetic Energy
eV
1191.6
0.5
2
Intensity
d
Transmission
d
pulse counting
0.1
1
1e+037
1e+037
1e+037
1e+037
2
ESCAPE DEPTH TYPE
d
0
PHI_AtomicNumber
d
6
82
0
1
0
1
839
116.676
853
116.675
773
116.675
882
116.674
851
116.674
838
116.673
839
116.672
787
116.672
898
116.671
824
116.671
835
116.67
833
116.669
882
116.669
852
116.668
865
116.668
784
116.667
853
116.666
855
116.666
838
116.665
863
116.665
837
116.664
831
116.663
868
116.663
887
116.662
873
116.661
850
116.661
862
116.66
852
116.66
899
116.659
827
116.658
813
116.658
840
116.657
872
116.657
844
116.656
893
116.655
837
116.655
879
116.654
837
116.654
835
116.653
825
116.652
856
116.652
C 1s 118
C:\Datafiles\users\MIT\berggren\emmabat\211206\Temp104.1.ITOSA3ci+1_1.pro:1:1:1.ITOSA3ci
2021
12
6
0
0
0
0
9
Casa Info Follows
0
0
0
0
1.ITOSA3ci
( 0.003689 m , 0.005537 m , 0.169504 m ) Angle: 45.0062 degrees , -0.1 degrees
emmabat211206
1 1
XPS
900
Al
1486.6
50.38
200
200
1e+037
1e+037
FAT
117.4
1e+037
4.399
1e+037
1e+037
1e+037
1e+037
1e+037
C
1s
-1
Kinetic Energy
eV
1191.6
0.5
2
Intensity
d
Transmission
d
pulse counting
0.1
1
1e+037
1e+037
1e+037
1e+037
2
ESCAPE DEPTH TYPE
d
0
PHI_AtomicNumber
d
6
82
0
1
0
1
855
116.676
865
116.675
814
116.675
818
116.674
829
116.674
876
116.673
821
116.672
831
116.672
843
116.671
860
116.671
842
116.67
841
116.669
856
116.669
810
116.668
846
116.668
880
116.667
835
116.666
811
116.666
828
116.665
877
116.665
824
116.664
832
116.663
861
116.663
866
116.662
836
116.661
841
116.661
833
116.66
867
116.66
889
116.659
838
116.658
818
116.658
845
116.657
837
116.657
844
116.656
841
116.655
833
116.655
900
116.654
827
116.654
856
116.653
847
116.652
854
116.652
C 1s 119
C:\Datafiles\users\MIT\berggren\emmabat\211206\Temp104.1.ITOSA3ci+1_1.pro:1:1:1.ITOSA3ci
2021
12
6
0
0
0
0
9
Casa Info Follows
0
0
0
0
1.ITOSA3ci
( 0.003689 m , 0.005537 m , 0.169504 m ) Angle: 45.0062 degrees , -0.1 degrees
emmabat211206
1 1
XPS
960
Al
1486.6
50.38
200
200
1e+037
1e+037
FAT
117.4
1e+037
4.399
1e+037
1e+037
1e+037
1e+037
1e+037
C
1s
-1
Kinetic Energy
eV
1191.6
0.5
2
Intensity
d
Transmission
d
pulse counting
0.1
1
1e+037
1e+037
1e+037
1e+037
2
ESCAPE DEPTH TYPE
d
0
PHI_AtomicNumber
d
6
82
0
1
0
1
832
116.676
805
116.675
769
116.675
831
116.674
832
116.674
897
116.673
832
116.672
785
116.672
794
116.671
835
116.671
794
116.67
781
116.669
877
116.669
895
116.668
818
116.668
796
116.667
821
116.666
848
116.666
819
116.665
843
116.665
839
116.664
831
116.663
851
116.663
899
116.662
823
116.661
857
116.661
820
116.66
840
116.66
836
116.659
841
116.658
851
116.658
805
116.657
847
116.657
796
116.656
893
116.655
826
116.655
869
116.654
888
116.654
911
116.653
890
116.652
867
116.652
C 1s 120
C:\Datafiles\users\MIT\berggren\emmabat\211206\Temp104.1.ITOSA3ci+1_1.pro:1:1:1.ITOSA3ci
2021
12
6
0
0
0
0
9
Casa Info Follows
0
0
0
0
1.ITOSA3ci
( 0.003689 m , 0.005537 m , 0.169504 m ) Angle: 45.0062 degrees , -0.1 degrees
emmabat211206
1 1
XPS
1020
Al
1486.6
50.38
200
200
1e+037
1e+037
FAT
117.4
1e+037
4.399
1e+037
1e+037
1e+037
1e+037
1e+037
C
1s
-1
Kinetic Energy
eV
1191.6
0.5
2
Intensity
d
Transmission
d
pulse counting
0.1
1
1e+037
1e+037
1e+037
1e+037
2
ESCAPE DEPTH TYPE
d
0
PHI_AtomicNumber
d
6
82
0
1
0
1
835
116.676
870
116.675
880
116.675
853
116.674
864
116.674
865
116.673
836
116.672
889
116.672
805
116.671
889
116.671
818
116.67
860
116.669
825
116.669
867
116.668
812
116.668
834
116.667
814
116.666
832
116.666
855
116.665
798
116.665
845
116.664
814
116.663
880
116.663
831
116.662
854
116.661
853
116.661
870
116.66
847
116.66
885
116.659
842
116.658
832
116.658
873
116.657
856
116.657
857
116.656
851
116.655
833
116.655
880
116.654
854
116.654
821
116.653
860
116.652
797
116.652
C 1s 121
C:\Datafiles\users\MIT\berggren\emmabat\211206\Temp104.1.ITOSA3ci+1_1.pro:1:1:1.ITOSA3ci
2021
12
6
0
0
0
0
9
Casa Info Follows
0
0
0
0
1.ITOSA3ci
( 0.003689 m , 0.005537 m , 0.169504 m ) Angle: 45.0062 degrees , -0.1 degrees
emmabat211206
1 1
XPS
1080
Al
1486.6
50.38
200
200
1e+037
1e+037
FAT
117.4
1e+037
4.399
1e+037
1e+037
1e+037
1e+037
1e+037
C
1s
-1
Kinetic Energy
eV
1191.6
0.5
2
Intensity
d
Transmission
d
pulse counting
0.1
1
1e+037
1e+037
1e+037
1e+037
2
ESCAPE DEPTH TYPE
d
0
PHI_AtomicNumber
d
6
82
0
1
0
1
780
116.676
809
116.675
795
116.675
856
116.674
856
116.674
865
116.673
804
116.672
814
116.672
816
116.671
866
116.671
801
116.67
865
116.669
846
116.669
818
116.668
856
116.668
821
116.667
833
116.666
787
116.666
867
116.665
791
116.665
850
116.664
835
116.663
832
116.663
807
116.662
878
116.661
835
116.661
853
116.66
867
116.66
829
116.659
899
116.658
826
116.658
773
116.657
814
116.657
843
116.656
832
116.655
781
116.655
820
116.654
793
116.654
875
116.653
825
116.652
849
116.652
C 1s 122
C:\Datafiles\users\MIT\berggren\emmabat\211206\Temp104.1.ITOSA3ci+1_1.pro:1:1:1.ITOSA3ci
2021
12
6
0
0
0
0
9
Casa Info Follows
0
0
0
0
1.ITOSA3ci
( 0.003689 m , 0.005537 m , 0.169504 m ) Angle: 45.0062 degrees , -0.1 degrees
emmabat211206
1 1
XPS
1140
Al
1486.6
50.38
200
200
1e+037
1e+037
FAT
117.4
1e+037
4.399
1e+037
1e+037
1e+037
1e+037
1e+037
C
1s
-1
Kinetic Energy
eV
1191.6
0.5
2
Intensity
d
Transmission
d
pulse counting
0.1
1
1e+037
1e+037
1e+037
1e+037
2
ESCAPE DEPTH TYPE
d
0
PHI_AtomicNumber
d
6
82
0
1
0
1
814
116.676
781
116.675
806
116.675
841
116.674
829
116.674
840
116.673
800
116.672
819
116.672
835
116.671
838
116.671
792
116.67
868
116.669
856
116.669
868
116.668
858
116.668
848
116.667
865
116.666
848
116.666
816
116.665
847
116.665
797
116.664
863
116.663
857
116.663
898
116.662
892
116.661
884
116.661
806
116.66
899
116.66
837
116.659
850
116.658
840
116.658
841
116.657
909
116.657
882
116.656
833
116.655
802
116.655
826
116.654
798
116.654
806
116.653
844
116.652
812
116.652
C 1s 123
C:\Datafiles\users\MIT\berggren\emmabat\211206\Temp104.1.ITOSA3ci+1_1.pro:1:1:1.ITOSA3ci
2021
12
6
0
0
0
0
9
Casa Info Follows
0
0
0
0
1.ITOSA3ci
( 0.003689 m , 0.005537 m , 0.169504 m ) Angle: 45.0062 degrees , -0.1 degrees
emmabat211206
1 1
XPS
1200
Al
1486.6
50.38
200
200
1e+037
1e+037
FAT
117.4
1e+037
4.399
1e+037
1e+037
1e+037
1e+037
1e+037
C
1s
-1
Kinetic Energy
eV
1191.6
0.5
2
Intensity
d
Transmission
d
pulse counting
0.1
1
1e+037
1e+037
1e+037
1e+037
2
ESCAPE DEPTH TYPE
d
0
PHI_AtomicNumber
d
6
82
0
1
0
1
796
116.676
822
116.675
808
116.675
805
116.674
799
116.674
831
116.673
824
116.672
810
116.672
776
116.671
791
116.671
831
116.67
814
116.669
850
116.669
829
116.668
832
116.668
796
116.667
837
116.666
817
116.666
835
116.665
836
116.665
816
116.664
820
116.663
789
116.663
826
116.662
806
116.661
839
116.661
853
116.66
845
116.66
805
116.659
880
116.658
872
116.658
853
116.657
837
116.657
830
116.656
839
116.655
828
116.655
814
116.654
872
116.654
846
116.653
860
116.652
897
116.652
C 1s 124
C:\Datafiles\users\MIT\berggren\emmabat\211206\Temp104.1.ITOSA3ci+1_1.pro:1:1:1.ITOSA3ci
2021
12
6
0
0
0
0
9
Casa Info Follows
0
0
0
0
1.ITOSA3ci
( 0.003689 m , 0.005537 m , 0.169504 m ) Angle: 45.0062 degrees , -0.1 degrees
emmabat211206
1 1
XPS
1260
Al
1486.6
50.38
200
200
1e+037
1e+037
FAT
117.4
1e+037
4.399
1e+037
1e+037
1e+037
1e+037
1e+037
C
1s
-1
Kinetic Energy
eV
1191.6
0.5
2
Intensity
d
Transmission
d
pulse counting
0.1
1
1e+037
1e+037
1e+037
1e+037
2
ESCAPE DEPTH TYPE
d
0
PHI_AtomicNumber
d
6
82
0
1
0
1
842
116.676
811
116.675
828
116.675
856
116.674
827
116.674
797
116.673
835
116.672
788
116.672
804
116.671
840
116.671
846
116.67
835
116.669
848
116.669
874
116.668
835
116.668
793
116.667
783
116.666
825
116.666
834
116.665
788
116.665
826
116.664
827
116.663
808
116.663
832
116.662
855
116.661
858
116.661
821
116.66
833
116.66
803
116.659
881
116.658
821
116.658
869
116.657
818
116.657
830
116.656
842
116.655
813
116.655
834
116.654
842
116.654
878
116.653
880
116.652
825
116.652
C 1s 125
C:\Datafiles\users\MIT\berggren\emmabat\211206\Temp104.1.ITOSA3ci+1_1.pro:1:1:1.ITOSA3ci
2021
12
6
0
0
0
0
9
Casa Info Follows
0
0
0
0
1.ITOSA3ci
( 0.003689 m , 0.005537 m , 0.169504 m ) Angle: 45.0062 degrees , -0.1 degrees
emmabat211206
1 1
XPS
1320
Al
1486.6
50.38
200
200
1e+037
1e+037
FAT
117.4
1e+037
4.399
1e+037
1e+037
1e+037
1e+037
1e+037
C
1s
-1
Kinetic Energy
eV
1191.6
0.5
2
Intensity
d
Transmission
d
pulse counting
0.1
1
1e+037
1e+037
1e+037
1e+037
2
ESCAPE DEPTH TYPE
d
0
PHI_AtomicNumber
d
6
82
0
1
0
1
784
116.676
801
116.675
794
116.675
783
116.674
752
116.674
818
116.673
789
116.672
823
116.672
810
116.671
843
116.671
780
116.67
781
116.669
798
116.669
815
116.668
850
116.668
781
116.667
838
116.666
817
116.666
817
116.665
834
116.665
829
116.664
801
116.663
816
116.663
820
116.662
812
116.661
821
116.661
860
116.66
824
116.66
816
116.659
886
116.658
841
116.658
836
116.657
812
116.657
843
116.656
853
116.655
844
116.655
796
116.654
845
116.654
848
116.653
872
116.652
822
116.652
C 1s 126
C:\Datafiles\users\MIT\berggren\emmabat\211206\Temp104.1.ITOSA3ci+1_1.pro:1:1:1.ITOSA3ci
2021
12
6
0
0
0
0
9
Casa Info Follows
0
0
0
0
1.ITOSA3ci
( 0.003689 m , 0.005537 m , 0.169504 m ) Angle: 45.0062 degrees , -0.1 degrees
emmabat211206
1 1
XPS
1380
Al
1486.6
50.38
200
200
1e+037
1e+037
FAT
117.4
1e+037
4.399
1e+037
1e+037
1e+037
1e+037
1e+037
C
1s
-1
Kinetic Energy
eV
1191.6
0.5
2
Intensity
d
Transmission
d
pulse counting
0.1
1
1e+037
1e+037
1e+037
1e+037
2
ESCAPE DEPTH TYPE
d
0
PHI_AtomicNumber
d
6
82
0
1
0
1
868
116.676
805
116.675
830
116.675
866
116.674
797
116.674
828
116.673
800
116.672
815
116.672
776
116.671
813
116.671
786
116.67
787
116.669
811
116.669
812
116.668
777
116.668
806
116.667
808
116.666
829
116.666
771
116.665
823
116.665
805
116.664
818
116.663
786
116.663
837
116.662
817
116.661
847
116.661
846
116.66
803
116.66
776
116.659
850
116.658
794
116.658
852
116.657
777
116.657
838
116.656
847
116.655
837
116.655
865
116.654
868
116.654
834
116.653
857
116.652
850
116.652
C 1s 127
C:\Datafiles\users\MIT\berggren\emmabat\211206\Temp104.1.ITOSA3ci+1_1.pro:1:1:1.ITOSA3ci
2021
12
6
0
0
0
0
9
Casa Info Follows
0
0
0
0
1.ITOSA3ci
( 0.003689 m , 0.005537 m , 0.169504 m ) Angle: 45.0062 degrees , -0.1 degrees
emmabat211206
1 1
XPS
1440
Al
1486.6
50.38
200
200
1e+037
1e+037
FAT
117.4
1e+037
4.399
1e+037
1e+037
1e+037
1e+037
1e+037
C
1s
-1
Kinetic Energy
eV
1191.6
0.5
2
Intensity
d
Transmission
d
pulse counting
0.1
1
1e+037
1e+037
1e+037
1e+037
2
ESCAPE DEPTH TYPE
d
0
PHI_AtomicNumber
d
6
82
0
1
0
1
768
116.676
847
116.675
840
116.675
823
116.674
827
116.674
821
116.673
862
116.672
788
116.672
847
116.671
800
116.671
836
116.67
818
116.669
819
116.669
777
116.668
838
116.668
773
116.667
816
116.666
819
116.666
851
116.665
829
116.665
859
116.664
863
116.663
799
116.663
862
116.662
827
116.661
796
116.661
827
116.66
832
116.66
839
116.659
858
116.658
827
116.658
756
116.657
882
116.657
790
116.656
827
116.655
863
116.655
855
116.654
833
116.654
840
116.653
819
116.652
809
116.652
C 1s 128
C:\Datafiles\users\MIT\berggren\emmabat\211206\Temp104.1.ITOSA3ci+1_1.pro:1:1:1.ITOSA3ci
2021
12
6
0
0
0
0
9
Casa Info Follows
0
0
0
0
1.ITOSA3ci
( 0.003689 m , 0.005537 m , 0.169504 m ) Angle: 45.0062 degrees , -0.1 degrees
emmabat211206
1 1
XPS
1500
Al
1486.6
50.38
200
200
1e+037
1e+037
FAT
117.4
1e+037
4.399
1e+037
1e+037
1e+037
1e+037
1e+037
C
1s
-1
Kinetic Energy
eV
1191.6
0.5
2
Intensity
d
Transmission
d
pulse counting
0.1
1
1e+037
1e+037
1e+037
1e+037
2
ESCAPE DEPTH TYPE
d
0
PHI_AtomicNumber
d
6
82
0
1
0
1
856
116.676
794
116.675
842
116.675
831
116.674
802
116.674
803
116.673
805
116.672
778
116.672
815
116.671
736
116.671
813
116.67
790
116.669
857
116.669
867
116.668
799
116.668
812
116.667
839
116.666
817
116.666
813
116.665
792
116.665
854
116.664
841
116.663
835
116.663
881
116.662
862
116.661
828
116.661
814
116.66
810
116.66
821
116.659
801
116.658
828
116.658
835
116.657
888
116.657
783
116.656
816
116.655
855
116.655
851
116.654
794
116.654
812
116.653
866
116.652
818
116.652
C 1s 129
C:\Datafiles\users\MIT\berggren\emmabat\211206\Temp104.1.ITOSA3ci+1_1.pro:1:1:1.ITOSA3ci
2021
12
6
0
0
0
0
9
Casa Info Follows
0
0
0
0
1.ITOSA3ci
( 0.003689 m , 0.005537 m , 0.169504 m ) Angle: 45.0062 degrees , -0.1 degrees
emmabat211206
1 1
XPS
1560
Al
1486.6
50.38
200
200
1e+037
1e+037
FAT
117.4
1e+037
4.399
1e+037
1e+037
1e+037
1e+037
1e+037
C
1s
-1
Kinetic Energy
eV
1191.6
0.5
2
Intensity
d
Transmission
d
pulse counting
0.1
1
1e+037
1e+037
1e+037
1e+037
2
ESCAPE DEPTH TYPE
d
0
PHI_AtomicNumber
d
6
82
0
1
0
1
796
116.676
824
116.675
804
116.675
827
116.674
785
116.674
791
116.673
771
116.672
820
116.672
758
116.671
804
116.671
780
116.67
835
116.669
801
116.669
818
116.668
803
116.668
826
116.667
779
116.666
822
116.666
818
116.665
836
116.665
810
116.664
817
116.663
826
116.663
802
116.662
850
116.661
883
116.661
871
116.66
800
116.66
872
116.659
899
116.658
801
116.658
803
116.657
775
116.657
770
116.656
797
116.655
828
116.655
835
116.654
826
116.654
888
116.653
810
116.652
877
116.652
C 1s 130
C:\Datafiles\users\MIT\berggren\emmabat\211206\Temp104.1.ITOSA3ci+1_1.pro:1:1:1.ITOSA3ci
2021
12
6
0
0
0
0
9
Casa Info Follows
0
0
0
0
1.ITOSA3ci
( 0.003689 m , 0.005537 m , 0.169504 m ) Angle: 45.0062 degrees , -0.1 degrees
emmabat211206
1 1
XPS
1620
Al
1486.6
50.38
200
200
1e+037
1e+037
FAT
117.4
1e+037
4.399
1e+037
1e+037
1e+037
1e+037
1e+037
C
1s
-1
Kinetic Energy
eV
1191.6
0.5
2
Intensity
d
Transmission
d
pulse counting
0.1
1
1e+037
1e+037
1e+037
1e+037
2
ESCAPE DEPTH TYPE
d
0
PHI_AtomicNumber
d
6
82
0
1
0
1
789
116.676
795
116.675
814
116.675
731
116.674
806
116.674
814
116.673
814
116.672
798
116.672
841
116.671
855
116.671
840
116.67
835
116.669
757
116.669
783
116.668
823
116.668
768
116.667
762
116.666
834
116.666
803
116.665
812
116.665
828
116.664
821
116.663
827
116.663
825
116.662
829
116.661
766
116.661
810
116.66
804
116.66
786
116.659
788
116.658
835
116.658
815
116.657
804
116.657
879
116.656
804
116.655
806
116.655
805
116.654
835
116.654
750
116.653
815
116.652
815
116.652
C 1s 131
C:\Datafiles\users\MIT\berggren\emmabat\211206\Temp104.1.ITOSA3ci+1_1.pro:1:1:1.ITOSA3ci
2021
12
6
0
0
0
0
9
Casa Info Follows
0
0
0
0
1.ITOSA3ci
( 0.003689 m , 0.005537 m , 0.169504 m ) Angle: 45.0062 degrees , -0.1 degrees
emmabat211206
1 1
XPS
1680
Al
1486.6
50.38
200
200
1e+037
1e+037
FAT
117.4
1e+037
4.399
1e+037
1e+037
1e+037
1e+037
1e+037
C
1s
-1
Kinetic Energy
eV
1191.6
0.5
2
Intensity
d
Transmission
d
pulse counting
0.1
1
1e+037
1e+037
1e+037
1e+037
2
ESCAPE DEPTH TYPE
d
0
PHI_AtomicNumber
d
6
82
0
1
0
1
779
116.676
798
116.675
743
116.675
779
116.674
762
116.674
810
116.673
793
116.672
835
116.672
834
116.671
860
116.671
807
116.67
780
116.669
837
116.669
828
116.668
744
116.668
806
116.667
797
116.666
842
116.666
826
116.665
853
116.665
804
116.664
758
116.663
836
116.663
813
116.662
821
116.661
809
116.661
819
116.66
849
116.66
837
116.659
823
116.658
798
116.658
816
116.657
787
116.657
871
116.656
823
116.655
852
116.655
825
116.654
811
116.654
785
116.653
810
116.652
830
116.652
C 1s 132
C:\Datafiles\users\MIT\berggren\emmabat\211206\Temp104.1.ITOSA3ci+1_1.pro:1:1:1.ITOSA3ci
2021
12
6
0
0
0
0
9
Casa Info Follows
0
0
0
0
1.ITOSA3ci
( 0.003689 m , 0.005537 m , 0.169504 m ) Angle: 45.0062 degrees , -0.1 degrees
emmabat211206
1 1
XPS
1740
Al
1486.6
50.38
200
200
1e+037
1e+037
FAT
117.4
1e+037
4.399
1e+037
1e+037
1e+037
1e+037
1e+037
C
1s
-1
Kinetic Energy
eV
1191.6
0.5
2
Intensity
d
Transmission
d
pulse counting
0.1
1
1e+037
1e+037
1e+037
1e+037
2
ESCAPE DEPTH TYPE
d
0
PHI_AtomicNumber
d
6
82
0
1
0
1
818
116.676
773
116.675
827
116.675
814
116.674
811
116.674
892
116.673
808
116.672
818
116.672
796
116.671
784
116.671
793
116.67
822
116.669
837
116.669
779
116.668
787
116.668
788
116.667
830
116.666
798
116.666
786
116.665
782
116.665
830
116.664
827
116.663
796
116.663
785
116.662
821
116.661
850
116.661
801
116.66
829
116.66
835
116.659
850
116.658
855
116.658
815
116.657
818
116.657
822
116.656
840
116.655
822
116.655
813
116.654
844
116.654
817
116.653
775
116.652
815
116.652
C 1s 133
C:\Datafiles\users\MIT\berggren\emmabat\211206\Temp104.1.ITOSA3ci+1_1.pro:1:1:1.ITOSA3ci
2021
12
6
0
0
0
0
9
Casa Info Follows
0
0
0
0
1.ITOSA3ci
( 0.003689 m , 0.005537 m , 0.169504 m ) Angle: 45.0062 degrees , -0.1 degrees
emmabat211206
1 1
XPS
1800
Al
1486.6
50.38
200
200
1e+037
1e+037
FAT
117.4
1e+037
4.399
1e+037
1e+037
1e+037
1e+037
1e+037
C
1s
-1
Kinetic Energy
eV
1191.6
0.5
2
Intensity
d
Transmission
d
pulse counting
0.1
1
1e+037
1e+037
1e+037
1e+037
2
ESCAPE DEPTH TYPE
d
0
PHI_AtomicNumber
d
6
82
0
1
0
1
822
116.676
818
116.675
786
116.675
851
116.674
809
116.674
825
116.673
793
116.672
764
116.672
817
116.671
791
116.671
841
116.67
824
116.669
800
116.669
845
116.668
861
116.668
818
116.667
829
116.666
821
116.666
872
116.665
881
116.665
890
116.664
834
116.663
862
116.663
756
116.662
831
116.661
776
116.661
879
116.66
833
116.66
851
116.659
802
116.658
780
116.658
751
116.657
820
116.657
764
116.656
796
116.655
836
116.655
894
116.654
772
116.654
868
116.653
816
116.652
896
116.652
C 1s 134
C:\Datafiles\users\MIT\berggren\emmabat\211206\Temp104.1.ITOSA3ci+1_1.pro:1:1:1.ITOSA3ci
2021
12
6
0
0
0
0
9
Casa Info Follows
0
0
0
0
1.ITOSA3ci
( 0.003689 m , 0.005537 m , 0.169504 m ) Angle: 45.0062 degrees , -0.1 degrees
emmabat211206
1 1
XPS
1860
Al
1486.6
50.38
200
200
1e+037
1e+037
FAT
117.4
1e+037
4.399
1e+037
1e+037
1e+037
1e+037
1e+037
C
1s
-1
Kinetic Energy
eV
1191.6
0.5
2
Intensity
d
Transmission
d
pulse counting
0.1
1
1e+037
1e+037
1e+037
1e+037
2
ESCAPE DEPTH TYPE
d
0
PHI_AtomicNumber
d
6
82
0
1
0
1
818
116.676
771
116.675
791
116.675
792
116.674
821
116.674
829
116.673
820
116.672
763
116.672
811
116.671
846
116.671
795
116.67
868
116.669
786
116.669
842
116.668
786
116.668
810
116.667
789
116.666
800
116.666
815
116.665
779
116.665
819
116.664
815
116.663
811
116.663
804
116.662
780
116.661
814
116.661
829
116.66
814
116.66
779
116.659
820
116.658
773
116.658
770
116.657
781
116.657
828
116.656
821
116.655
873
116.655
794
116.654
833
116.654
819
116.653
827
116.652
846
116.652
C 1s 135
C:\Datafiles\users\MIT\berggren\emmabat\211206\Temp104.1.ITOSA3ci+1_1.pro:1:1:1.ITOSA3ci
2021
12
6
0
0
0
0
9
Casa Info Follows
0
0
0
0
1.ITOSA3ci
( 0.003689 m , 0.005537 m , 0.169504 m ) Angle: 45.0062 degrees , -0.1 degrees
emmabat211206
1 1
XPS
1920
Al
1486.6
50.38
200
200
1e+037
1e+037
FAT
117.4
1e+037
4.399
1e+037
1e+037
1e+037
1e+037
1e+037
C
1s
-1
Kinetic Energy
eV
1191.6
0.5
2
Intensity
d
Transmission
d
pulse counting
0.1
1
1e+037
1e+037
1e+037
1e+037
2
ESCAPE DEPTH TYPE
d
0
PHI_AtomicNumber
d
6
82
0
1
0
1
845
116.676
763
116.675
786
116.675
797
116.674
840
116.674
801
116.673
802
116.672
809
116.672
800
116.671
810
116.671
833
116.67
808
116.669
754
116.669
791
116.668
769
116.668
757
116.667
826
116.666
794
116.666
833
116.665
768
116.665
748
116.664
808
116.663
802
116.663
853
116.662
746
116.661
853
116.661
820
116.66
821
116.66
784
116.659
809
116.658
818
116.658
815
116.657
814
116.657
821
116.656
822
116.655
775
116.655
838
116.654
856
116.654
825
116.653
867
116.652
823
116.652
C 1s 136
C:\Datafiles\users\MIT\berggren\emmabat\211206\Temp104.1.ITOSA3ci+1_1.pro:1:1:1.ITOSA3ci
2021
12
6
0
0
0
0
9
Casa Info Follows
0
0
0
0
1.ITOSA3ci
( 0.003689 m , 0.005537 m , 0.169504 m ) Angle: 45.0062 degrees , -0.1 degrees
emmabat211206
1 1
XPS
1980
Al
1486.6
50.38
200
200
1e+037
1e+037
FAT
117.4
1e+037
4.399
1e+037
1e+037
1e+037
1e+037
1e+037
C
1s
-1
Kinetic Energy
eV
1191.6
0.5
2
Intensity
d
Transmission
d
pulse counting
0.1
1
1e+037
1e+037
1e+037
1e+037
2
ESCAPE DEPTH TYPE
d
0
PHI_AtomicNumber
d
6
82
0
1
0
1
859
116.676
783
116.675
759
116.675
847
116.674
788
116.674
810
116.673
820
116.672
836
116.672
795
116.671
848
116.671
775
116.67
848
116.669
807
116.669
800
116.668
783
116.668
817
116.667
825
116.666
799
116.666
834
116.665
838
116.665
800
116.664
831
116.663
807
116.663
768
116.662
792
116.661
826
116.661
794
116.66
821
116.66
771
116.659
851
116.658
811
116.658
861
116.657
833
116.657
805
116.656
836
116.655
831
116.655
827
116.654
834
116.654
838
116.653
800
116.652
868
116.652
end of experiment