File: example_data/211124/102.1.control.vms
VAMAS Surface Chemical Analysis Standard Data Transfer Format 1988 May 4
MIT
PHI VersaProbe II
Emma Batson
FILE:C:\Datafiles\users\MIT\berggren\emmabat\211124\102.1.control.spe;BATCH:211124;DESC:1.control;
153
SOFH
Platform: PC
Technique: XPS
FileType:  SPECTRUM
FileDesc: 1.control
SoftwareVersion: SS 2.8.0.30
InstrumentModel: PHI VersaProbe II
AcqFilename: C:\Datafiles\users\MIT\berggren\emmabat\211124\102.1.control.spe
FileDate: 2021 11 24
AcqFileDate: 2021 11 24
Institution: MIT
Operator: Emma Batson
ExperimentID: 211124
EnergyReference: none 0.0
AnalyserWorkFcn: 4.399 eV
AnalyserRetardGain: 1.000506
PlatenID: emmabat211124
PhotoFilename: 101.Low Mag.pho
SXIFilename:
SourceAnalyserAngle: 45.0 d
AnalyserSolidAngle: 0.38 sr
IntensityRecal: no
IntensityCalCoeff: 104.036 0.653
EnergyRecal: no
ScanDeflectionSpan: 30 60
ScanDeflectionOffset: 0 -20
SCAMultiplierVoltage: 1875.0 V
NarrowAcceptanceAngle: no
PeakToNoiseRatioState: no
DelayBeforeAcquire: 5 seconds
C60IonGun: 10kV C60 Ion Gun
BiasBoxMode: 0
TFCParameters: 0, 1, 2, 93.73, 7.481, 1, 1
SemFieldOfView: 0.0000000
ImageSizeXY: 0.0000 0.0000
IonGunMode: Off
SputterIon: Ar+
SputterCurrent: 0.000 uA
SputterRate: 0.000 A/min
SputterEnergy: 2.000 kV
FloatVolt: 0.0 V
FloatEnable: no
GridVolt: 120.0
CondensorVolt: 1358.00
ObjectiveVolt: 1440.00
BendVolt: 22.00
SputterRaster: 2.00 2.00 mm
SputterRasterOffset: 0.600 -0.850 mm
TargetSputterTime: 9.0 min
SputterEmission: 0.00 mA
DeflectionBias: 0.0 V
XpsScanMode: scanned
AnalyserMode: FAT
SurvNumCycles: 2
SurvTimePerStep: 50.000000
NoSpectralRegFull: 1
SpectralRegDefFull: 1 1 Su1s 111 1379 -0.8000 1100.0000 -3.0000 1099.0000 -2.0000 0.000000 187.85 AREA
SpectralRegDef2Full: 1 1103.0 1 0 1 1
SpectralRegBackgroundFull: 1 0.0 548.5 0.0
SpectralRegHeroFull: 1 548.5 0.0 0.0 0.00
SpectralRegIRFull: 1 0 0.000 0.000 0.0
NoSpectralReg: 1
SpectralRegDef: 1 1 Su1s 111 1379 -0.8000 1100.0000 -3.0000 1099.0000 -2.0000 0.100000 187.85 AREA
SpectralRegDef2: 1 1103.0 1 0 1 1
SpectralRegBackground: 1 0.0 548.5 0.0
SpectralRegHero: 1 548.5 0.0 0.0 0.00
SpectralRegIR: 1 0 0.000 0.000 0.0
NoSpatialArea: 1
SpatialAreaDef: 1 1 1 (-15.8 1934.7 17486.9 45.0 0.0)
SpatialAreaDesc: 1
SpatialHRPhotoCor: 1 (0.0 0.0)
XraySource: Al 1486.6 mono
XrayAnodePosition: 5
XrayPower: 50.38 W
XrayBeamDiameter: 200.0 um
XRayBeamVoltage: 15000.0 V
XRayCondenserLensVoltage: 7600.0 V
XRayObjectiveCoilCurrent: 0.707 A
XRayBlankingVoltage: 290.0 V
XRayFilamentCurrent: 1.522 A
XRayStigmator: -0.3 0.0
XRayHighPower: no
EgunNeutMode: Off
NeutralizerCurrent: 20.0 uA
NeutralizerEnergy: 1.00 V
EgunNeutExtractor: 45.0 V
EgunNeutXSteering: 20.0
EgunNeutYSteering: -8.0
EgunNeutFilament: 1.13 A
EgunNeutPulseLength: 10.0 msec
SxiPersistence: 1
SxiSecPerDisplay: 1.0
SxiAutoContrast: yes
SxiAutoContrastLow: 0.30
SxiAutoContrastHigh: 0.30
SxiBindingEnergy: 410.0 eV
SxiPassEnergy: 376 eV
SxiLens2: -804 V
SxiLens3: -761 V
SxiLensBias: 200 V
SxiShutterBias: no
SxiShutterBiasVoltage: 250.0 V
SxiDisplayMode: 2
Detector Acq Time: 20.0 (min)
Number Of Channels: 16
Channel Info: 1 1 1.688
Channel Info: 2 1 1.270
Channel Info: 3 1 1.225
Channel Info: 4 1 1.068
Channel Info: 5 1 1.078
Channel Info: 6 1 0.946
Channel Info: 7 1 0.996
Channel Info: 8 1 0.983
Channel Info: 9 1 1.103
Channel Info: 10 1 1.052
Channel Info: 11 1 0.980
Channel Info: 12 1 0.735
Channel Info: 13 1 0.768
Channel Info: 14 1 0.698
Channel Info: 15 1 0.850
Channel Info: 16 1 1.405
StagePosition: -0.2682 -1.2205 17.4869 45.0031 -0.0500
StageCurrentRotationSpeed: 1.0000
DefectPosID: 1
DefectPosComment:
DefectPosU: -0.0158
DefectPosV: -1.9350
DefectPosX: -0.2682
DefectPosY: -1.2205
DefectPosZ: 17.4869
DefectPosTilt: 45.0031
DefectPosRotation: -0.0500
DefectPosAligment: None
DefectPosReferenceImage: 101.Low Mag.pho
C60IonGunMode: Off
C60IonCurrent: 0.0 uA
C60SputterRate: 0.0 A/min
C60Beam: 10.000 kV
C60Temperature: 383.0 C
C60Repellor: -76.0 V
C60Grid: 120.0 V
C60Lens2: 6.215 kV
C60Extractor: -833.0 kV
C60Deflector: -91.0 -124.0 V
C60BlankingDeflector: no yes
C60Raster: 0.8 2.3 mm
C60RasterOffset: 0.4 -0.2 mm
C60Emission: 10.00 mA
C60Filament: 2.80 A
Deconvolution: no
DeconvolutionPassEnergy: 2.95 eV
XRaySetting: 200u50W15KV
EOFH
NORM
REGULAR
0
0
0
0
0
0
1
Su1s 1
C:\Datafiles\users\MIT\berggren\emmabat\211124\102.1.control.spe:1:1:1.control
2021
11
24
0
0
0
0
11
Casa Info Follows
0
0
0
0
1.control
( -0.002682 m , -0.012205 m , 0.174869 m ) Angle: 45.0031 degrees , -0.05 degrees
emmabat211124
SputterRaster: 2.00 2.00 mm
1
1
XPS
Al
1486.6
50.38
200
200
1e+037
1e+037
FAT
187.85
1e+037
4.399
1e+037
1e+037
1e+037
1e+037
1e+037
Su1s

-1
Kinetic Energy
eV
386.6
0.8
2
Intensity
d
Transmission
d
pulse counting
0.1
1
1e+037
1e+037
1e+037
1e+037
2
ESCAPE DEPTH TYPE
d
0
PHI_AtomicNumber
d
111
0
0
5781
5686
5575
5663
5576
5447
5550
5629
5550
5523
5765
5856
5803
5938
6282
6383
6327
6348
6275
6134
5873
5810
5650
5773
5639
5847
5620
5415
5241
5090
5140
5043
4925
4968
4976
4938
4832
4965
4865
4972
5013
4900
4831
4909
4915
5085
4979
5039
4937
4888
5003
4971
4955
4903
4928
4835
4889
5012
5049
4986
4832
4938
5008
4938
4949
4842
5100
5018
4992
5013
5080
5068
4932
4968
5077
5003
5066
5009
5095
5100
5059
5042
5067
5004
5021
5237
5136
5092
5108
5231
5081
5265
5260
5219
5135
5251
5273
5370
5179
5271
5390
5415
5283
5339
5357
5365
5350
5386
5427
5541
5406
5436
5370
5395
5540
5429
5432
5325
5409
5322
5455
5498
5468
5638
5523
5676
5591
5612
5763
5683
5575
5808
5602
5591
5619
5580
5475
5530
5487
5459
5560
5608
5381
5564
5723
5551
5548
5566
5683
5661
5689
5784
5902
5898
6096
6029
6189
6004
5861
5880
5683
5745
5617
5568
5560
5376
5297
5249
5256
5276
5125
5187
5132
5059
5156
5068
5070
5206
5111
5316
5150
5203
5178
5171
5156
5188
5407
5260
5300
5167
5378
5196
5136
5376
5287
5322
5352
5292
5350
5348
5320
5324
5273
5299
5329
5393
5521
5377
5268
5466
5414
5468
5433
5479
5411
5354
5359
5478
5651
5552
5566
5541
5507
5602
5684
5649
5630
5479
5705
5614
5607
5594
5732
5612
5633
5543
5721
5535
5577
5599
5683
5762
5708
5691
5703
5687
5577
5685
5634
5756
5732
5729
5964
5730
5764
5913
5869
5742
5856
5784
5724
5859
5834
5782
5755
5812
5909
5968
5981
6001
5813
5906
5848
5954
6050
5807
5991
5988
6038
5898
5971
5981
5982
5962
6079
6053
5999
6078
6053
6129
6021
6182
6222
6143
6212
6180
6026
6270
6090
6086
6017
6215
6188
6173
6178
6146
6302
6148
6328
6348
6251
6350
6179
6455
6170
6339
6277
6361
6235
6284
6338
6423
6285
6370
6461
6417
6479
6484
6424
6424
6400
6361
6426
6384
6442
6594
6484
6452
6619
6639
6840
6709
6714
6738
6500
6677
6555
6588
6541
6491
6515
6583
6408
6498
6625
6431
6433
6645
6554
6561
6547
6564
6469
6560
6528
6746
6610
6588
6645
6469
6732
6677
6617
6657
6542
6437
6615
6604
6694
6741
6713
6878
6851
6669
6655
6629
6717
6712
6612
6753
6754
6778
6694
6776
6799
6939
6688
6989
6885
6827
6865
6836
7018
6725
7063
6797
6943
7047
6803
6890
7108
6938
7080
7011
7045
6977
6976
7141
7122
7043
7080
7206
7075
7136
7080
7156
7194
7166
7227
7219
7135
7194
7127
7102
7097
7193
7149
7055
7165
7249
7084
7271
7193
7161
7141
7214
7234
7247
7282
7154
7214
7269
7337
7295
7276
7277
7368
7277
7388
7351
7603
7343
7281
7416
7366
7399
7440
7354
7385
7463
7485
7396
7570
7369
7597
7525
7679
7463
7554
7664
7659
7623
7380
7381
7413
7448
7401
7272
7349
7429
7494
7726
8101
8501
8432
8561
8414
8076
7603
7461
7260
7278
7228
7184
7149
7206
7091
7121
7222
7192
7041
7175
7334
7106
7321
7084
7128
7345
7114
7267
7224
7084
7135
7030
7086
6877
6790
6883
6888
6971
6858
6738
6743
6866
6853
7041
7015
7145
7650
8059
8902
9308
9832
9648
8933
8124
7516
6972
6753
6619
6289
6446
6350
6319
6450
6180
6294
6230
6173
6185
6206
6115
6354
6157
6087
6338
6110
6158
6170
6271
6120
6316
6348
6206
6201
6230
6201
6312
6342
6360
6338
6254
6450
6356
6336
6291
6359
6360
6248
6298
6237
6346
6290
6384
6319
6352
6634
6429
6394
6292
6485
6336
6485
6379
6410
6431
6472
6345
6440
6518
6405
6431
6484
6524
6481
6503
6564
6432
6555
6487
6524
6601
6526
6522
6521
6752
6596
6498
6781
6584
6561
6604
6792
6651
6709
6714
6747
6806
6632
6642
6636
6665
6814
6754
6657
6951
6763
6796
6833
6797
6915
6784
6884
6726
6695
6887
6775
6840
6857
6927
6860
6968
6866
6945
6944
6948
6848
6751
6830
6859
7090
6841
6797
7072
6926
7005
7022
6993
6960
7036
6974
6997
6855
7077
7092
7095
7174
7254
7018
7209
7225
7013
7172
7007
6764
6821
6761
6653
6653
6691
6657
6632
6583
6573
6608
6662
6985
7314
7989
8919
9799
10147
9437
8498
7274
6578
6537
6347
6334
6411
6346
6326
6282
6293
6294
6392
6318
6317
6296
6101
6396
6291
6431
6406
6412
6285
6327
6509
6390
6403
6356
6373
6178
6469
6298
6295
6268
6231
6394
6294
6342
6370
6272
6403
6737
7049
7212
6725
6419
6196
6240
6119
6112
6111
6706
7116
7500
7299
6847
6216
6168
6029
6064
6131
6084
5898
5988
6049
6109
6167
6180
6100
6216
6296
6265
6298
6355
6395
6388
6204
6266
6122
6137
5980
5962
5883
5642
5540
5288
5008
4857
4730
4555
4343
4457
4543
5157
7091
10955
14066
12920
8669
5249
3872
3703
3949
5929
10799
16617
17766
13455
7008
3535
2571
2060
1854
1627
1690
1502
1455
1389
1432
1288
1258
1275
1174
1210
1244
1264
1215
1123
1205
1132
1187
1178
1248
1188
1142
1162
1161
1240
1235
1232
1164
1218
1170
1187
1173
1207
1276
1218
1170
1210
1179
1188
1140
1117
1188
1199
1182
1176
1215
1201
1225
1295
1219
1252
1204
1207
1162
1238
1166
1202
1252
1164
1199
1173
1221
1215
1225
1251
1274
1218
1274
1238
1228
1322
1228
1190
1264
1290
1247
1236
1222
1250
1246
1281
1301
1235
1249
1270
1244
1271
1314
1218
1228
1240
1236
1240
1219
1308
1280
1323
1213
1275
1279
1281
1323
1308
1339
1310
1306
1307
1320
1268
1261
1381
1340
1283
1295
1331
1289
1270
1287
1319
1356
1312
1348
1337
1314
1348
1380
1372
1278
1345
1370
1322
1319
1397
1379
1353
1418
1367
1433
1360
1409
1432
1371
1401
1403
1429
1464
1461
1475
1410
1431
1482
1524
1495
1471
1395
1443
1482
1436
1468
1459
1598
1451
1506
1497
1572
1496
1565
1456
1511
1486
1480
1472
1496
1535
1527
1359
1446
1506
1464
1495
1450
1486
1414
1475
1489
1502
1553
1638
1674
1816
2000
2562
2813
2770
2216
1663
1466
1481
1427
1408
1419
1332
1426
1391
1347
1364
1377
1377
1333
1425
1438
1416
1383
1410
1424
1431
1390
1401
1391
1377
1376
1426
1408
1390
1459
1465
1331
1433
1349
1478
1420
1378
1438
1417
1414
1465
1403
1419
1415
1345
1348
1390
1404
1432
1399
1429
1427
1383
1420
1385
1449
1454
1431
1465
1495
1442
1414
1436
1440
1499
1426
1449
1448
1484
1429
1507
1520
1518
1489
1498
1507
1490
1471
1497
1477
1510
1505
1470
1545
1457
1478
1531
1512
1496
1537
1449
1492
1519
1501
1540
1471
1507
1523
1513
1464
1531
1592
1532
1606
1497
1579
1565
1582
1524
1577
1492
1548
1585
1509
1542
1657
1541
1598
1633
1601
1580
1555
1522
1513
1564
1557
1586
1581
1546
1538
1558
1528
1609
1569
1559
1597
1591
1578
1589
1560
1624
1628
1607
1645
1616
1659
1570
1573
1605
1623
1659
1593
1670
1579
1627
1657
1576
1601
1638
1561
1653
1713
1781
1730
1657
1603
1623
1638
1581
1647
1615
1641
1595
1632
1683
1661
1672
1696
1637
1736
1713
1672
1611
1673
1644
1701
1714
1696
1679
1746
1619
1583
1629
1664
1696
1739
1808
1844
1881
1775
1848
1882
1717
1649
1649
1603
1575
1645
1628
1548
1575
1562
1521
1549
1582
1577
1565
1606
1573
1589
1492
1521
1606
1545
1661
1764
1721
1763
1629
1601
1554
1540
1585
1503
1639
1525
1582
1596
1632
1595
1610
1665
1626
1668
1621
1698
1606
1708
1615
1683
1651
1734
1734
1710
1740
1694
1702
1682
1572
1514
1507
1433
1333
1198
1215
1167
1107
1034
1058
1020
1063
969
946
936
915
987
927
893
864
900
931
883
871
863
855
871
929
875
917
873
948
949
927
944
962
988
1016
959
979
987
958
950
984
1041
946
967
996
890
929
941
901
846
859
796
806
750
756
755
835
931
1048
1028
873
779
826
752
799
887
1328
2335
3724
4312
3533
2065
1061
484
316
249
192
211
176
193
203
244
263
248
254
261
252
188
108
61
29
26
18
15
6
8
187.141
end of experiment