File: example_data/211124/103.2.dii.vms
VAMAS Surface Chemical Analysis Standard Data Transfer Format 1988 May 4
MIT
PHI VersaProbe II
Emma Batson
FILE:C:\Datafiles\users\MIT\berggren\emmabat\211124\103.2.dii.spe;BATCH:211124;DESC:2.dii;
153
SOFH
Platform: PC
Technique: XPS
FileType:  SPECTRUM
FileDesc: 2.dii
SoftwareVersion: SS 2.8.0.30
InstrumentModel: PHI VersaProbe II
AcqFilename: C:\Datafiles\users\MIT\berggren\emmabat\211124\103.2.dii.spe
FileDate: 2021 11 24
AcqFileDate: 2021 11 24
Institution: MIT
Operator: Emma Batson
ExperimentID: 211124
EnergyReference: none 0.0
AnalyserWorkFcn: 4.399 eV
AnalyserRetardGain: 1.000506
PlatenID: emmabat211124
PhotoFilename: 101.Low Mag.pho
SXIFilename:
SourceAnalyserAngle: 45.0 d
AnalyserSolidAngle: 0.38 sr
IntensityRecal: no
IntensityCalCoeff: 104.036 0.653
EnergyRecal: no
ScanDeflectionSpan: 30 60
ScanDeflectionOffset: 0 -20
SCAMultiplierVoltage: 1875.0 V
NarrowAcceptanceAngle: no
PeakToNoiseRatioState: no
DelayBeforeAcquire: 5 seconds
C60IonGun: 10kV C60 Ion Gun
BiasBoxMode: 0
TFCParameters: 0, 1, 2, 93.73, 7.481, 1, 1
SemFieldOfView: 0.0000000
ImageSizeXY: 0.0000 0.0000
IonGunMode: Off
SputterIon: Ar+
SputterCurrent: 0.000 uA
SputterRate: 0.000 A/min
SputterEnergy: 2.000 kV
FloatVolt: 0.0 V
FloatEnable: no
GridVolt: 120.0
CondensorVolt: 1358.00
ObjectiveVolt: 1440.00
BendVolt: 22.00
SputterRaster: 2.00 2.00 mm
SputterRasterOffset: 0.600 -0.850 mm
TargetSputterTime: 9.0 min
SputterEmission: 0.00 mA
DeflectionBias: 0.0 V
XpsScanMode: scanned
AnalyserMode: FAT
SurvNumCycles: 2
SurvTimePerStep: 50.000000
NoSpectralRegFull: 1
SpectralRegDefFull: 1 1 Su1s 111 1379 -0.8000 1100.0000 -3.0000 1099.0000 -2.0000 0.000000 187.85 AREA
SpectralRegDef2Full: 1 1103.0 1 0 1 1
SpectralRegBackgroundFull: 1 0.0 548.5 0.0
SpectralRegHeroFull: 1 548.5 0.0 0.0 0.00
SpectralRegIRFull: 1 0 0.000 0.000 0.0
NoSpectralReg: 1
SpectralRegDef: 1 1 Su1s 111 1379 -0.8000 1100.0000 -3.0000 1099.0000 -2.0000 0.100000 187.85 AREA
SpectralRegDef2: 1 1103.0 1 0 1 1
SpectralRegBackground: 1 0.0 548.5 0.0
SpectralRegHero: 1 548.5 0.0 0.0 0.00
SpectralRegIR: 1 0 0.000 0.000 0.0
NoSpatialArea: 1
SpatialAreaDef: 1 2 1 (2167.0 -917.2 17505.2 45.0 0.0)
SpatialAreaDesc: 1
SpatialHRPhotoCor: 1 (0.0 0.0)
XraySource: Al 1486.6 mono
XrayAnodePosition: 5
XrayPower: 50.38 W
XrayBeamDiameter: 200.0 um
XRayBeamVoltage: 15000.0 V
XRayCondenserLensVoltage: 7600.0 V
XRayObjectiveCoilCurrent: 0.707 A
XRayBlankingVoltage: 290.0 V
XRayFilamentCurrent: 1.518 A
XRayStigmator: -0.3 0.0
XRayHighPower: no
EgunNeutMode: Off
NeutralizerCurrent: 20.0 uA
NeutralizerEnergy: 1.00 V
EgunNeutExtractor: 45.0 V
EgunNeutXSteering: 20.0
EgunNeutYSteering: -8.0
EgunNeutFilament: 1.13 A
EgunNeutPulseLength: 10.0 msec
SxiPersistence: 1
SxiSecPerDisplay: 1.0
SxiAutoContrast: yes
SxiAutoContrastLow: 0.30
SxiAutoContrastHigh: 0.30
SxiBindingEnergy: 410.0 eV
SxiPassEnergy: 376 eV
SxiLens2: -804 V
SxiLens3: -761 V
SxiLensBias: 200 V
SxiShutterBias: no
SxiShutterBiasVoltage: 250.0 V
SxiDisplayMode: 2
Detector Acq Time: 20.0 (min)
Number Of Channels: 16
Channel Info: 1 1 1.688
Channel Info: 2 1 1.270
Channel Info: 3 1 1.225
Channel Info: 4 1 1.068
Channel Info: 5 1 1.078
Channel Info: 6 1 0.946
Channel Info: 7 1 0.996
Channel Info: 8 1 0.983
Channel Info: 9 1 1.103
Channel Info: 10 1 1.052
Channel Info: 11 1 0.980
Channel Info: 12 1 0.735
Channel Info: 13 1 0.768
Channel Info: 14 1 0.698
Channel Info: 15 1 0.850
Channel Info: 16 1 1.405
StagePosition: 1.9409 1.5798 17.5052 45.0031 -0.0500
StageCurrentRotationSpeed: 1.0000
DefectPosID: 2
DefectPosComment:
DefectPosU: 2.1644
DefectPosV: 0.9186
DefectPosX: 1.9409
DefectPosY: 1.5808
DefectPosZ: 17.5052
DefectPosTilt: 45.0031
DefectPosRotation: -0.0500
DefectPosAligment: None
DefectPosReferenceImage: 101.Low Mag.pho
C60IonGunMode: Off
C60IonCurrent: 0.0 uA
C60SputterRate: 0.0 A/min
C60Beam: 10.000 kV
C60Temperature: 383.0 C
C60Repellor: -76.0 V
C60Grid: 120.0 V
C60Lens2: 6.215 kV
C60Extractor: -833.0 kV
C60Deflector: -91.0 -124.0 V
C60BlankingDeflector: no yes
C60Raster: 0.8 2.3 mm
C60RasterOffset: 0.4 -0.2 mm
C60Emission: 10.00 mA
C60Filament: 2.80 A
Deconvolution: no
DeconvolutionPassEnergy: 2.95 eV
XRaySetting: 200u50W15KV
EOFH
NORM
REGULAR
0
0
0
0
0
0
1
Su1s 1
C:\Datafiles\users\MIT\berggren\emmabat\211124\103.2.dii.spe:1:2:2.dii
2021
11
24
0
0
0
0
11
Casa Info Follows
0
0
0
0
2.dii
( 0.019409 m , 0.015798 m , 0.175052 m ) Angle: 45.0031 degrees , -0.05 degrees
emmabat211124
SputterRaster: 2.00 2.00 mm
1
2
XPS
Al
1486.6
50.38
200
200
1e+037
1e+037
FAT
187.85
1e+037
4.399
1e+037
1e+037
1e+037
1e+037
1e+037
Su1s

-1
Kinetic Energy
eV
386.6
0.8
2
Intensity
d
Transmission
d
pulse counting
0.1
1
1e+037
1e+037
1e+037
1e+037
2
ESCAPE DEPTH TYPE
d
0
PHI_AtomicNumber
d
111
0
0
6530
6517
6588
6439
6534
6463
6523
6466
6459
6554
6547
6684
6894
7281
7321
7599
7792
7521
7464
7420
7062
6947
6819
6772
6844
6845
6647
6389
6205
6053
5924
5750
5511
5545
5478
5611
5631
5517
5604
5668
5667
5514
5584
5550
5586
5647
5593
5608
5703
5694
5625
5641
5632
5497
5592
5576
5630
5438
5659
5660
5554
5572
5584
5559
5510
5532
5478
5614
5479
5586
5572
5634
5602
5634
5602
5559
5689
5651
5631
5699
5604
5854
5736
5725
5689
5734
5680
5651
5732
5867
5828
5783
5770
5750
5661
5887
5914
5922
5874
5781
5815
5960
5888
5864
5942
5970
5912
6098
6091
6101
5901
5936
6004
6103
6154
5986
6114
6178
6111
6252
6178
6222
6226
6250
6254
6245
6176
6242
6417
6274
6405
6358
6269
6336
6308
6160
6213
6209
6183
6265
6216
6183
6058
6302
6219
6331
6237
6462
6423
6327
6417
6405
6589
6597
6719
6824
6902
6866
6616
6483
6518
6199
6274
5962
5880
6057
5938
5960
5858
5867
5758
5755
5727
5840
5809
5734
5755
5725
5638
5743
5828
5764
5818
5932
5938
5855
5845
5810
5731
5706
5915
5890
6048
5966
5868
5915
5872
5972
5859
5941
5871
6004
5955
5973
6002
5850
6026
6126
6026
5885
6122
6047
5990
5788
6128
6090
6133
6001
6030
6201
6122
6010
5996
6082
6325
6116
6109
6089
6222
6162
6127
6259
6142
6219
6134
6228
6174
6165
6144
6276
6359
6211
6165
6260
6180
6188
6259
6245
6384
6244
6216
6326
6317
6422
6420
6299
6401
6494
6438
6598
6345
6488
6241
6472
6436
6511
6525
6379
6469
6558
6494
6384
6373
6539
6445
6455
6441
6621
6523
6684
6563
6692
6566
6679
6510
6698
6466
6537
6491
6639
6710
6710
6718
6718
6779
6659
6668
6562
6664
6641
6707
6740
6695
6585
6842
6543
6723
6729
6709
6793
6822
6804
6910
6749
6832
6623
6766
6769
6832
6827
6955
6967
6883
6913
6891
7010
6670
6854
7016
6921
7118
6937
7032
7084
7074
7086
7324
7061
7150
7380
7143
7328
7252
7071
7212
7035
7171
7015
7034
7111
6898
6982
6969
7006
6943
7125
7015
7011
6954
6999
6978
7067
6806
7175
6941
7090
6966
6962
7071
7119
7055
6955
7020
7023
7123
7183
7058
7073
6946
7108
7054
7052
7252
7122
7188
7227
7180
7215
7323
7275
7156
7158
7201
7272
7240
7173
7214
7387
7433
7197
7163
7235
7243
7237
7294
7175
7467
7354
7232
7372
7382
7331
7268
7384
7489
7402
7466
7397
7274
7357
7456
7433
7455
7486
7561
7653
7514
7612
7617
7680
7495
7465
7543
7510
7596
7537
7576
7526
7481
7468
7608
7565
7545
7654
7561
7611
7699
7565
7562
7678
7585
7474
7674
7750
7647
7586
7759
7730
7635
7888
7734
7980
7629
7866
7824
7835
7808
7912
7723
7766
7932
7736
7999
7955
8085
8042
8090
8005
8136
8028
7986
7859
7758
7758
7643
7675
7876
7834
7832
7851
7893
8330
8510
8879
9318
9432
9001
8639
8255
8097
7740
7584
7608
7642
7422
7406
7533
7429
7548
7374
7468
7571
7592
7588
7628
7596
7684
7585
7606
7462
7489
7416
7500
7579
7535
7245
7387
7183
7385
7138
7300
7258
7023
7212
7271
7256
7443
7698
8300
9025
9705
10661
10814
10285
9474
8601
7835
7489
7157
6939
6763
6808
6674
6642
6558
6458
6663
6444
6505
6528
6471
6345
6471
6423
6394
6388
6392
6375
6461
6462
6281
6415
6306
6344
6531
6483
6312
6605
6524
6586
6461
6406
6491
6505
6460
6620
6516
6603
6665
6498
6580
6223
6685
6514
6440
6410
6576
6400
6591
6508
6580
6780
6618
6649
6585
6742
6552
6563
6693
6723
6689
6755
6612
6785
6719
6670
6755
6629
6687
6754
6571
6770
6892
6871
6831
6783
6796
6953
6864
6807
6910
6915
6883
6714
6837
6929
6835
6941
6780
6984
6794
6902
6842
6760
6825
7058
6834
6992
7009
6970
6870
7032
7059
6991
7087
6898
7164
7028
7035
7005
7172
7023
7017
7098
7000
6904
7133
6924
7036
7039
7049
7040
6972
7061
6925
6966
7188
7126
7082
7258
7180
7081
7053
7249
7294
7224
7292
7188
7125
7246
7271
7174
7052
6953
6761
6981
6907
6760
6763
6709
6643
6755
6619
6733
6677
6858
6856
7460
8147
9276
10332
10655
9988
8681
7276
6828
6429
6468
6464
6367
6402
6341
6402
6411
6386
6416
6379
6355
6373
6372
6436
6505
6493
6397
6441
6507
6498
6454
6511
6573
6406
6432
6344
6542
6346
6329
6494
6389
6274
6254
6426
6260
6329
6490
6799
7022
7111
6884
6468
6190
6172
6236
6326
6452
6751
7218
7392
7045
6740
6300
6268
6280
6263
6227
6117
6266
6298
6320
6210
6367
6389
6386
6311
6609
6520
6751
6738
6643
6524
6479
6513
6514
6472
6406
6313
6182
6045
5889
5518
5488
5201
5270
4934
4890
4993
5177
6283
9204
13297
16371
13759
8783
5276
4211
4092
5015
7987
13955
19857
19819
13746
6725
3685
2737
2283
1976
1853
1773
1657
1579
1439
1470
1405
1344
1372
1329
1304
1382
1240
1301
1317
1263
1242
1313
1248
1310
1294
1276
1275
1295
1256
1178
1200
1188
1226
1245
1228
1254
1272
1242
1258
1260
1211
1239
1203
1250
1268
1272
1242
1244
1224
1283
1262
1346
1330
1264
1247
1241
1315
1304
1293
1299
1299
1308
1310
1283
1309
1215
1290
1301
1294
1242
1276
1279
1316
1200
1325
1391
1266
1313
1346
1276
1293
1218
1300
1396
1331
1376
1324
1407
1291
1316
1321
1306
1322
1355
1387
1329
1222
1399
1324
1301
1342
1381
1348
1352
1346
1322
1425
1411
1398
1408
1404
1368
1488
1382
1436
1429
1425
1385
1366
1424
1385
1466
1302
1389
1338
1336
1435
1370
1378
1390
1404
1410
1421
1401
1435
1408
1421
1440
1419
1417
1442
1370
1460
1421
1413
1396
1440
1481
1534
1526
1491
1454
1516
1493
1506
1511
1533
1497
1474
1531
1512
1563
1406
1524
1480
1546
1506
1539
1502
1489
1553
1533
1563
1554
1491
1593
1572
1571
1524
1511
1511
1546
1459
1502
1440
1512
1494
1463
1516
1525
1595
1666
1702
1725
1863
2248
2435
2437
2114
1640
1519
1498
1469
1491
1441
1451
1472
1383
1418
1422
1398
1436
1369
1460
1448
1485
1447
1490
1453
1397
1410
1426
1422
1458
1457
1441
1425
1444
1428
1444
1507
1474
1419
1460
1457
1478
1444
1442
1486
1469
1471
1464
1460
1478
1494
1535
1448
1512
1443
1450
1490
1445
1434
1442
1428
1472
1469
1442
1452
1506
1512
1516
1522
1483
1486
1545
1526
1506
1498
1493
1476
1539
1573
1501
1527
1466
1500
1462
1476
1519
1551
1493
1593
1513
1579
1479
1489
1500
1537
1523
1506
1529
1494
1538
1544
1497
1530
1598
1549
1524
1509
1501
1598
1604
1713
1609
1570
1660
1460
1567
1516
1488
1640
1544
1599
1563
1598
1626
1632
1624
1646
1667
1518
1622
1624
1621
1552
1541
1530
1559
1551
1570
1600
1574
1575
1605
1633
1661
1657
1629
1597
1618
1581
1633
1642
1631
1597
1592
1596
1629
1581
1624
1604
1602
1614
1647
1657
1636
1626
1696
1769
1842
1802
1717
1604
1643
1641
1604
1605
1605
1668
1624
1654
1688
1654
1622
1643
1605
1681
1630
1665
1709
1658
1575
1654
1608
1660
1553
1626
1635
1651
1594
1733
1686
1689
1751
1882
1948
1898
1949
1845
1852
1705
1635
1610
1632
1569
1540
1556
1587
1599
1630
1539
1518
1584
1619
1580
1563
1645
1612
1602
1568
1708
1695
1773
1772
1757
1717
1646
1640
1651
1582
1599
1578
1642
1597
1552
1585
1586
1562
1680
1601
1709
1674
1698
1613
1739
1768
1668
1717
1705
1839
1821
1728
1859
1727
1691
1572
1526
1555
1388
1399
1330
1217
1203
1129
1141
1111
1034
951
935
958
906
953
957
918
902
847
886
867
899
907
901
886
911
841
876
922
890
859
882
892
896
912
965
947
1043
905
1014
950
939
964
972
977
987
956
1035
979
921
932
896
901
866
843
804
800
783
869
908
939
932
827
760
740
775
912
1068
1646
2872
4367
4701
3672
1980
915
482
347
272
219
207
173
208
196
254
235
272
288
288
254
181
105
56
25
29
22
16
10
14
187.141
end of experiment