File: example_data/211124/104.3.fi.vms
VAMAS Surface Chemical Analysis Standard Data Transfer Format 1988 May 4
MIT
PHI VersaProbe II
Emma Batson
FILE:C:\Datafiles\users\MIT\berggren\emmabat\211124\104.3.fi.spe;BATCH:211124;DESC:3.fi;
153
SOFH
Platform: PC
Technique: XPS
FileType:  SPECTRUM
FileDesc: 3.fi
SoftwareVersion: SS 2.8.0.30
InstrumentModel: PHI VersaProbe II
AcqFilename: C:\Datafiles\users\MIT\berggren\emmabat\211124\104.3.fi.spe
FileDate: 2021 11 24
AcqFileDate: 2021 11 24
Institution: MIT
Operator: Emma Batson
ExperimentID: 211124
EnergyReference: none 0.0
AnalyserWorkFcn: 4.399 eV
AnalyserRetardGain: 1.000506
PlatenID: emmabat211124
PhotoFilename: 101.Low Mag.pho
SXIFilename:
SourceAnalyserAngle: 45.0 d
AnalyserSolidAngle: 0.38 sr
IntensityRecal: no
IntensityCalCoeff: 104.036 0.653
EnergyRecal: no
ScanDeflectionSpan: 30 60
ScanDeflectionOffset: 0 -20
SCAMultiplierVoltage: 1875.0 V
NarrowAcceptanceAngle: no
PeakToNoiseRatioState: no
DelayBeforeAcquire: 5 seconds
C60IonGun: 10kV C60 Ion Gun
BiasBoxMode: 0
TFCParameters: 0, 1, 2, 93.73, 7.481, 1, 1
SemFieldOfView: 0.0000000
ImageSizeXY: 0.0000 0.0000
IonGunMode: Off
SputterIon: Ar+
SputterCurrent: 0.000 uA
SputterRate: 0.000 A/min
SputterEnergy: 2.000 kV
FloatVolt: 0.0 V
FloatEnable: no
GridVolt: 120.0
CondensorVolt: 1358.00
ObjectiveVolt: 1440.00
BendVolt: 22.00
SputterRaster: 2.00 2.00 mm
SputterRasterOffset: 0.600 -0.850 mm
TargetSputterTime: 9.0 min
SputterEmission: 0.00 mA
DeflectionBias: 0.0 V
XpsScanMode: scanned
AnalyserMode: FAT
SurvNumCycles: 2
SurvTimePerStep: 50.000000
NoSpectralRegFull: 1
SpectralRegDefFull: 1 1 Su1s 111 1379 -0.8000 1100.0000 -3.0000 1099.0000 -2.0000 0.000000 187.85 AREA
SpectralRegDef2Full: 1 1103.0 1 0 1 1
SpectralRegBackgroundFull: 1 0.0 548.5 0.0
SpectralRegHeroFull: 1 548.5 0.0 0.0 0.00
SpectralRegIRFull: 1 0 0.000 0.000 0.0
NoSpectralReg: 1
SpectralRegDef: 1 1 Su1s 111 1379 -0.8000 1100.0000 -3.0000 1099.0000 -2.0000 0.100000 187.85 AREA
SpectralRegDef2: 1 1103.0 1 0 1 1
SpectralRegBackground: 1 0.0 548.5 0.0
SpectralRegHero: 1 548.5 0.0 0.0 0.00
SpectralRegIR: 1 0 0.000 0.000 0.0
NoSpatialArea: 1
SpatialAreaDef: 1 3 1 (6896.4 793.9 17478.7 45.0 0.0)
SpatialAreaDesc: 1
SpatialHRPhotoCor: 1 (0.0 0.0)
XraySource: Al 1486.6 mono
XrayAnodePosition: 5
XrayPower: 50.38 W
XrayBeamDiameter: 200.0 um
XRayBeamVoltage: 15000.0 V
XRayCondenserLensVoltage: 7600.0 V
XRayObjectiveCoilCurrent: 0.707 A
XRayBlankingVoltage: 290.0 V
XRayFilamentCurrent: 1.518 A
XRayStigmator: -0.3 0.0
XRayHighPower: no
EgunNeutMode: Off
NeutralizerCurrent: 20.0 uA
NeutralizerEnergy: 1.00 V
EgunNeutExtractor: 45.0 V
EgunNeutXSteering: 20.0
EgunNeutYSteering: -8.0
EgunNeutFilament: 1.13 A
EgunNeutPulseLength: 10.0 msec
SxiPersistence: 1
SxiSecPerDisplay: 1.0
SxiAutoContrast: yes
SxiAutoContrastLow: 0.30
SxiAutoContrastHigh: 0.30
SxiBindingEnergy: 410.0 eV
SxiPassEnergy: 376 eV
SxiLens2: -804 V
SxiLens3: -761 V
SxiLensBias: 200 V
SxiShutterBias: no
SxiShutterBiasVoltage: 250.0 V
SxiDisplayMode: 2
Detector Acq Time: 20.0 (min)
Number Of Channels: 16
Channel Info: 1 1 1.688
Channel Info: 2 1 1.270
Channel Info: 3 1 1.225
Channel Info: 4 1 1.068
Channel Info: 5 1 1.078
Channel Info: 6 1 0.946
Channel Info: 7 1 0.996
Channel Info: 8 1 0.983
Channel Info: 9 1 1.103
Channel Info: 10 1 1.052
Channel Info: 11 1 0.980
Channel Info: 12 1 0.735
Channel Info: 13 1 0.768
Channel Info: 14 1 0.698
Channel Info: 15 1 0.850
Channel Info: 16 1 1.405
StagePosition: 6.6142 -0.1872 17.4787 45.0031 -0.0500
StageCurrentRotationSpeed: 1.0000
DefectPosID: 3
DefectPosComment:
DefectPosU: 6.8954
DefectPosV: -0.7889
DefectPosX: 6.6142
DefectPosY: -0.1872
DefectPosZ: 17.4787
DefectPosTilt: 45.0031
DefectPosRotation: -0.0500
DefectPosAligment: None
DefectPosReferenceImage: 101.Low Mag.pho
C60IonGunMode: Off
C60IonCurrent: 0.0 uA
C60SputterRate: 0.0 A/min
C60Beam: 10.000 kV
C60Temperature: 383.0 C
C60Repellor: -76.0 V
C60Grid: 120.0 V
C60Lens2: 6.215 kV
C60Extractor: -833.0 kV
C60Deflector: -91.0 -124.0 V
C60BlankingDeflector: no yes
C60Raster: 0.8 2.3 mm
C60RasterOffset: 0.4 -0.2 mm
C60Emission: 10.00 mA
C60Filament: 2.80 A
Deconvolution: no
DeconvolutionPassEnergy: 2.95 eV
XRaySetting: 200u50W15KV
EOFH
NORM
REGULAR
0
0
0
0
0
0
1
Su1s 1
C:\Datafiles\users\MIT\berggren\emmabat\211124\104.3.fi.spe:1:3:3.fi
2021
11
24
0
0
0
0
11
Casa Info Follows
0
0
0
0
3.fi
( 0.066142 m , -0.001872 m , 0.174787 m ) Angle: 45.0031 degrees , -0.05 degrees
emmabat211124
SputterRaster: 2.00 2.00 mm
1
3
XPS
Al
1486.6
50.38
200
200
1e+037
1e+037
FAT
187.85
1e+037
4.399
1e+037
1e+037
1e+037
1e+037
1e+037
Su1s

-1
Kinetic Energy
eV
386.6
0.8
2
Intensity
d
Transmission
d
pulse counting
0.1
1
1e+037
1e+037
1e+037
1e+037
2
ESCAPE DEPTH TYPE
d
0
PHI_AtomicNumber
d
111
0
0
7114
6979
7099
6999
6761
6903
7024
6993
7051
7183
7106
7250
7620
7905
8060
8392
8338
8412
8178
7919
7580
7526
7468
7341
7420
7387
7263
6908
6584
6475
6225
6027
5985
6087
6026
5902
5970
5893
5988
6017
5925
6039
5958
6044
6042
6034
5991
6123
6189
6129
6082
5858
5868
5953
5885
5974
5963
5939
5783
5814
6075
5989
5875
5888
5978
5945
6016
5914
6061
5950
6000
5950
5935
5924
5942
6041
6019
5909
5924
5986
6061
6048
5993
6001
5970
6106
6098
6032
6204
6047
6341
6088
6095
6107
6099
6205
6214
6374
6477
6358
6325
6240
6223
6386
6475
6378
6392
6453
6435
6394
6442
6509
6489
6703
6370
6413
6582
6306
6348
6383
6485
6574
6417
6575
6765
6653
6694
6785
6570
6681
6693
6824
6586
6673
6726
6679
6562
6680
6537
6626
6330
6591
6487
6460
6746
6461
6511
6554
6732
6642
6822
6910
6994
6950
7237
7125
7385
7214
7170
6998
6734
6576
6547
6516
6357
6312
6234
6111
6013
6093
5985
6077
6103
5857
6094
6174
6116
6072
6105
6101
5998
6144
6022
6045
6046
6147
6108
6120
6143
6242
6078
6152
6044
6123
6171
6188
6190
6254
6344
6265
6225
6216
6230
6251
6316
6109
6393
6338
6308
6168
6429
6162
6448
6377
6320
6331
6254
6403
6259
6411
6433
6438
6464
6331
6350
6358
6521
6424
6455
6462
6290
6588
6529
6566
6568
6418
6430
6599
6458
6626
6594
6593
6586
6579
6501
6607
6649
6518
6595
6551
6537
6647
6785
6554
6693
6621
6577
6588
6799
6679
6782
6693
6651
6778
6670
6663
6779
6782
6783
6789
6730
6677
6700
6664
6867
6868
6744
6780
6752
6909
6796
6922
6917
6680
6759
6905
6915
6786
6873
6894
6924
6979
7068
6916
6959
6952
6793
6890
6882
6970
6931
6884
6952
7209
7011
7116
6900
7029
7089
7105
7148
7148
7025
7130
7109
7016
7065
7140
6971
6974
7193
7080
7298
7179
7218
7154
7040
7145
7126
7229
7442
7258
7219
7278
7413
7260
7170
7339
7364
7650
7332
7464
7428
7515
7332
7470
7404
7414
7463
7223
7340
7293
7337
7095
7276
7273
7229
7245
7213
7112
7247
7219
7246
7391
7234
7291
7272
7175
7373
7258
7234
7199
7483
7347
7241
7266
7357
7368
7358
7307
7317
7352
7361
7201
7298
7336
7402
7210
7435
7332
7293
7277
7364
7438
7517
7305
7403
7577
7435
7528
7523
7603
7551
7712
7338
7475
7466
7524
7609
7528
7571
7450
7459
7552
7332
7588
7576
7624
7562
7636
7598
7751
7710
7861
7695
7783
7888
7768
7740
7853
7647
7797
7706
7715
7665
7692
7749
7667
7665
7652
7670
7862
7752
7777
7739
7870
7953
7917
7870
7682
7812
7848
7768
7817
7957
7816
7900
8053
7828
7962
7824
7944
7935
8000
8143
8025
8177
8109
7986
8031
8111
7932
7864
8138
8121
8045
8065
8175
8263
8234
8207
7996
8012
7842
7923
8011
7968
7905
8011
8164
8382
8499
9132
9273
9978
9881
9411
8810
8551
8117
8056
8033
7673
7773
7694
7631
7760
7753
7709
7766
7741
7834
7747
7739
7727
7893
7825
7986
7753
7858
7719
7795
7715
7763
7536
7470
7517
7382
7524
7456
7392
7255
7245
7380
7472
7703
7845
8112
8664
9445
10362
11116
11409
10884
9650
8947
8203
7780
7381
7331
7087
6956
6890
6812
6608
6671
6804
6740
6656
6705
6584
6683
6680
6539
6614
6470
6519
6586
6561
6543
6499
6578
6629
6718
6793
6592
6599
6548
6751
6778
6678
6526
6681
6718
6767
6613
6689
6767
6641
6639
6727
6731
6703
6689
6735
6652
6639
6853
6786
6642
6711
6855
6768
6842
6711
6814
6730
6662
6817
6671
6725
6633
6814
6772
6847
6738
6855
6721
6963
7007
6865
6845
6882
6865
6877
6930
6778
6810
6944
7056
6968
7034
6984
6927
6899
7076
6916
6975
6871
7062
7049
6981
7040
7040
6964
6886
7018
6964
6984
7027
7055
6977
7041
7020
7165
7058
6912
7085
7077
7081
7204
7270
7182
7081
6996
7022
7029
7098
7081
7165
6943
7071
7112
7049
7133
7066
7177
7139
7319
7344
7245
7360
7316
7314
7321
7225
7335
7414
7399
7401
7399
7314
7159
7070
7087
6947
6946
6986
6844
6818
6679
6755
6852
6780
6820
6874
7141
7488
8588
9638
10442
10806
10034
8503
7277
6740
6620
6574
6507
6404
6404
6345
6347
6375
6416
6276
6453
6412
6419
6467
6475
6557
6336
6384
6417
6554
6376
6762
6551
6492
6504
6449
6541
6527
6510
6415
6397
6401
6385
6406
6489
6367
6445
6655
6838
7001
7033
6606
6516
6385
6394
6286
6438
6393
6741
7300
7245
7025
6564
6395
6429
6423
6527
6380
6304
6326
6315
6303
6364
6366
6459
6582
6667
6646
6723
6853
6804
6656
6750
6506
6665
6564
6497
6523
6461
6334
6339
6024
5834
5760
5522
5246
5275
5070
5276
5544
6952
10371
14964
16946
13958
8630
5289
4411
4497
5662
9115
15965
21295
20299
13070
6539
3571
2670
2311
2088
2017
1729
1691
1637
1515
1585
1474
1402
1373
1340
1355
1352
1369
1349
1332
1310
1320
1306
1332
1305
1367
1342
1313
1272
1388
1294
1312
1348
1346
1343
1299
1364
1333
1346
1302
1287
1318
1289
1345
1360
1310
1297
1281
1277
1339
1299
1398
1318
1402
1346
1386
1334
1314
1338
1387
1266
1367
1344
1327
1403
1349
1390
1397
1353
1317
1351
1325
1367
1349
1332
1302
1302
1390
1380
1405
1380
1407
1371
1375
1323
1349
1356
1350
1362
1359
1410
1364
1386
1399
1384
1391
1418
1347
1412
1408
1333
1407
1410
1387
1454
1388
1410
1473
1374
1425
1436
1403
1407
1430
1420
1387
1463
1503
1433
1396
1434
1474
1524
1502
1500
1475
1418
1474
1433
1421
1445
1479
1445
1471
1479
1441
1507
1548
1447
1509
1495
1519
1465
1451
1423
1451
1477
1485
1454
1519
1513
1539
1496
1538
1435
1563
1550
1489
1558
1551
1551
1531
1495
1567
1553
1527
1612
1552
1501
1534
1546
1522
1493
1438
1530
1551
1557
1530
1571
1504
1607
1578
1487
1514
1488
1488
1517
1516
1546
1552
1609
1649
1710
1679
1836
1986
2272
2451
2294
1930
1645
1504
1479
1469
1540
1448
1456
1404
1571
1469
1422
1448
1414
1417
1419
1457
1479
1541
1450
1469
1395
1477
1411
1520
1441
1483
1470
1503
1466
1437
1478
1536
1476
1493
1470
1454
1434
1477
1476
1566
1459
1472
1521
1519
1495
1508
1435
1460
1497
1550
1515
1576
1548
1491
1540
1542
1522
1518
1480
1558
1488
1530
1549
1541
1522
1603
1475
1485
1534
1559
1504
1528
1539
1544
1533
1544
1526
1555
1492
1596
1567
1562
1511
1524
1622
1601
1493
1610
1656
1612
1499
1625
1524
1633
1586
1573
1606
1569
1572
1539
1557
1597
1587
1662
1680
1612
1629
1555
1548
1558
1550
1585
1582
1556
1623
1604
1592
1649
1642
1614
1567
1609
1575
1577
1605
1563
1636
1673
1549
1704
1547
1700
1613
1658
1580
1607
1555
1652
1659
1631
1637
1669
1671
1680
1655
1663
1552
1601
1582
1664
1580
1603
1608
1682
1685
1713
1662
1751
1621
1698
1748
1803
1790
1767
1649
1728
1719
1698
1606
1641
1698
1696
1643
1711
1635
1627
1629
1705
1715
1677
1642
1664
1658
1661
1638
1557
1549
1600
1632
1595
1651
1658
1637
1680
1720
1714
1831
1973
1971
1942
1978
1810
1853
1687
1659
1618
1545
1536
1500
1527
1527
1514
1524
1596
1551
1569
1571
1693
1504
1564
1608
1595
1634
1640
1659
1740
1847
1740
1624
1719
1627
1559
1679
1644
1652
1701
1591
1598
1593
1640
1760
1641
1659
1721
1697
1708
1847
1743
1772
1777
1835
1874
1788
1879
1896
1858
1708
1675
1684
1513
1572
1325
1402
1301
1235
1174
1126
1052
1017
984
953
964
1001
898
889
933
857
916
810
913
853
887
888
953
845
899
891
892
868
886
900
875
925
899
967
993
922
902
993
949
983
993
960
915
975
942
954
995
1004
922
946
886
891
887
864
798
828
822
875
865
917
892
868
784
784
819
911
1190
1890
3224
4542
4791
3512
1843
858
491
311
252
232
215
210
223
247
269
279
296
330
304
261
169
75
54
41
21
23
16
11
9
187.141
end of experiment