File: example_data/211124/105.4.fii.vms
VAMAS Surface Chemical Analysis Standard Data Transfer Format 1988 May 4
MIT
PHI VersaProbe II
Emma Batson
FILE:C:\Datafiles\users\MIT\berggren\emmabat\211124\105.4.fii.spe;BATCH:211124;DESC:4.fii;
153
SOFH
Platform: PC
Technique: XPS
FileType:  SPECTRUM
FileDesc: 4.fii
SoftwareVersion: SS 2.8.0.30
InstrumentModel: PHI VersaProbe II
AcqFilename: C:\Datafiles\users\MIT\berggren\emmabat\211124\105.4.fii.spe
FileDate: 2021 11 24
AcqFileDate: 2021 11 24
Institution: MIT
Operator: Emma Batson
ExperimentID: 211124
EnergyReference: none 0.0
AnalyserWorkFcn: 4.399 eV
AnalyserRetardGain: 1.000506
PlatenID: emmabat211124
PhotoFilename: 101.Low Mag.pho
SXIFilename:
SourceAnalyserAngle: 45.0 d
AnalyserSolidAngle: 0.38 sr
IntensityRecal: no
IntensityCalCoeff: 104.036 0.653
EnergyRecal: no
ScanDeflectionSpan: 30 60
ScanDeflectionOffset: 0 -20
SCAMultiplierVoltage: 1875.0 V
NarrowAcceptanceAngle: no
PeakToNoiseRatioState: no
DelayBeforeAcquire: 5 seconds
C60IonGun: 10kV C60 Ion Gun
BiasBoxMode: 0
TFCParameters: 0, 1, 2, 93.73, 7.481, 1, 1
SemFieldOfView: 0.0000000
ImageSizeXY: 0.0000 0.0000
IonGunMode: Off
SputterIon: Ar+
SputterCurrent: 0.000 uA
SputterRate: 0.000 A/min
SputterEnergy: 2.000 kV
FloatVolt: 0.0 V
FloatEnable: no
GridVolt: 120.0
CondensorVolt: 1358.00
ObjectiveVolt: 1440.00
BendVolt: 22.00
SputterRaster: 2.00 2.00 mm
SputterRasterOffset: 0.600 -0.850 mm
TargetSputterTime: 9.0 min
SputterEmission: 0.00 mA
DeflectionBias: 0.0 V
XpsScanMode: scanned
AnalyserMode: FAT
SurvNumCycles: 2
SurvTimePerStep: 50.000000
NoSpectralRegFull: 1
SpectralRegDefFull: 1 1 Su1s 111 1379 -0.8000 1100.0000 -3.0000 1099.0000 -2.0000 0.000000 187.85 AREA
SpectralRegDef2Full: 1 1103.0 1 0 1 1
SpectralRegBackgroundFull: 1 0.0 548.5 0.0
SpectralRegHeroFull: 1 548.5 0.0 0.0 0.00
SpectralRegIRFull: 1 0 0.000 0.000 0.0
NoSpectralReg: 1
SpectralRegDef: 1 1 Su1s 111 1379 -0.8000 1100.0000 -3.0000 1099.0000 -2.0000 0.100000 187.85 AREA
SpectralRegDef2: 1 1103.0 1 0 1 1
SpectralRegBackground: 1 0.0 548.5 0.0
SpectralRegHero: 1 548.5 0.0 0.0 0.00
SpectralRegIR: 1 0 0.000 0.000 0.0
NoSpatialArea: 1
SpatialAreaDef: 1 4 1 (4869.5 -2006.1 17480.8 45.0 0.0)
SpatialAreaDesc: 1
SpatialHRPhotoCor: 1 (0.0 0.0)
XraySource: Al 1486.6 mono
XrayAnodePosition: 5
XrayPower: 50.38 W
XrayBeamDiameter: 200.0 um
XRayBeamVoltage: 15000.0 V
XRayCondenserLensVoltage: 7600.0 V
XRayObjectiveCoilCurrent: 0.707 A
XRayBlankingVoltage: 290.0 V
XRayFilamentCurrent: 1.518 A
XRayStigmator: -0.3 0.0
XRayHighPower: no
EgunNeutMode: Off
NeutralizerCurrent: 20.0 uA
NeutralizerEnergy: 1.00 V
EgunNeutExtractor: 45.0 V
EgunNeutXSteering: 20.0
EgunNeutYSteering: -8.0
EgunNeutFilament: 1.13 A
EgunNeutPulseLength: 10.0 msec
SxiPersistence: 1
SxiSecPerDisplay: 1.0
SxiAutoContrast: yes
SxiAutoContrastLow: 0.30
SxiAutoContrastHigh: 0.30
SxiBindingEnergy: 410.0 eV
SxiPassEnergy: 376 eV
SxiLens2: -804 V
SxiLens3: -761 V
SxiLensBias: 200 V
SxiShutterBias: no
SxiShutterBiasVoltage: 250.0 V
SxiDisplayMode: 2
Detector Acq Time: 20.0 (min)
Number Of Channels: 16
Channel Info: 1 1 1.688
Channel Info: 2 1 1.270
Channel Info: 3 1 1.225
Channel Info: 4 1 1.068
Channel Info: 5 1 1.078
Channel Info: 6 1 0.946
Channel Info: 7 1 0.996
Channel Info: 8 1 0.983
Channel Info: 9 1 1.103
Channel Info: 10 1 1.052
Channel Info: 11 1 0.980
Channel Info: 12 1 0.735
Channel Info: 13 1 0.768
Channel Info: 14 1 0.698
Channel Info: 15 1 0.850
Channel Info: 16 1 1.405
StagePosition: 4.6412 2.6233 17.4808 45.0031 -0.0500
StageCurrentRotationSpeed: 1.0000
DefectPosID: 4
DefectPosComment:
DefectPosU: 4.8663
DefectPosV: 2.0094
DefectPosX: 4.6412
DefectPosY: 2.6233
DefectPosZ: 17.4808
DefectPosTilt: 45.0031
DefectPosRotation: -0.0500
DefectPosAligment: None
DefectPosReferenceImage: 101.Low Mag.pho
C60IonGunMode: Off
C60IonCurrent: 0.0 uA
C60SputterRate: 0.0 A/min
C60Beam: 10.000 kV
C60Temperature: 383.0 C
C60Repellor: -76.0 V
C60Grid: 120.0 V
C60Lens2: 6.215 kV
C60Extractor: -833.0 kV
C60Deflector: -91.0 -124.0 V
C60BlankingDeflector: no yes
C60Raster: 0.8 2.3 mm
C60RasterOffset: 0.4 -0.2 mm
C60Emission: 10.00 mA
C60Filament: 2.80 A
Deconvolution: no
DeconvolutionPassEnergy: 2.95 eV
XRaySetting: 200u50W15KV
EOFH
NORM
REGULAR
0
0
0
0
0
0
1
Su1s 1
C:\Datafiles\users\MIT\berggren\emmabat\211124\105.4.fii.spe:1:4:4.fii
2021
11
24
0
0
0
0
11
Casa Info Follows
0
0
0
0
4.fii
( 0.046412 m , 0.026233 m , 0.174808 m ) Angle: 45.0031 degrees , -0.05 degrees
emmabat211124
SputterRaster: 2.00 2.00 mm
1
4
XPS
Al
1486.6
50.38
200
200
1e+037
1e+037
FAT
187.85
1e+037
4.399
1e+037
1e+037
1e+037
1e+037
1e+037
Su1s

-1
Kinetic Energy
eV
386.6
0.8
2
Intensity
d
Transmission
d
pulse counting
0.1
1
1e+037
1e+037
1e+037
1e+037
2
ESCAPE DEPTH TYPE
d
0
PHI_AtomicNumber
d
111
0
0
7307
7242
7270
7396
7187
7100
7141
7147
7323
7319
7379
7556
7801
8004
8320
8626
8766
8527
8467
8332
7940
7668
7656
7738
7704
7555
7570
7227
6940
6695
6498
6305
6319
6150
6196
6129
6141
6173
6073
6262
6238
6275
6207
6165
6306
6210
6283
6255
6370
6315
6052
6264
6046
6168
6029
5973
6140
6195
6223
6156
6117
6162
5997
6050
6188
6170
6155
6114
6173
6107
6213
6217
6306
6279
6346
6335
6263
6330
6101
6248
6299
6339
6252
6168
6349
6273
6287
6358
6370
6324
6323
6481
6486
6344
6371
6558
6506
6486
6321
6458
6529
6609
6600
6484
6578
6702
6592
6559
6609
6680
6640
6734
6674
6702
6690
6654
6572
6633
6813
6613
6700
6883
6842
6634
6977
6814
6866
6922
7052
7008
6944
6916
6892
6863
6869
6814
6830
6948
6814
6759
6735
6697
6576
6855
6797
6793
6882
6905
7105
7038
7131
7118
7183
7258
7393
7554
7641
7467
7408
7167
7061
6902
6910
6666
6616
6531
6521
6389
6280
6351
6207
6464
6186
6412
6262
6182
6312
6295
6279
6289
6171
6325
6442
6383
6247
6313
6333
6408
6280
6411
6333
6399
6478
6421
6318
6547
6267
6495
6376
6466
6408
6341
6460
6534
6534
6465
6650
6539
6385
6594
6619
6457
6514
6458
6598
6525
6657
6591
6759
6607
6614
6613
6654
6485
6702
6524
6533
6549
6713
6587
6721
6752
6596
6678
6687
6730
6594
6713
6666
6861
6718
6730
6611
6825
6755
6798
6761
6842
6768
6835
6727
6899
6823
6847
6896
6861
6950
6931
6979
6826
6854
6927
6991
6880
6870
6880
6942
6871
6926
7072
6948
6984
6956
7068
7090
7126
6979
7171
7026
7097
7188
7049
7168
7169
7184
7165
7118
7183
7235
7041
7176
7053
7289
7106
7055
7104
7322
7103
7162
7260
7260
7211
7389
7259
7189
7308
7378
7315
7237
7244
7345
7457
7354
7287
7373
7323
7298
7403
7416
7410
7381
7301
7376
7370
7389
7340
7448
7451
7458
7349
7488
7527
7460
7588
7614
7522
7678
7642
7746
7745
7796
7918
7781
7787
7639
7590
7684
7509
7602
7506
7639
7575
7534
7469
7562
7333
7530
7491
7503
7477
7420
7586
7607
7551
7602
7659
7464
7576
7675
7486
7546
7436
7471
7524
7507
7601
7528
7628
7475
7529
7603
7601
7520
7444
7619
7671
7713
7739
7647
7768
8037
7907
7750
7771
7584
7773
7700
7821
7794
7752
7751
7776
7743
7757
7875
7779
7790
7803
7828
7722
7918
7980
7827
7962
7851
7832
7886
7880
7898
7777
7841
8049
7913
7969
7981
8149
7827
8140
8103
8096
8076
8058
7932
8008
8027
7944
8058
7860
8105
8186
8064
8030
7986
8098
7991
8177
8081
8196
8104
8190
8242
8185
8010
8080
8187
8314
8258
8041
8223
8309
8206
8424
8264
8247
8255
8272
8448
8383
8368
8271
8406
8415
8364
8507
8421
8378
8499
8503
8694
8486
8495
8351
8302
8173
8270
8184
8349
8411
8386
8404
8705
8963
9289
9817
10092
10147
9731
9168
8646
8416
8202
8189
8234
8062
8035
7858
8023
7876
8007
8023
8022
7949
7944
8114
8024
8052
7909
8064
8092
8134
8150
8091
7902
7986
7921
7826
7839
7930
7585
7814
7763
7777
7372
7647
7793
7765
8027
8272
8833
9404
10578
11336
11497
11135
10346
9259
8565
7869
7508
7257
7204
7107
7038
6930
6983
6995
6922
6831
6914
7028
6933
6896
6799
6871
6895
6711
6801
6887
6905
6844
6728
6784
6831
6806
6857
6790
6838
6843
6938
6793
6832
6813
6859
6927
7014
6851
6625
6960
6916
6976
6903
7012
6765
6875
6820
6926
6939
6735
6928
7011
6993
6952
7029
7008
7065
6932
7007
7073
7142
6946
7129
6898
6940
6987
7031
7011
6910
7141
7113
7296
7216
6971
6974
7058
7112
7031
7062
7064
7045
7174
7277
7211
7025
7191
6998
7296
7109
7190
7288
7234
7076
7134
7283
7118
7115
7201
7211
7303
7348
7268
7228
7346
7276
7182
7339
7277
7292
7336
7290
7279
7421
7418
7471
7243
7355
7310
7326
7241
7329
7338
7397
7377
7415
7262
7456
7211
7474
7313
7562
7372
7549
7457
7573
7626
7646
7593
7514
7611
7535
7484
7533
7486
7230
7312
7180
7174
7170
7280
7117
7030
7090
6901
7047
6821
6928
7107
7233
7754
8581
9642
10851
11153
10408
8991
7813
7089
6907
6741
6819
6677
6697
6690
6756
6572
6716
6641
6619
6627
6631
6582
6694
6550
6818
6604
6721
6518
6676
6513
6760
6674
6853
6663
6680
6613
6704
6640
6740
6436
6705
6528
6721
6552
6822
6666
7216
7317
7250
6947
6773
6485
6517
6574
6678
6584
6986
7440
7663
7309
6975
6649
6484
6593
6583
6509
6503
6640
6755
6436
6524
6443
6668
6620
6867
6808
6923
6936
6935
6825
7054
6844
6899
6758
6688
6697
6609
6550
6465
6128
6025
5819
5637
5443
5388
5356
5405
5925
6913
10227
15075
17446
15035
9397
5751
4566
4605
5578
8898
15613
21626
21661
14459
7275
3889
2879
2375
2163
2012
1820
1762
1634
1602
1523
1533
1459
1496
1421
1406
1425
1404
1383
1351
1389
1300
1355
1295
1320
1341
1259
1337
1372
1350
1285
1353
1357
1450
1391
1348
1269
1386
1335
1374
1359
1306
1322
1334
1307
1408
1339
1396
1371
1316
1343
1409
1330
1378
1421
1368
1384
1373
1392
1387
1376
1350
1380
1436
1347
1464
1355
1393
1375
1417
1287
1368
1364
1442
1380
1438
1401
1444
1407
1401
1393
1420
1323
1374
1502
1391
1431
1420
1454
1481
1392
1435
1404
1400
1424
1426
1440
1458
1416
1432
1491
1409
1364
1417
1399
1416
1447
1442
1440
1452
1438
1456
1427
1418
1479
1544
1502
1498
1514
1546
1479
1419
1477
1435
1480
1527
1496
1438
1541
1453
1547
1533
1547
1475
1554
1534
1560
1443
1527
1485
1462
1504
1493
1499
1491
1564
1540
1548
1549
1528
1534
1553
1520
1465
1555
1504
1502
1547
1601
1666
1545
1578
1599
1558
1581
1518
1516
1632
1659
1583
1524
1645
1562
1569
1609
1688
1634
1671
1575
1591
1520
1510
1557
1563
1583
1612
1519
1563
1552
1594
1619
1669
1707
1744
1861
1841
2292
2528
2298
1983
1695
1569
1496
1526
1501
1476
1548
1496
1538
1502
1531
1516
1480
1562
1533
1526
1541
1488
1508
1497
1479
1476
1417
1553
1507
1518
1532
1478
1471
1528
1594
1521
1589
1491
1567
1549
1507
1519
1517
1500
1489
1499
1532
1541
1636
1632
1617
1487
1554
1524
1547
1517
1556
1560
1558
1575
1572
1572
1449
1536
1560
1673
1536
1589
1618
1576
1589
1563
1586
1563
1643
1554
1526
1592
1604
1634
1620
1583
1593
1534
1628
1561
1543
1559
1580
1630
1583
1679
1639
1601
1696
1605
1652
1597
1605
1600
1628
1639
1664
1617
1644
1576
1670
1665
1612
1658
1709
1636
1664
1557
1641
1696
1604
1646
1650
1649
1626
1604
1635
1644
1651
1727
1669
1603
1676
1603
1659
1611
1633
1701
1712
1621
1656
1617
1723
1643
1683
1783
1637
1615
1747
1701
1639
1723
1756
1650
1713
1721
1722
1720
1671
1771
1732
1629
1678
1671
1702
1668
1755
1704
1751
1799
1842
1828
1786
1723
1712
1679
1762
1680
1639
1747
1611
1761
1742
1801
1667
1718
1757
1779
1796
1690
1750
1676
1741
1673
1700
1673
1751
1775
1749
1730
1774
1685
1779
1909
1802
1932
1999
2055
2029
1975
1879
1745
1682
1615
1644
1588
1623
1576
1633
1686
1649
1578
1586
1655
1640
1638
1628
1673
1649
1660
1626
1760
1671
1828
1872
1744
1727
1711
1639
1600
1704
1723
1648
1657
1673
1750
1704
1679
1767
1678
1707
1697
1777
1824
1851
1805
1838
1827
1851
1871
1926
1878
1813
1871
1835
1799
1692
1636
1561
1399
1473
1333
1242
1220
1122
1099
1074
1055
1007
930
992
1033
951
908
880
850
880
869
934
899
922
894
936
901
903
865
931
937
954
924
937
970
943
899
1021
943
988
950
996
963
992
1028
982
988
992
1001
956
1024
948
926
901
887
858
837
835
855
902
932
978
944
913
828
784
858
954
1211
1796
3121
4732
5021
3793
2074
924
477
358
271
212
204
196
206
240
282
298
273
298
316
284
197
102
46
24
26
15
16
7
9
187.141
end of experiment