File: example_data/211124/106.5.cii.vms
VAMAS Surface Chemical Analysis Standard Data Transfer Format 1988 May 4
MIT
PHI VersaProbe II
Emma Batson
FILE:C:\Datafiles\users\MIT\berggren\emmabat\211124\106.5.cii.spe;BATCH:211124;DESC:5.cii;
153
SOFH
Platform: PC
Technique: XPS
FileType:  SPECTRUM
FileDesc: 5.cii
SoftwareVersion: SS 2.8.0.30
InstrumentModel: PHI VersaProbe II
AcqFilename: C:\Datafiles\users\MIT\berggren\emmabat\211124\106.5.cii.spe
FileDate: 2021 11 24
AcqFileDate: 2021 11 24
Institution: MIT
Operator: Emma Batson
ExperimentID: 211124
EnergyReference: none 0.0
AnalyserWorkFcn: 4.399 eV
AnalyserRetardGain: 1.000506
PlatenID: emmabat211124
PhotoFilename: 101.Low Mag.pho
SXIFilename:
SourceAnalyserAngle: 45.0 d
AnalyserSolidAngle: 0.38 sr
IntensityRecal: no
IntensityCalCoeff: 104.036 0.653
EnergyRecal: no
ScanDeflectionSpan: 30 60
ScanDeflectionOffset: 0 -20
SCAMultiplierVoltage: 1875.0 V
NarrowAcceptanceAngle: no
PeakToNoiseRatioState: no
DelayBeforeAcquire: 5 seconds
C60IonGun: 10kV C60 Ion Gun
BiasBoxMode: 0
TFCParameters: 0, 1, 2, 93.73, 7.481, 1, 1
SemFieldOfView: 0.0000000
ImageSizeXY: 0.0000 0.0000
IonGunMode: Off
SputterIon: Ar+
SputterCurrent: 0.000 uA
SputterRate: 0.000 A/min
SputterEnergy: 2.000 kV
FloatVolt: 0.0 V
FloatEnable: no
GridVolt: 120.0
CondensorVolt: 1358.00
ObjectiveVolt: 1440.00
BendVolt: 22.00
SputterRaster: 2.00 2.00 mm
SputterRasterOffset: 0.600 -0.850 mm
TargetSputterTime: 9.0 min
SputterEmission: 0.00 mA
DeflectionBias: 0.0 V
XpsScanMode: scanned
AnalyserMode: FAT
SurvNumCycles: 2
SurvTimePerStep: 50.000000
NoSpectralRegFull: 1
SpectralRegDefFull: 1 1 Su1s 111 1379 -0.8000 1100.0000 -3.0000 1099.0000 -2.0000 0.000000 187.85 AREA
SpectralRegDef2Full: 1 1103.0 1 0 1 1
SpectralRegBackgroundFull: 1 0.0 548.5 0.0
SpectralRegHeroFull: 1 548.5 0.0 0.0 0.00
SpectralRegIRFull: 1 0 0.000 0.000 0.0
NoSpectralReg: 1
SpectralRegDef: 1 1 Su1s 111 1379 -0.8000 1100.0000 -3.0000 1099.0000 -2.0000 0.100000 187.85 AREA
SpectralRegDef2: 1 1103.0 1 0 1 1
SpectralRegBackground: 1 0.0 548.5 0.0
SpectralRegHero: 1 548.5 0.0 0.0 0.00
SpectralRegIR: 1 0 0.000 0.000 0.0
NoSpatialArea: 1
SpatialAreaDef: 1 5 1 (7312.1 -3043.1 17509.3 45.0 0.0)
SpatialAreaDesc: 1
SpatialHRPhotoCor: 1 (0.0 0.0)
XraySource: Al 1486.6 mono
XrayAnodePosition: 5
XrayPower: 50.38 W
XrayBeamDiameter: 200.0 um
XRayBeamVoltage: 15000.0 V
XRayCondenserLensVoltage: 7600.0 V
XRayObjectiveCoilCurrent: 0.707 A
XRayBlankingVoltage: 290.0 V
XRayFilamentCurrent: 1.513 A
XRayStigmator: -0.3 0.0
XRayHighPower: no
EgunNeutMode: Off
NeutralizerCurrent: 20.0 uA
NeutralizerEnergy: 1.00 V
EgunNeutExtractor: 45.0 V
EgunNeutXSteering: 20.0
EgunNeutYSteering: -8.0
EgunNeutFilament: 1.13 A
EgunNeutPulseLength: 10.0 msec
SxiPersistence: 1
SxiSecPerDisplay: 1.0
SxiAutoContrast: yes
SxiAutoContrastLow: 0.30
SxiAutoContrastHigh: 0.30
SxiBindingEnergy: 410.0 eV
SxiPassEnergy: 376 eV
SxiLens2: -804 V
SxiLens3: -761 V
SxiLensBias: 200 V
SxiShutterBias: no
SxiShutterBiasVoltage: 250.0 V
SxiDisplayMode: 2
Detector Acq Time: 20.0 (min)
Number Of Channels: 16
Channel Info: 1 1 1.688
Channel Info: 2 1 1.270
Channel Info: 3 1 1.225
Channel Info: 4 1 1.068
Channel Info: 5 1 1.078
Channel Info: 6 1 0.946
Channel Info: 7 1 0.996
Channel Info: 8 1 0.983
Channel Info: 9 1 1.103
Channel Info: 10 1 1.052
Channel Info: 11 1 0.980
Channel Info: 12 1 0.735
Channel Info: 13 1 0.768
Channel Info: 14 1 0.698
Channel Info: 15 1 0.850
Channel Info: 16 1 1.405
StagePosition: 7.0821 3.6177 17.5093 45.0031 -0.0500
StageCurrentRotationSpeed: 1.0000
DefectPosID: 5
DefectPosComment:
DefectPosU: 7.3076
DefectPosV: 3.0479
DefectPosX: 7.0821
DefectPosY: 3.6177
DefectPosZ: 17.5093
DefectPosTilt: 45.0031
DefectPosRotation: -0.0500
DefectPosAligment: None
DefectPosReferenceImage: 101.Low Mag.pho
C60IonGunMode: Off
C60IonCurrent: 0.0 uA
C60SputterRate: 0.0 A/min
C60Beam: 10.000 kV
C60Temperature: 383.0 C
C60Repellor: -76.0 V
C60Grid: 120.0 V
C60Lens2: 6.215 kV
C60Extractor: -833.0 kV
C60Deflector: -91.0 -124.0 V
C60BlankingDeflector: no yes
C60Raster: 0.8 2.3 mm
C60RasterOffset: 0.4 -0.2 mm
C60Emission: 10.00 mA
C60Filament: 2.80 A
Deconvolution: no
DeconvolutionPassEnergy: 2.95 eV
XRaySetting: 200u50W15KV
EOFH
NORM
REGULAR
0
0
0
0
0
0
1
Su1s 1
C:\Datafiles\users\MIT\berggren\emmabat\211124\106.5.cii.spe:1:5:5.cii
2021
11
24
0
0
0
0
11
Casa Info Follows
0
0
0
0
5.cii
( 0.070821 m , 0.036177 m , 0.175093 m ) Angle: 45.0031 degrees , -0.05 degrees
emmabat211124
SputterRaster: 2.00 2.00 mm
1
5
XPS
Al
1486.6
50.38
200
200
1e+037
1e+037
FAT
187.85
1e+037
4.399
1e+037
1e+037
1e+037
1e+037
1e+037
Su1s

-1
Kinetic Energy
eV
386.6
0.8
2
Intensity
d
Transmission
d
pulse counting
0.1
1
1e+037
1e+037
1e+037
1e+037
2
ESCAPE DEPTH TYPE
d
0
PHI_AtomicNumber
d
111
0
0
6406
6572
6422
6402
6427
6334
6561
6259
6415
6275
6415
6406
6616
6611
7044
7058
7142
7156
7055
6950
6732
6731
6604
6712
6636
6702
6548
6340
6278
5978
5894
5772
5705
5604
5624
5512
5632
5605
5474
5667
5695
5642
5760
5658
5725
5918
5744
5739
5791
5813
5598
5659
5723
5677
5736
5682
5749
5776
5572
5709
5569
5807
5650
5609
5666
5640
5776
5712
5769
5748
5736
5674
5659
5925
5837
5768
5777
5813
5843
5672
5861
5939
5848
5907
5802
5832
5954
5857
5933
5823
5960
5956
5905
5946
6068
6133
6244
6005
6079
6002
5947
6033
6088
6102
6231
6167
6086
6116
6263
6123
6397
6161
6243
6268
6122
6302
6191
6194
6191
6251
6185
6401
6250
6374
6323
6387
6379
6407
6581
6404
6474
6345
6420
6373
6427
6408
6410
6379
6336
6354
6259
6376
6335
6420
6314
6355
6295
6384
6421
6472
6524
6715
6444
6818
6747
6768
6750
6672
6501
6376
6310
6347
6225
6246
6194
6013
5977
5901
5894
5813
5813
5827
5855
5866
5933
5859
6036
5739
5963
5870
5985
5908
5874
5815
5896
5944
5937
6018
6047
5886
5956
5947
5985
6025
5965
6043
5971
6001
6065
6085
5899
6141
6020
6026
6082
6063
6024
6147
6116
6015
6096
6227
6051
6124
6088
6070
6197
6201
6125
6182
6221
6127
6296
6096
6279
6200
6104
6157
6207
6210
6227
6297
6125
6243
6383
6251
6363
6392
6333
6374
6462
6244
6336
6252
6242
6226
6316
6323
6322
6351
6338
6472
6319
6364
6365
6292
6677
6642
6475
6482
6495
6485
6540
6433
6674
6448
6558
6428
6550
6504
6571
6672
6659
6514
6598
6511
6641
6489
6659
6787
6590
6790
6543
6731
6678
6739
6712
6716
6694
6586
6764
6752
6722
6682
6839
6785
6830
6769
6805
6695
6890
6849
6662
6852
6772
6911
6853
6830
6784
6817
6910
6904
6993
6853
6957
6983
6839
7070
6987
7041
6910
6924
6877
6762
6826
6854
6885
6980
7060
6921
6834
7043
7189
7112
7146
7072
6993
7194
7212
7238
7257
7188
7334
7113
7050
7104
7064
7179
7148
7045
7138
7066
6890
6934
6984
7168
7110
6951
7001
7108
6947
7212
7091
6958
6970
7280
7100
6957
7061
7207
7018
7079
7044
7208
7006
7123
7108
7217
6951
7123
7287
7159
7144
7263
7232
7232
7167
7275
7226
7236
7225
7319
7201
7211
7041
7276
7115
7311
7185
7233
7209
7484
7295
7280
7098
7406
7270
7312
7368
7394
7441
7528
7311
7469
7376
7360
7366
7428
7388
7669
7389
7696
7503
7475
7558
7564
7597
7481
7556
7474
7431
7556
7538
7677
7689
7676
7526
7620
7487
7661
7684
7491
7468
7700
7469
7547
7636
7595
7699
7667
7830
7731
7770
7774
7851
7698
7637
7710
7651
7718
7897
7633
7830
7707
7693
7832
7841
7655
7886
7772
7911
7846
7737
7938
7916
7873
7913
7816
7793
7990
7804
7683
7701
7748
7685
7606
7695
7572
7727
7753
7804
8117
8429
8773
9065
8931
8843
8261
8169
7693
7759
7404
7548
7372
7466
7330
7526
7467
7586
7310
7253
7554
7645
7565
7600
7510
7436
7522
7486
7514
7617
7494
7512
7402
7326
7518
7417
7319
7185
7247
7126
7078
7042
6914
7154
7040
7345
7489
8064
8533
9393
9750
10016
9716
9051
8193
7800
7382
7182
6941
6826
6704
6654
6643
6602
6556
6605
6551
6602
6448
6532
6406
6523
6502
6418
6407
6424
6321
6451
6424
6468
6364
6502
6421
6605
6517
6463
6514
6450
6523
6468
6499
6361
6531
6561
6531
6439
6407
6600
6629
6644
6733
6437
6654
6486
6678
6749
6657
6530
6701
6658
6639
6611
6572
6619
6687
6599
6605
6656
6644
6590
6542
6629
6715
6743
6604
6674
6598
6615
6749
6702
6793
6689
6744
6677
6805
6819
6696
6810
6679
6646
6657
6737
6967
6771
6800
6868
6909
6817
6809
6695
6825
6852
6828
6863
6858
6809
6873
6942
6832
6929
6903
6983
6937
6853
6963
6874
6964
6927
6976
6881
6952
6866
6909
6925
6837
6928
6886
7088
7113
7049
6933
6881
7065
6986
7035
7043
6925
6949
7053
7109
6942
7254
7023
7184
7067
7198
7136
7182
7211
7183
6966
7127
6919
6898
6864
6729
6754
6558
6545
6615
6592
6644
6616
6525
6561
6827
7476
8354
9301
9995
10137
9486
8016
6973
6668
6462
6359
6346
6361
6251
6192
6133
6260
6171
6015
6229
6187
6268
6307
6093
6185
6118
6189
6315
6075
6333
6181
6211
6298
6376
6228
6192
6327
6243
6228
6163
6072
6081
6220
6245
6277
6206
6530
6574
6763
6680
6452
6335
6235
6095
6171
6193
6248
6541
6905
6892
6781
6555
6083
6039
6050
6061
6032
5949
6179
6200
6258
6142
6189
6183
6213
6307
6254
6495
6356
6435
6470
6464
6533
6379
6265
6257
6152
6131
5994
5929
5691
5524
5186
5129
4803
4639
4758
4724
4938
5811
7988
12020
13980
11654
7519
4611
3893
3990
4768
7212
12584
17480
17226
11264
5837
3257
2500
2157
1916
1778
1705
1649
1576
1483
1475
1459
1433
1372
1342
1322
1337
1325
1286
1320
1276
1333
1297
1378
1316
1288
1320
1304
1355
1360
1334
1356
1311
1301
1292
1353
1255
1368
1310
1407
1319
1403
1356
1336
1316
1315
1316
1347
1310
1271
1382
1342
1417
1369
1320
1280
1327
1316
1362
1326
1346
1434
1380
1371
1345
1429
1253
1428
1366
1299
1356
1311
1367
1432
1350
1408
1342
1368
1358
1348
1339
1399
1410
1381
1393
1333
1403
1450
1308
1380
1422
1412
1413
1431
1400
1351
1457
1443
1375
1418
1467
1459
1462
1390
1467
1455
1425
1446
1449
1375
1402
1508
1446
1514
1436
1496
1506
1475
1465
1518
1474
1489
1460
1487
1454
1485
1451
1473
1441
1515
1445
1419
1462
1472
1478
1500
1488
1536
1499
1521
1478
1510
1450
1540
1545
1540
1564
1490
1546
1608
1521
1514
1494
1504
1535
1552
1520
1499
1606
1587
1578
1502
1589
1550
1555
1512
1558
1506
1570
1618
1647
1593
1612
1638
1577
1636
1605
1654
1620
1586
1539
1574
1498
1579
1536
1493
1498
1531
1506
1548
1520
1586
1602
1655
1748
1875
2238
2596
2546
2150
1716
1535
1543
1526
1502
1397
1545
1406
1379
1464
1427
1426
1450
1475
1461
1509
1458
1530
1464
1483
1480
1519
1495
1476
1482
1462
1525
1496
1512
1477
1486
1442
1448
1455
1421
1496
1499
1444
1432
1443
1497
1516
1443
1516
1499
1483
1522
1501
1500
1539
1543
1449
1478
1467
1532
1501
1529
1572
1455
1558
1479
1548
1544
1539
1470
1537
1532
1513
1514
1485
1544
1467
1512
1520
1546
1530
1520
1507
1534
1622
1598
1605
1526
1567
1525
1553
1577
1604
1580
1576
1555
1554
1541
1593
1574
1607
1533
1624
1541
1652
1553
1627
1590
1628
1579
1586
1646
1620
1506
1606
1584
1561
1514
1540
1515
1612
1607
1542
1628
1598
1614
1555
1564
1618
1606
1646
1595
1637
1559
1547
1596
1615
1649
1629
1647
1641
1614
1657
1552
1657
1604
1593
1641
1673
1617
1573
1576
1578
1620
1594
1547
1589
1617
1643
1634
1602
1635
1671
1685
1763
1815
1983
1928
1920
1843
1698
1637
1668
1674
1688
1657
1658
1689
1666
1606
1687
1628
1597
1672
1647
1621
1637
1594
1671
1593
1672
1641
1598
1608
1586
1637
1703
1632
1637
1692
1733
1844
1828
1842
1840
1821
1783
1748
1646
1607
1599
1590
1529
1552
1505
1571
1585
1535
1504
1533
1551
1559
1600
1520
1492
1538
1502
1557
1639
1692
1934
1998
1818
1649
1543
1514
1486
1437
1514
1548
1527
1492
1527
1517
1567
1521
1632
1667
1589
1616
1585
1590
1617
1598
1570
1557
1540
1667
1708
1640
1650
1591
1554
1545
1422
1363
1294
1296
1169
1189
1154
1076
1055
992
929
920
946
915
964
926
906
866
843
905
878
856
835
914
884
870
863
898
839
869
905
855
892
821
871
898
869
947
924
905
923
883
948
940
954
942
937
919
981
957
957
922
858
870
845
785
739
738
732
820
809
846
890
696
686
652
707
799
1032
1511
2729
3912
4110
3173
1683
823
438
299
256
164
147
193
174
227
244
256
258
256
269
239
147
106
57
33
15
17
16
11
6
187.141
end of experiment