File: example_data/211124/107.6.ci.vms
VAMAS Surface Chemical Analysis Standard Data Transfer Format 1988 May 4
MIT
PHI VersaProbe II
Emma Batson
FILE:C:\Datafiles\users\MIT\berggren\emmabat\211124\107.6.ci.spe;BATCH:211124;DESC:6.ci;
153
SOFH
Platform: PC
Technique: XPS
FileType:  SPECTRUM
FileDesc: 6.ci
SoftwareVersion: SS 2.8.0.30
InstrumentModel: PHI VersaProbe II
AcqFilename: C:\Datafiles\users\MIT\berggren\emmabat\211124\107.6.ci.spe
FileDate: 2021 11 24
AcqFileDate: 2021 11 24
Institution: MIT
Operator: Emma Batson
ExperimentID: 211124
EnergyReference: none 0.0
AnalyserWorkFcn: 4.399 eV
AnalyserRetardGain: 1.000506
PlatenID: emmabat211124
PhotoFilename: 101.Low Mag.pho
SXIFilename:
SourceAnalyserAngle: 45.0 d
AnalyserSolidAngle: 0.38 sr
IntensityRecal: no
IntensityCalCoeff: 104.036 0.653
EnergyRecal: no
ScanDeflectionSpan: 30 60
ScanDeflectionOffset: 0 -20
SCAMultiplierVoltage: 1875.0 V
NarrowAcceptanceAngle: no
PeakToNoiseRatioState: no
DelayBeforeAcquire: 5 seconds
C60IonGun: 10kV C60 Ion Gun
BiasBoxMode: 0
TFCParameters: 0, 1, 2, 93.73, 7.481, 1, 1
SemFieldOfView: 0.0000000
ImageSizeXY: 0.0000 0.0000
IonGunMode: Off
SputterIon: Ar+
SputterCurrent: 0.000 uA
SputterRate: 0.000 A/min
SputterEnergy: 2.000 kV
FloatVolt: 0.0 V
FloatEnable: no
GridVolt: 120.0
CondensorVolt: 1358.00
ObjectiveVolt: 1440.00
BendVolt: 22.00
SputterRaster: 2.00 2.00 mm
SputterRasterOffset: 0.600 -0.850 mm
TargetSputterTime: 9.0 min
SputterEmission: 0.00 mA
DeflectionBias: 0.0 V
XpsScanMode: scanned
AnalyserMode: FAT
SurvNumCycles: 2
SurvTimePerStep: 50.000000
NoSpectralRegFull: 1
SpectralRegDefFull: 1 1 Su1s 111 1379 -0.8000 1100.0000 -3.0000 1099.0000 -2.0000 0.000000 187.85 AREA
SpectralRegDef2Full: 1 1103.0 1 0 1 1
SpectralRegBackgroundFull: 1 0.0 548.5 0.0
SpectralRegHeroFull: 1 548.5 0.0 0.0 0.00
SpectralRegIRFull: 1 0 0.000 0.000 0.0
NoSpectralReg: 1
SpectralRegDef: 1 1 Su1s 111 1379 -0.8000 1100.0000 -3.0000 1099.0000 -2.0000 0.100000 187.85 AREA
SpectralRegDef2: 1 1103.0 1 0 1 1
SpectralRegBackground: 1 0.0 548.5 0.0
SpectralRegHero: 1 548.5 0.0 0.0 0.00
SpectralRegIR: 1 0 0.000 0.000 0.0
NoSpatialArea: 1
SpatialAreaDef: 1 6 1 (10066.6 -554.2 17507.3 45.0 0.0)
SpatialAreaDesc: 1
SpatialHRPhotoCor: 1 (0.0 0.0)
XraySource: Al 1486.6 mono
XrayAnodePosition: 5
XrayPower: 50.38 W
XrayBeamDiameter: 200.0 um
XRayBeamVoltage: 15000.0 V
XRayCondenserLensVoltage: 7600.0 V
XRayObjectiveCoilCurrent: 0.707 A
XRayBlankingVoltage: 290.0 V
XRayFilamentCurrent: 1.513 A
XRayStigmator: -0.3 0.0
XRayHighPower: no
EgunNeutMode: Off
NeutralizerCurrent: 20.0 uA
NeutralizerEnergy: 1.00 V
EgunNeutExtractor: 45.0 V
EgunNeutXSteering: 20.0
EgunNeutYSteering: -8.0
EgunNeutFilament: 1.13 A
EgunNeutPulseLength: 10.0 msec
SxiPersistence: 1
SxiSecPerDisplay: 1.0
SxiAutoContrast: yes
SxiAutoContrastLow: 0.30
SxiAutoContrastHigh: 0.30
SxiBindingEnergy: 410.0 eV
SxiPassEnergy: 376 eV
SxiLens2: -804 V
SxiLens3: -761 V
SxiLensBias: 200 V
SxiShutterBias: no
SxiShutterBiasVoltage: 250.0 V
SxiDisplayMode: 2
Detector Acq Time: 20.0 (min)
Number Of Channels: 16
Channel Info: 1 1 1.688
Channel Info: 2 1 1.270
Channel Info: 3 1 1.225
Channel Info: 4 1 1.068
Channel Info: 5 1 1.078
Channel Info: 6 1 0.946
Channel Info: 7 1 0.996
Channel Info: 8 1 0.983
Channel Info: 9 1 1.103
Channel Info: 10 1 1.052
Channel Info: 11 1 0.980
Channel Info: 12 1 0.735
Channel Info: 13 1 0.768
Channel Info: 14 1 0.698
Channel Info: 15 1 0.850
Channel Info: 16 1 1.405
StagePosition: 9.7833 1.1066 17.5073 45.0031 -0.0500
StageCurrentRotationSpeed: 1.0000
DefectPosID: 6
DefectPosComment:
DefectPosU: 10.0651
DefectPosV: 0.5622
DefectPosX: 9.7833
DefectPosY: 1.1066
DefectPosZ: 17.5073
DefectPosTilt: 45.0031
DefectPosRotation: -0.0500
DefectPosAligment: None
DefectPosReferenceImage: 101.Low Mag.pho
C60IonGunMode: Off
C60IonCurrent: 0.0 uA
C60SputterRate: 0.0 A/min
C60Beam: 10.000 kV
C60Temperature: 383.0 C
C60Repellor: -76.0 V
C60Grid: 120.0 V
C60Lens2: 6.215 kV
C60Extractor: -833.0 kV
C60Deflector: -91.0 -124.0 V
C60BlankingDeflector: no yes
C60Raster: 0.8 2.3 mm
C60RasterOffset: 0.4 -0.2 mm
C60Emission: 10.00 mA
C60Filament: 2.80 A
Deconvolution: no
DeconvolutionPassEnergy: 2.95 eV
XRaySetting: 200u50W15KV
EOFH
NORM
REGULAR
0
0
0
0
0
0
1
Su1s 1
C:\Datafiles\users\MIT\berggren\emmabat\211124\107.6.ci.spe:1:6:6.ci
2021
11
24
0
0
0
0
11
Casa Info Follows
0
0
0
0
6.ci
( 0.097833 m , 0.011066 m , 0.175073 m ) Angle: 45.0031 degrees , -0.05 degrees
emmabat211124
SputterRaster: 2.00 2.00 mm
1
6
XPS
Al
1486.6
50.38
200
200
1e+037
1e+037
FAT
187.85
1e+037
4.399
1e+037
1e+037
1e+037
1e+037
1e+037
Su1s

-1
Kinetic Energy
eV
386.6
0.8
2
Intensity
d
Transmission
d
pulse counting
0.1
1
1e+037
1e+037
1e+037
1e+037
2
ESCAPE DEPTH TYPE
d
0
PHI_AtomicNumber
d
111
0
0
7356
7297
7344
7342
7397
7428
7362
7458
7443
7340
7595
7720
8006
8268
8578
8828
8876
8797
8780
8296
8276
7934
7835
7732
8062
7672
7659
7173
7085
6783
6786
6174
6385
6322
6416
6338
6378
6114
6261
6146
6345
6238
6125
6286
6247
6360
6376
6380
6252
6272
6273
6223
6318
6131
6221
6145
6278
6262
6220
6286
6221
6242
6177
6142
6173
6189
6139
6157
6276
6222
6197
6178
6283
6248
6268
6355
6176
6283
6227
6273
6361
6269
6358
6449
6434
6354
6335
6380
6403
6498
6345
6490
6322
6412
6506
6484
6356
6533
6601
6518
6450
6754
6555
6645
6520
6594
6610
6808
6692
6818
6884
6936
6800
6655
6759
6540
6700
6791
6774
6765
6826
6901
6947
7015
6858
7128
6897
6960
7079
6964
7149
7075
6911
7022
6849
6943
6977
6774
6736
6783
6974
6872
6897
6777
6899
6912
6739
6964
6849
7083
6876
7322
7179
7437
7504
7785
7667
7703
7473
7375
7143
6937
7067
6906
6676
6713
6591
6563
6387
6466
6422
6294
6321
6308
6440
6395
6333
6349
6361
6445
6247
6327
6425
6333
6331
6333
6418
6387
6426
6372
6368
6325
6508
6412
6527
6492
6505
6407
6605
6513
6546
6441
6492
6562
6543
6502
6510
6492
6577
6516
6539
6530
6642
6408
6534
6487
6510
6712
6774
6578
6828
6615
6663
6700
6721
6561
6659
6734
6771
6673
6806
6897
6853
6822
6809
7029
6849
6940
6785
6946
6840
6876
7012
6777
6931
6798
6858
6926
6886
6953
6936
6875
6825
7061
6880
7066
6888
7154
7055
6859
6988
6930
7035
6982
7144
6963
7030
7033
6977
7016
6908
7152
6951
6951
7142
7073
7137
7144
7056
7070
7172
7119
6903
7100
7188
7092
7230
7207
7074
7226
7072
7136
7220
7133
7364
7359
7389
7347
7207
7293
7428
7093
7216
7092
7472
7316
7305
7268
7170
7409
7299
7236
7311
7388
7501
7529
7427
7585
7555
7472
7443
7302
7516
7354
7431
7418
7501
7298
7546
7644
7444
7585
7583
7684
7656
7834
7625
7794
7704
7795
7720
7663
7993
7851
7680
7755
7646
7676
7641
7507
7533
7375
7496
7573
7452
7750
7417
7485
7417
7651
7494
7685
7646
7510
7461
7488
7610
7507
7655
7570
7643
7546
7601
7605
7726
7622
7764
7513
7686
7668
7546
7650
7530
7618
7629
7666
7627
7718
7797
7692
7780
7765
7766
7727
7702
7762
7700
7783
7673
7800
7836
7619
7764
7816
7814
7877
7942
7846
7911
7771
7852
7763
7836
7831
7863
7773
7929
7879
7896
7996
8030
8012
8050
8057
7815
8178
7974
8130
7926
8171
8179
8078
7941
8029
8133
8004
8062
7994
7932
8087
8141
8052
8165
7907
8289
8231
8236
8029
8094
7991
8170
8224
8350
8255
8366
8256
8355
8267
8281
8212
8186
8312
8411
8221
8345
8301
8370
8134
8395
8476
8393
8368
8427
8475
8342
8386
8564
8495
8455
8478
8539
8456
8307
8290
8227
8307
8249
8339
8314
8312
8696
9081
9351
10000
10372
10138
9953
9444
8734
8428
8410
8295
8028
8087
8066
7957
8084
7817
7992
8013
7973
8062
7942
8056
8033
8134
8101
8100
8010
8174
8078
8230
7996
7930
7949
7930
7978
7862
7948
7819
7791
7618
7570
7730
7860
7957
7936
8445
8935
9702
10955
11671
11934
11383
10410
9391
8444
8086
7744
7530
7366
7268
7107
7087
7014
6930
6906
6790
6851
6910
6756
6718
6721
6764
6915
6787
6817
6864
6837
6826
6877
6690
6856
6675
6816
6787
6767
7016
6923
6773
6827
6781
6912
6891
6855
6800
6830
6957
6800
6893
6924
6958
6813
6883
6898
7094
7047
6923
6971
6973
7105
7106
6969
6924
7048
6945
7210
6950
7078
7094
7225
7262
7133
7087
7099
7225
7200
7009
7043
7088
7270
7158
7051
6942
7002
7113
7205
7094
6882
7056
7160
7121
7263
7123
7249
7101
7270
7153
7094
7295
7130
7152
7113
7143
7288
7152
7140
7163
7240
7148
7140
7094
7298
7259
7270
7425
7254
7238
7348
7475
7377
7312
7240
7238
7337
7321
7396
7344
7462
7335
7362
7302
7363
7307
7379
7323
7287
7522
7444
7527
7491
7381
7511
7507
7535
7357
7481
7584
7503
7451
7518
7628
7552
7199
7265
7311
7266
7103
6986
6978
7079
7028
7022
7026
6968
7014
7355
7694
8749
9870
10820
11375
10756
8869
7653
7009
7031
6614
6712
6712
6647
6759
6744
6757
6642
6769
6672
6514
6589
6567
6569
6753
6563
6688
6716
6776
6706
6684
6735
6583
6809
6566
6671
6595
6804
6679
6738
6663
6701
6813
6894
6777
6804
6849
7251
7208
7302
6935
6746
6733
6788
6657
6651
6934
6897
7451
7366
7098
6949
6674
6581
6472
6585
6695
6454
6533
6554
6599
6489
6637
6825
6743
6985
7091
6998
6987
7002
7013
7022
6901
6728
6802
6866
6759
6810
6582
6479
6434
6088
5894
5699
5440
5409
5496
5630
5976
7190
10819
15660
18052
14856
9489
5665
4615
4786
5978
9517
16368
22662
22005
14426
7072
3945
2954
2547
2163
2036
1835
1746
1659
1608
1551
1600
1504
1496
1416
1371
1371
1313
1370
1309
1393
1342
1384
1428
1382
1413
1398
1327
1291
1350
1379
1377
1391
1359
1346
1344
1365
1354
1393
1369
1385
1401
1431
1345
1344
1410
1410
1338
1384
1440
1406
1407
1418
1448
1328
1414
1334
1393
1409
1397
1422
1380
1386
1442
1387
1376
1423
1436
1402
1381
1424
1446
1414
1383
1422
1371
1397
1461
1408
1435
1390
1296
1420
1404
1426
1436
1470
1376
1503
1472
1362
1425
1455
1463
1435
1455
1399
1352
1477
1425
1458
1428
1469
1333
1447
1439
1514
1363
1465
1487
1464
1479
1456
1516
1503
1493
1480
1443
1446
1578
1492
1429
1490
1459
1513
1441
1478
1528
1536
1473
1524
1485
1530
1521
1477
1488
1556
1538
1475
1512
1532
1498
1514
1541
1513
1543
1527
1614
1507
1612
1521
1562
1520
1565
1597
1589
1560
1607
1532
1608
1562
1524
1549
1600
1565
1593
1587
1539
1573
1564
1607
1621
1570
1616
1689
1686
1621
1655
1638
1672
1662
1542
1528
1562
1554
1613
1566
1515
1651
1613
1686
1651
1771
1752
1842
1983
2131
2484
2257
1978
1659
1538
1605
1531
1537
1514
1557
1608
1567
1512
1509
1514
1455
1577
1518
1507
1567
1637
1519
1610
1640
1545
1548
1548
1551
1518
1537
1551
1522
1563
1559
1595
1527
1524
1517
1546
1534
1539
1563
1591
1585
1542
1634
1582
1614
1600
1600
1486
1618
1548
1567
1532
1610
1546
1678
1583
1566
1538
1562
1594
1525
1678
1605
1581
1516
1623
1615
1595
1596
1550
1536
1601
1611
1614
1612
1579
1607
1563
1636
1607
1626
1586
1658
1578
1639
1630
1598
1536
1678
1603
1658
1583
1658
1679
1655
1546
1592
1589
1663
1600
1725
1600
1601
1674
1687
1710
1723
1726
1656
1681
1630
1633
1612
1714
1651
1678
1686
1676
1587
1718
1658
1658
1596
1677
1746
1676
1689
1699
1642
1686
1625
1694
1655
1692
1698
1665
1697
1615
1609
1673
1662
1598
1633
1663
1613
1604
1654
1717
1653
1611
1686
1650
1678
1702
1682
1696
1672
1640
1713
1688
1753
1886
1822
1856
1820
1685
1729
1680
1782
1776
1781
1706
1701
1724
1757
1770
1747
1763
1809
1683
1720
1717
1742
1723
1678
1736
1707
1699
1701
1625
1667
1751
1709
1766
1760
1852
1880
1988
2011
1983
2014
1852
1838
1867
1660
1725
1654
1694
1628
1664
1718
1659
1639
1626
1663
1632
1541
1625
1652
1658
1627
1689
1703
1693
1715
1836
1823
1831
1683
1715
1625
1713
1721
1735
1700
1736
1688
1677
1724
1741
1810
1761
1753
1754
1715
1779
1821
1849
1752
1797
1784
1938
1850
1913
1904
1922
1875
1763
1647
1611
1559
1504
1423
1352
1191
1258
1175
1148
1052
1054
993
1004
985
1017
911
935
912
856
951
887
914
949
924
951
920
872
886
932
941
891
920
903
930
959
993
976
902
990
993
997
1009
976
953
987
1046
1053
1007
980
967
965
921
897
910
881
961
850
843
857
896
859
980
937
841
804
847
931
950
1176
1958
3428
4920
4971
3722
2061
951
484
345
275
244
215
210
268
237
252
264
271
295
290
248
183
108
46
42
23
20
14
9
10
187.141
end of experiment