File: example_data/211124/108.7.bi.vms
VAMAS Surface Chemical Analysis Standard Data Transfer Format 1988 May 4
MIT
PHI VersaProbe II
Emma Batson
FILE:C:\Datafiles\users\MIT\berggren\emmabat\211124\108.7.bi.spe;BATCH:211124;DESC:7.bi;
153
SOFH
Platform: PC
Technique: XPS
FileType:  SPECTRUM
FileDesc: 7.bi
SoftwareVersion: SS 2.8.0.30
InstrumentModel: PHI VersaProbe II
AcqFilename: C:\Datafiles\users\MIT\berggren\emmabat\211124\108.7.bi.spe
FileDate: 2021 11 24
AcqFileDate: 2021 11 24
Institution: MIT
Operator: Emma Batson
ExperimentID: 211124
EnergyReference: none 0.0
AnalyserWorkFcn: 4.399 eV
AnalyserRetardGain: 1.000506
PlatenID: emmabat211124
PhotoFilename: 101.Low Mag.pho
SXIFilename:
SourceAnalyserAngle: 45.0 d
AnalyserSolidAngle: 0.38 sr
IntensityRecal: no
IntensityCalCoeff: 104.036 0.653
EnergyRecal: no
ScanDeflectionSpan: 30 60
ScanDeflectionOffset: 0 -20
SCAMultiplierVoltage: 1875.0 V
NarrowAcceptanceAngle: no
PeakToNoiseRatioState: no
DelayBeforeAcquire: 5 seconds
C60IonGun: 10kV C60 Ion Gun
BiasBoxMode: 0
TFCParameters: 0, 1, 2, 93.73, 7.481, 1, 1
SemFieldOfView: 0.0000000
ImageSizeXY: 0.0000 0.0000
IonGunMode: Off
SputterIon: Ar+
SputterCurrent: 0.000 uA
SputterRate: 0.000 A/min
SputterEnergy: 2.000 kV
FloatVolt: 0.0 V
FloatEnable: no
GridVolt: 120.0
CondensorVolt: 1358.00
ObjectiveVolt: 1440.00
BendVolt: 22.00
SputterRaster: 2.00 2.00 mm
SputterRasterOffset: 0.600 -0.850 mm
TargetSputterTime: 9.0 min
SputterEmission: 0.00 mA
DeflectionBias: 0.0 V
XpsScanMode: scanned
AnalyserMode: FAT
SurvNumCycles: 2
SurvTimePerStep: 50.000000
NoSpectralRegFull: 1
SpectralRegDefFull: 1 1 Su1s 111 1379 -0.8000 1100.0000 -3.0000 1099.0000 -2.0000 0.000000 187.85 AREA
SpectralRegDef2Full: 1 1103.0 1 0 1 1
SpectralRegBackgroundFull: 1 0.0 548.5 0.0
SpectralRegHeroFull: 1 548.5 0.0 0.0 0.00
SpectralRegIRFull: 1 0 0.000 0.000 0.0
NoSpectralReg: 1
SpectralRegDef: 1 1 Su1s 111 1379 -0.8000 1100.0000 -3.0000 1099.0000 -2.0000 0.100000 187.85 AREA
SpectralRegDef2: 1 1103.0 1 0 1 1
SpectralRegBackground: 1 0.0 548.5 0.0
SpectralRegHero: 1 548.5 0.0 0.0 0.00
SpectralRegIR: 1 0 0.000 0.000 0.0
NoSpatialArea: 1
SpatialAreaDef: 1 7 1 (9546.9 -4443.2 17511.4 45.0 0.0)
SpatialAreaDesc: 1
SpatialHRPhotoCor: 1 (0.0 0.0)
XraySource: Al 1486.6 mono
XrayAnodePosition: 5
XrayPower: 50.38 W
XrayBeamDiameter: 200.0 um
XRayBeamVoltage: 15000.0 V
XRayCondenserLensVoltage: 7600.0 V
XRayObjectiveCoilCurrent: 0.707 A
XRayBlankingVoltage: 290.0 V
XRayFilamentCurrent: 1.518 A
XRayStigmator: -0.3 0.0
XRayHighPower: no
EgunNeutMode: Off
NeutralizerCurrent: 20.0 uA
NeutralizerEnergy: 1.00 V
EgunNeutExtractor: 45.0 V
EgunNeutXSteering: 20.0
EgunNeutYSteering: -8.0
EgunNeutFilament: 1.13 A
EgunNeutPulseLength: 10.0 msec
SxiPersistence: 1
SxiSecPerDisplay: 1.0
SxiAutoContrast: yes
SxiAutoContrastLow: 0.30
SxiAutoContrastHigh: 0.30
SxiBindingEnergy: 410.0 eV
SxiPassEnergy: 376 eV
SxiLens2: -804 V
SxiLens3: -761 V
SxiLensBias: 200 V
SxiShutterBias: no
SxiShutterBiasVoltage: 250.0 V
SxiDisplayMode: 2
Detector Acq Time: 20.0 (min)
Number Of Channels: 16
Channel Info: 1 1 1.688
Channel Info: 2 1 1.270
Channel Info: 3 1 1.225
Channel Info: 4 1 1.068
Channel Info: 5 1 1.078
Channel Info: 6 1 0.946
Channel Info: 7 1 0.996
Channel Info: 8 1 0.983
Channel Info: 9 1 1.103
Channel Info: 10 1 1.052
Channel Info: 11 1 0.980
Channel Info: 12 1 0.735
Channel Info: 13 1 0.768
Channel Info: 14 1 0.698
Channel Info: 15 1 0.850
Channel Info: 16 1 1.405
StagePosition: 9.3224 4.9769 17.5114 45.0031 -0.0500
StageCurrentRotationSpeed: 1.0000
DefectPosID: 7
DefectPosComment:
DefectPosU: 9.5416
DefectPosV: 4.4505
DefectPosX: 9.3224
DefectPosY: 4.9769
DefectPosZ: 17.5114
DefectPosTilt: 45.0031
DefectPosRotation: -0.0500
DefectPosAligment: None
DefectPosReferenceImage: 101.Low Mag.pho
C60IonGunMode: Off
C60IonCurrent: 0.0 uA
C60SputterRate: 0.0 A/min
C60Beam: 10.000 kV
C60Temperature: 383.0 C
C60Repellor: -76.0 V
C60Grid: 120.0 V
C60Lens2: 6.215 kV
C60Extractor: -833.0 kV
C60Deflector: -91.0 -124.0 V
C60BlankingDeflector: no yes
C60Raster: 0.8 2.3 mm
C60RasterOffset: 0.4 -0.2 mm
C60Emission: 10.00 mA
C60Filament: 2.80 A
Deconvolution: no
DeconvolutionPassEnergy: 2.95 eV
XRaySetting: 200u50W15KV
EOFH
NORM
REGULAR
0
0
0
0
0
0
1
Su1s 1
C:\Datafiles\users\MIT\berggren\emmabat\211124\108.7.bi.spe:1:7:7.bi
2021
11
24
0
0
0
0
11
Casa Info Follows
0
0
0
0
7.bi
( 0.093224 m , 0.049769 m , 0.175114 m ) Angle: 45.0031 degrees , -0.05 degrees
emmabat211124
SputterRaster: 2.00 2.00 mm
1
7
XPS
Al
1486.6
50.38
200
200
1e+037
1e+037
FAT
187.85
1e+037
4.399
1e+037
1e+037
1e+037
1e+037
1e+037
Su1s

-1
Kinetic Energy
eV
386.6
0.8
2
Intensity
d
Transmission
d
pulse counting
0.1
1
1e+037
1e+037
1e+037
1e+037
2
ESCAPE DEPTH TYPE
d
0
PHI_AtomicNumber
d
111
0
0
7175
7027
7089
7038
7143
7193
7160
7296
7268
7187
7289
7706
7927
7992
8288
8570
8801
8532
8379
8187
7704
7824
7735
7606
7502
7517
7337
7096
6863
6673
6558
6264
6085
6218
6079
6177
6175
6237
6138
6069
6264
6137
6002
6138
6136
6233
6051
6164
6098
6232
6165
6125
6051
6015
6054
6022
6084
6051
5927
6109
6129
5933
6071
5982
5972
5991
6027
6047
6070
6066
6051
6022
6026
5958
6195
6158
6118
6097
6155
6267
6304
6114
6089
6092
6233
6118
6156
6304
6159
6310
6299
6283
6219
6308
6214
6371
6344
6476
6395
6506
6329
6455
6306
6487
6476
6474
6354
6516
6575
6482
6462
6485
6456
6637
6615
6548
6636
6533
6594
6579
6535
6386
6659
6769
6672
6708
6962
6719
6872
6794
6937
6730
6771
6828
6686
6578
6605
6797
6747
6795
6758
6648
6476
6720
6711
6635
6749
6703
6860
6759
6816
6970
7157
7199
7412
7229
7499
7294
7116
6908
6923
6822
6749
6602
6390
6445
6283
6324
6219
6160
6274
6142
6320
6204
6029
6252
6115
5989
6256
6102
6148
6032
6206
6238
6236
6246
6279
6334
6404
6180
6221
6469
6318
6293
6389
6381
6307
6328
6317
6413
6311
6449
6423
6388
6552
6480
6510
6543
6448
6441
6449
6586
6457
6435
6458
6534
6554
6517
6634
6416
6438
6542
6561
6555
6425
6551
6378
6512
6544
6656
6602
6631
6588
6646
6614
6708
6650
6753
6777
6770
6762
6658
6596
6706
6761
6708
6774
6714
6714
6898
6774
6740
6653
6669
6778
6556
6759
6707
6793
6811
6761
6874
6833
6819
6904
6857
6846
6801
7010
6739
6957
6976
6872
6868
6866
6953
7074
6861
6864
6935
6758
6922
6974
6979
6948
6884
7001
6920
7001
6728
7079
6936
7125
7057
7209
6942
7012
7052
7142
6978
7084
6991
7139
7003
7206
7060
7224
7208
7092
7351
7247
7144
7179
7302
7332
7248
7351
7323
7397
7202
7211
7207
7112
7225
7198
7273
7330
7304
7270
7271
7358
7425
7371
7370
7531
7235
7486
7549
7490
7481
7746
7627
7788
7701
7488
7427
7522
7306
7422
7402
7292
7338
7085
7393
7413
7330
7283
7135
7343
7231
7419
7284
7208
7386
7295
7453
7378
7304
7331
7361
7419
7397
7379
7370
7378
7382
7396
7386
7451
7432
7363
7436
7388
7417
7577
7595
7447
7435
7486
7544
7563
7542
7634
7434
7380
7519
7541
7616
7603
7722
7565
7624
7477
7686
7345
7664
7685
7902
7590
7572
7718
7701
7645
7539
7857
7759
7736
7774
7792
7771
7755
7694
7764
7726
7896
7961
7861
8020
7923
7820
7757
7768
7948
7945
7870
7942
7855
7923
8060
7881
7938
7918
7849
7928
7876
7990
7970
7978
8063
7925
7736
7864
7943
7958
8025
8082
8038
8014
8027
7982
8062
8234
8079
8073
7977
7963
8323
8082
8211
8134
8341
8351
8192
8141
8311
8237
8312
8263
8343
8262
8276
8187
8198
8046
7967
8143
8003
8095
8174
8310
8351
8715
9376
9659
9955
9910
9556
9122
8443
8450
8102
8065
7969
7923
7798
7969
7822
7653
7942
7749
8035
7973
7683
7727
8070
7689
7970
7999
8075
7846
8043
7859
7851
7942
7891
7764
7746
7751
7636
7668
7551
7453
7624
7509
7540
7688
7858
8268
8927
9535
10592
11206
11525
11128
9965
9152
8463
7830
7606
7321
7115
7028
7030
6895
6775
6884
6818
6848
6652
6694
6740
6631
6712
6654
6694
6642
6629
6666
6703
6596
6644
6693
6641
6734
6523
6830
6619
6659
6622
6762
6781
6761
6763
6820
6728
6700
6849
6725
6715
6703
6805
6759
6580
6777
6734
6698
6805
6733
6744
6750
6843
6832
6898
7055
6865
6744
6734
6850
6863
6933
6858
6853
6776
7013
6947
6860
6978
6875
7049
6892
6947
7125
6894
6910
7014
6993
7064
6851
6885
7109
7030
6985
7128
7021
7207
7064
7007
7095
7161
7016
7165
7066
7118
7083
7023
6998
7166
7177
7092
7230
7082
7293
7117
7192
7356
7210
7064
7116
7212
7125
7160
7264
7182
7145
7134
7293
7173
7235
7091
7294
7066
7130
7211
7029
7257
7348
7326
7318
7350
7429
7303
7235
7362
7317
7422
7478
7331
7385
7439
7351
7361
7419
7314
7191
7288
7043
7109
6931
6880
6891
6842
6678
6799
6694
6863
7045
6999
7569
8665
9778
10684
10976
10252
8756
7277
6846
6655
6493
6551
6574
6458
6445
6635
6557
6368
6356
6528
6465
6618
6561
6437
6466
6557
6313
6458
6395
6513
6493
6581
6384
6579
6424
6591
6528
6566
6330
6430
6421
6498
6562
6602
6591
6548
6738
6919
6954
7141
6726
6535
6426
6506
6459
6488
6466
6546
7067
7313
6997
6529
6477
6404
6431
6405
6436
6523
6463
6591
6472
6488
6453
6595
6515
6599
6799
6671
6873
6797
6818
6781
6694
6657
6702
6474
6828
6596
6513
6229
6129
5921
5721
5574
5303
5187
5246
5327
5677
6876
10380
15190
17510
14540
9044
5415
4473
4689
5736
9295
16004
21731
20949
13482
6907
3908
2885
2361
2105
1882
1736
1755
1657
1608
1633
1522
1422
1364
1398
1387
1316
1312
1369
1255
1386
1378
1341
1378
1325
1351
1340
1349
1331
1298
1423
1354
1341
1361
1387
1402
1339
1354
1249
1352
1322
1304
1390
1356
1393
1292
1366
1347
1283
1355
1308
1337
1361
1433
1406
1359
1368
1368
1332
1384
1321
1442
1392
1395
1294
1373
1340
1340
1371
1350
1343
1311
1410
1336
1375
1298
1388
1352
1364
1435
1353
1430
1417
1414
1390
1346
1343
1358
1393
1403
1398
1413
1355
1474
1361
1389
1358
1404
1443
1411
1418
1383
1429
1412
1450
1419
1439
1415
1457
1454
1451
1420
1474
1449
1443
1471
1476
1448
1413
1457
1455
1442
1447
1401
1427
1377
1463
1393
1466
1369
1511
1463
1491
1480
1468
1446
1479
1466
1462
1480
1506
1439
1484
1521
1529
1501
1511
1432
1578
1524
1504
1544
1476
1539
1588
1496
1542
1545
1544
1519
1536
1472
1455
1499
1550
1480
1571
1566
1626
1510
1539
1607
1581
1589
1591
1579
1570
1560
1613
1563
1561
1546
1490
1461
1502
1541
1499
1584
1586
1460
1526
1606
1663
1737
1776
1991
2220
2447
2238
1891
1676
1540
1465
1508
1481
1525
1458
1542
1512
1516
1505
1482
1498
1526
1430
1501
1549
1458
1492
1541
1536
1518
1532
1450
1511
1530
1489
1409
1513
1440
1521
1539
1480
1487
1519
1534
1539
1459
1514
1511
1536
1526
1498
1513
1456
1550
1565
1491
1480
1581
1482
1565
1460
1536
1552
1564
1539
1510
1562
1531
1542
1552
1552
1464
1547
1526
1567
1507
1565
1578
1569
1521
1556
1548
1579
1573
1603
1627
1615
1535
1626
1531
1597
1529
1603
1537
1616
1543
1536
1574
1566
1608
1589
1616
1606
1512
1659
1621
1609
1618
1620
1569
1641
1711
1691
1689
1652
1652
1622
1580
1644
1652
1654
1626
1657
1598
1653
1613
1560
1653
1628
1613
1674
1699
1697
1689
1578
1637
1544
1621
1570
1626
1647
1632
1635
1672
1598
1683
1623
1678
1555
1645
1642
1667
1696
1606
1690
1666
1615
1684
1655
1686
1642
1669
1613
1695
1626
1699
1682
1722
1804
1648
1820
1895
1737
1720
1675
1654
1757
1571
1625
1624
1708
1654
1712
1705
1686
1690
1628
1723
1691
1655
1669
1661
1642
1634
1584
1655
1596
1621
1580
1657
1637
1729
1680
1771
1776
1903
1917
1925
1874
1831
1765
1672
1691
1717
1536
1645
1569
1672
1552
1601
1567
1578
1541
1578
1538
1639
1479
1535
1584
1595
1641
1708
1717
1774
1866
1779
1605
1594
1645
1642
1633
1632
1619
1616
1566
1592
1683
1691
1659
1687
1627
1623
1674
1726
1728
1858
1728
1758
1759
1807
1751
1812
1875
1790
1800
1792
1639
1585
1533
1433
1306
1242
1237
1205
1169
1143
1039
1016
977
913
912
881
913
965
851
825
895
823
861
873
886
911
879
875
927
872
852
890
866
885
853
864
923
938
902
941
870
955
955
965
925
980
948
923
923
984
1004
982
967
913
884
897
901
773
850
848
822
831
947
893
827
831
790
890
1013
1129
1881
3363
4672
4873
3547
1913
854
486
349
272
212
190
205
218
242
290
277
273
301
307
263
180
116
52
34
22
27
15
14
5
187.141
end of experiment